Workbook

Sheet LONG
A1: Scenario_ID | B1: AttackTree_ID | C1: AttackTree_Key | D1: Step | E1: Step_num | F1: Technique_ID | G1: Technique_Name | H1: Asset | I1: Pi | J1: Mi_Current | K1: Ci | L1: Qi_Current | M1: Qhat_i_Current | N1: Ri_Current | O1: Mi_Full | P1: Qhat_i_Full | Q1: Ri_Full | R1: Mi_Worst | S1: Qhat_i_Worst | T1: Ri_Worst | U1: Rtree_Current | V1: Rtree_Full | W1: Rtree_Worst | X1: Log_Ratio | Y1: Risk_Class | Z1: Risk_B_Flag | AA1: High_Mi_Flag | AB1: High_Qhat_Flag | AC1: Formula_Check
A2: A | B2: 1 | C2: A-001 | D2: S1 | E2: 1 | F2: T1078.004 | G2: Cloud Accounts | H2: Management Console for Business Server OnCloud | I2: 0.72 | J2: 0.1 | K2: 2 | L2: =I2*J2 -> 0.072 | M2: =MIN(1,I2*J2*K2) -> 0.144 | N2: =M2 -> 0.144 | O2: ='Settings '!$B$8 -> 0.1 | P2: =MIN(1,I2*O2*K2) -> 0.144 | Q2: =P2 -> 0.144 | R2: ='Settings '!$B$9 -> 0.9 | S2: =MIN(1,I2*R2*K2) -> 1 | T2: =S2 -> 1 | U2: =IF(E2=4,N2,"") | V2: =IF(E2=4,Q2,"") | W2: =IF(E2=4,T2,"") | X2: =IF(E2=4,IFERROR((LN(U2)-LN(V2))/(LN(W2)-LN(V2)),0),"") | Y2: =IF(E2=4,IF(X2>='Settings '!$B$7,"Risk A",IF(X2>='Settings '!$B$6,"Risk B","Risk C")),"") | Z2: =IF(Y2="Risk B",1,0) -> 0 | AA2: =IF(J2>='Settings '!$B$10,1,0) -> 0 | AB2: =IF(M2>='Settings '!$B$11,1,0) -> 0 | AC2: =ABS(M2-MIN(1,I2*J2*K2)) -> 0
A3: A | B3: 1 | C3: A-001 | D3: S2 | E3: 2 | F3: T1021.007 | G3: Cloud Services | H3: Update server OnCloud | I3: 0.36 | J3: 0.1 | K3: 1.5 | L3: =I3*J3 -> 0.036 | M3: =MIN(1,I3*J3*K3) -> 0.054 | N3: =N2*M3 -> 0.007776 | O3: ='Settings '!$B$8 -> 0.1 | P3: =MIN(1,I3*O3*K3) -> 0.054 | Q3: =Q2*P3 -> 0.007776 | R3: ='Settings '!$B$9 -> 0.9 | S3: =MIN(1,I3*R3*K3) -> 0.486 | T3: =T2*S3 -> 0.486 | U3: =IF(E3=4,N3,"") | V3: =IF(E3=4,Q3,"") | W3: =IF(E3=4,T3,"") | X3: =IF(E3=4,IFERROR((LN(U3)-LN(V3))/(LN(W3)-LN(V3)),0),"") | Y3: =IF(E3=4,IF(X3>='Settings '!$B$7,"Risk A",IF(X3>='Settings '!$B$6,"Risk B","Risk C")),"") | Z3: =IF(Y3="Risk B",1,0) -> 0 | AA3: =IF(J3>='Settings '!$B$10,1,0) -> 0 | AB3: =IF(M3>='Settings '!$B$11,1,0) -> 0 | AC3: =ABS(M3-MIN(1,I3*J3*K3)) -> 0
A4: A | B4: 1 | C4: A-001 | D4: S3 | E4: 3 | F4: T1484.002 | G4: Trust Modification | H4: Business Server OnCloud | I4: 0.36 | J4: 0.1 | K4: 2 | L4: =I4*J4 -> 0.036 | M4: =MIN(1,I4*J4*K4) -> 0.072 | N4: =N3*M4 -> 0.000559872 | O4: ='Settings '!$B$8 -> 0.1 | P4: =MIN(1,I4*O4*K4) -> 0.072 | Q4: =Q3*P4 -> 0.000559872 | R4: ='Settings '!$B$9 -> 0.9 | S4: =MIN(1,I4*R4*K4) -> 0.648 | T4: =T3*S4 -> 0.314928 | U4: =IF(E4=4,N4,"") | V4: =IF(E4=4,Q4,"") | W4: =IF(E4=4,T4,"") | X4: =IF(E4=4,IFERROR((LN(U4)-LN(V4))/(LN(W4)-LN(V4)),0),"") | Y4: =IF(E4=4,IF(X4>='Settings '!$B$7,"Risk A",IF(X4>='Settings '!$B$6,"Risk B","Risk C")),"") | Z4: =IF(Y4="Risk B",1,0) -> 0 | AA4: =IF(J4>='Settings '!$B$10,1,0) -> 0 | AB4: =IF(M4>='Settings '!$B$11,1,0) -> 0 | AC4: =ABS(M4-MIN(1,I4*J4*K4)) -> 0
A5: A | B5: 1 | C5: A-001 | D5: S4 | E5: 4 | F5: T1486 | G5: Data Encrypted for Impact | H5: Proxy server OnCloud | I5: 0.9 | J5: 0.1 | K5: 2 | L5: =I5*J5 -> 0.09 | M5: =MIN(1,I5*J5*K5) -> 0.18 | N5: =N4*M5 -> 0.00010077696 | O5: ='Settings '!$B$8 -> 0.1 | P5: =MIN(1,I5*O5*K5) -> 0.18 | Q5: =Q4*P5 -> 0.00010077696 | R5: ='Settings '!$B$9 -> 0.9 | S5: =MIN(1,I5*R5*K5) -> 1 | T5: =T4*S5 -> 0.314928 | U5: =IF(E5=4,N5,"") -> 0.00010077696 | V5: =IF(E5=4,Q5,"") -> 0.00010077696 | W5: =IF(E5=4,T5,"") -> 0.314928 | X5: =IF(E5=4,IFERROR((LN(U5)-LN(V5))/(LN(W5)-LN(V5)),0),"") -> 0 | Y5: =IF(E5=4,IF(X5>='Settings '!$B$7,"Risk A",IF(X5>='Settings '!$B$6,"Risk B","Risk C")),"") -> Risk C | Z5: =IF(Y5="Risk B",1,0) -> 0 | AA5: =IF(J5>='Settings '!$B$10,1,0) -> 0 | AB5: =IF(M5>='Settings '!$B$11,1,0) -> 0 | AC5: =ABS(M5-MIN(1,I5*J5*K5)) -> 0
A6: A | B6: 2 | C6: A-002 | D6: S1 | E6: 1 | F6: T1078.004 | G6: Cloud Accounts | H6: Management Console for Business Server OnCloud | I6: 0.72 | J6: 0.1 | K6: 2 | L6: =I6*J6 -> 0.072 | M6: =MIN(1,I6*J6*K6) -> 0.144 | N6: =M6 -> 0.144 | O6: ='Settings '!$B$8 -> 0.1 | P6: =MIN(1,I6*O6*K6) -> 0.144 | Q6: =P6 -> 0.144 | R6: ='Settings '!$B$9 -> 0.9 | S6: =MIN(1,I6*R6*K6) -> 1 | T6: =S6 -> 1 | U6: =IF(E6=4,N6,"") | V6: =IF(E6=4,Q6,"") | W6: =IF(E6=4,T6,"") | X6: =IF(E6=4,IFERROR((LN(U6)-LN(V6))/(LN(W6)-LN(V6)),0),"") | Y6: =IF(E6=4,IF(X6>='Settings '!$B$7,"Risk A",IF(X6>='Settings '!$B$6,"Risk B","Risk C")),"") | Z6: =IF(Y6="Risk B",1,0) -> 0 | AA6: =IF(J6>='Settings '!$B$10,1,0) -> 0 | AB6: =IF(M6>='Settings '!$B$11,1,0) -> 0 | AC6: =ABS(M6-MIN(1,I6*J6*K6)) -> 0
A7: A | B7: 2 | C7: A-002 | D7: S2 | E7: 2 | F7: T1021.007 | G7: Cloud Services | H7: Update server OnCloud | I7: 0.36 | J7: 0.1 | K7: 1.5 | L7: =I7*J7 -> 0.036 | M7: =MIN(1,I7*J7*K7) -> 0.054 | N7: =N6*M7 -> 0.007776 | O7: ='Settings '!$B$8 -> 0.1 | P7: =MIN(1,I7*O7*K7) -> 0.054 | Q7: =Q6*P7 -> 0.007776 | R7: ='Settings '!$B$9 -> 0.9 | S7: =MIN(1,I7*R7*K7) -> 0.486 | T7: =T6*S7 -> 0.486 | U7: =IF(E7=4,N7,"") | V7: =IF(E7=4,Q7,"") | W7: =IF(E7=4,T7,"") | X7: =IF(E7=4,IFERROR((LN(U7)-LN(V7))/(LN(W7)-LN(V7)),0),"") | Y7: =IF(E7=4,IF(X7>='Settings '!$B$7,"Risk A",IF(X7>='Settings '!$B$6,"Risk B","Risk C")),"") | Z7: =IF(Y7="Risk B",1,0) -> 0 | AA7: =IF(J7>='Settings '!$B$10,1,0) -> 0 | AB7: =IF(M7>='Settings '!$B$11,1,0) -> 0 | AC7: =ABS(M7-MIN(1,I7*J7*K7)) -> 0
A8: A | B8: 2 | C8: A-002 | D8: S3 | E8: 3 | F8: T1484.002 | G8: Trust Modification | H8: Business Server OnCloud | I8: 0.36 | J8: 0.1 | K8: 2 | L8: =I8*J8 -> 0.036 | M8: =MIN(1,I8*J8*K8) -> 0.072 | N8: =N7*M8 -> 0.000559872 | O8: ='Settings '!$B$8 -> 0.1 | P8: =MIN(1,I8*O8*K8) -> 0.072 | Q8: =Q7*P8 -> 0.000559872 | R8: ='Settings '!$B$9 -> 0.9 | S8: =MIN(1,I8*R8*K8) -> 0.648 | T8: =T7*S8 -> 0.314928 | U8: =IF(E8=4,N8,"") | V8: =IF(E8=4,Q8,"") | W8: =IF(E8=4,T8,"") | X8: =IF(E8=4,IFERROR((LN(U8)-LN(V8))/(LN(W8)-LN(V8)),0),"") | Y8: =IF(E8=4,IF(X8>='Settings '!$B$7,"Risk A",IF(X8>='Settings '!$B$6,"Risk B","Risk C")),"") | Z8: =IF(Y8="Risk B",1,0) -> 0 | AA8: =IF(J8>='Settings '!$B$10,1,0) -> 0 | AB8: =IF(M8>='Settings '!$B$11,1,0) -> 0 | AC8: =ABS(M8-MIN(1,I8*J8*K8)) -> 0
A9: A | B9: 2 | C9: A-002 | D9: S4 | E9: 4 | F9: T1496.001 | G9: Compute Hijacking | H9: Proxy server OnCloud | I9: 0.72 | J9: 0.28 | K9: 2 | L9: =I9*J9 -> 0.2016 | M9: =MIN(1,I9*J9*K9) -> 0.4032 | N9: =N8*M9 -> 0.00022574039 | O9: ='Settings '!$B$8 -> 0.1 | P9: =MIN(1,I9*O9*K9) -> 0.144 | Q9: =Q8*P9 -> 8.0621568e-05 | R9: ='Settings '!$B$9 -> 0.9 | S9: =MIN(1,I9*R9*K9) -> 1 | T9: =T8*S9 -> 0.314928 | U9: =IF(E9=4,N9,"") -> 0.00022574039 | V9: =IF(E9=4,Q9,"") -> 8.0621568e-05 | W9: =IF(E9=4,T9,"") -> 0.314928 | X9: =IF(E9=4,IFERROR((LN(U9)-LN(V9))/(LN(W9)-LN(V9)),0),"") -> 0.12449552 | Y9: =IF(E9=4,IF(X9>='Settings '!$B$7,"Risk A",IF(X9>='Settings '!$B$6,"Risk B","Risk C")),"") -> Risk C | Z9: =IF(Y9="Risk B",1,0) -> 0 | AA9: =IF(J9>='Settings '!$B$10,1,0) -> 1 | AB9: =IF(M9>='Settings '!$B$11,1,0) -> 1 | AC9: =ABS(M9-MIN(1,I9*J9*K9)) -> 0
A10: A | B10: 3 | C10: A-003 | D10: S1 | E10: 1 | F10: T1078.004 | G10: Cloud Accounts | H10: Management Console for Business Server OnCloud | I10: 0.72 | J10: 0.1 | K10: 2 | L10: =I10*J10 -> 0.072 | M10: =MIN(1,I10*J10*K10) -> 0.144 | N10: =M10 -> 0.144 | O10: ='Settings '!$B$8 -> 0.1 | P10: =MIN(1,I10*O10*K10) -> 0.144 | Q10: =P10 -> 0.144 | R10: ='Settings '!$B$9 -> 0.9 | S10: =MIN(1,I10*R10*K10) -> 1 | T10: =S10 -> 1 | U10: =IF(E10=4,N10,"") | V10: =IF(E10=4,Q10,"") | W10: =IF(E10=4,T10,"") | X10: =IF(E10=4,IFERROR((LN(U10)-LN(V10))/(LN(W10)-LN(V10)),0),"") | Y10: =IF(E10=4,IF(X10>='Settings '!$B$7,"Risk A",IF(X10>='Settings '!$B$6,"Risk B","Risk C")),"") | Z10: =IF(Y10="Risk B",1,0) -> 0 | AA10: =IF(J10>='Settings '!$B$10,1,0) -> 0 | AB10: =IF(M10>='Settings '!$B$11,1,0) -> 0 | AC10: =ABS(M10-MIN(1,I10*J10*K10)) -> 0
A11: A | B11: 3 | C11: A-003 | D11: S2 | E11: 2 | F11: T1021.007 | G11: Cloud Services | H11: Update server OnCloud | I11: 0.36 | J11: 0.1 | K11: 1.5 | L11: =I11*J11 -> 0.036 | M11: =MIN(1,I11*J11*K11) -> 0.054 | N11: =N10*M11 -> 0.007776 | O11: ='Settings '!$B$8 -> 0.1 | P11: =MIN(1,I11*O11*K11) -> 0.054 | Q11: =Q10*P11 -> 0.007776 | R11: ='Settings '!$B$9 -> 0.9 | S11: =MIN(1,I11*R11*K11) -> 0.486 | T11: =T10*S11 -> 0.486 | U11: =IF(E11=4,N11,"") | V11: =IF(E11=4,Q11,"") | W11: =IF(E11=4,T11,"") | X11: =IF(E11=4,IFERROR((LN(U11)-LN(V11))/(LN(W11)-LN(V11)),0),"") | Y11: =IF(E11=4,IF(X11>='Settings '!$B$7,"Risk A",IF(X11>='Settings '!$B$6,"Risk B","Risk C")),"") | Z11: =IF(Y11="Risk B",1,0) -> 0 | AA11: =IF(J11>='Settings '!$B$10,1,0) -> 0 | AB11: =IF(M11>='Settings '!$B$11,1,0) -> 0 | AC11: =ABS(M11-MIN(1,I11*J11*K11)) -> 0
A12: A | B12: 3 | C12: A-003 | D12: S3 | E12: 3 | F12: T1484.002 | G12: Trust Modification | H12: Business Server OnCloud | I12: 0.36 | J12: 0.1 | K12: 2 | L12: =I12*J12 -> 0.036 | M12: =MIN(1,I12*J12*K12) -> 0.072 | N12: =N11*M12 -> 0.000559872 | O12: ='Settings '!$B$8 -> 0.1 | P12: =MIN(1,I12*O12*K12) -> 0.072 | Q12: =Q11*P12 -> 0.000559872 | R12: ='Settings '!$B$9 -> 0.9 | S12: =MIN(1,I12*R12*K12) -> 0.648 | T12: =T11*S12 -> 0.314928 | U12: =IF(E12=4,N12,"") | V12: =IF(E12=4,Q12,"") | W12: =IF(E12=4,T12,"") | X12: =IF(E12=4,IFERROR((LN(U12)-LN(V12))/(LN(W12)-LN(V12)),0),"") | Y12: =IF(E12=4,IF(X12>='Settings '!$B$7,"Risk A",IF(X12>='Settings '!$B$6,"Risk B","Risk C")),"") | Z12: =IF(Y12="Risk B",1,0) -> 0 | AA12: =IF(J12>='Settings '!$B$10,1,0) -> 0 | AB12: =IF(M12>='Settings '!$B$11,1,0) -> 0 | AC12: =ABS(M12-MIN(1,I12*J12*K12)) -> 0
A13: A | B13: 3 | C13: A-003 | D13: S4 | E13: 4 | F13: T1496.002 | G13: Bandwidth Hijacking | H13: Proxy server OnCloud | I13: 0.18 | J13: 0.28 | K13: 2 | L13: =I13*J13 -> 0.0504 | M13: =MIN(1,I13*J13*K13) -> 0.1008 | N13: =N12*M13 -> 5.6435098e-05 | O13: ='Settings '!$B$8 -> 0.1 | P13: =MIN(1,I13*O13*K13) -> 0.036 | Q13: =Q12*P13 -> 2.0155392e-05 | R13: ='Settings '!$B$9 -> 0.9 | S13: =MIN(1,I13*R13*K13) -> 0.324 | T13: =T12*S13 -> 0.10203667 | U13: =IF(E13=4,N13,"") -> 5.6435098e-05 | V13: =IF(E13=4,Q13,"") -> 2.0155392e-05 | W13: =IF(E13=4,T13,"") -> 0.10203667 | X13: =IF(E13=4,IFERROR((LN(U13)-LN(V13))/(LN(W13)-LN(V13)),0),"") -> 0.12071111 | Y13: =IF(E13=4,IF(X13>='Settings '!$B$7,"Risk A",IF(X13>='Settings '!$B$6,"Risk B","Risk C")),"") -> Risk C | Z13: =IF(Y13="Risk B",1,0) -> 0 | AA13: =IF(J13>='Settings '!$B$10,1,0) -> 1 | AB13: =IF(M13>='Settings '!$B$11,1,0) -> 0 | AC13: =ABS(M13-MIN(1,I13*J13*K13)) -> 0
A14: A | B14: 4 | C14: A-004 | D14: S1 | E14: 1 | F14: T1078.004 | G14: Cloud Accounts | H14: Management Console for Business Server OnCloud | I14: 0.72 | J14: 0.1 | K14: 2 | L14: =I14*J14 -> 0.072 | M14: =MIN(1,I14*J14*K14) -> 0.144 | N14: =M14 -> 0.144 | O14: ='Settings '!$B$8 -> 0.1 | P14: =MIN(1,I14*O14*K14) -> 0.144 | Q14: =P14 -> 0.144 | R14: ='Settings '!$B$9 -> 0.9 | S14: =MIN(1,I14*R14*K14) -> 1 | T14: =S14 -> 1 | U14: =IF(E14=4,N14,"") | V14: =IF(E14=4,Q14,"") | W14: =IF(E14=4,T14,"") | X14: =IF(E14=4,IFERROR((LN(U14)-LN(V14))/(LN(W14)-LN(V14)),0),"") | Y14: =IF(E14=4,IF(X14>='Settings '!$B$7,"Risk A",IF(X14>='Settings '!$B$6,"Risk B","Risk C")),"") | Z14: =IF(Y14="Risk B",1,0) -> 0 | AA14: =IF(J14>='Settings '!$B$10,1,0) -> 0 | AB14: =IF(M14>='Settings '!$B$11,1,0) -> 0 | AC14: =ABS(M14-MIN(1,I14*J14*K14)) -> 0
A15: A | B15: 4 | C15: A-004 | D15: S2 | E15: 2 | F15: T1021.007 | G15: Cloud Services | H15: Update server OnCloud | I15: 0.36 | J15: 0.1 | K15: 1.5 | L15: =I15*J15 -> 0.036 | M15: =MIN(1,I15*J15*K15) -> 0.054 | N15: =N14*M15 -> 0.007776 | O15: ='Settings '!$B$8 -> 0.1 | P15: =MIN(1,I15*O15*K15) -> 0.054 | Q15: =Q14*P15 -> 0.007776 | R15: ='Settings '!$B$9 -> 0.9 | S15: =MIN(1,I15*R15*K15) -> 0.486 | T15: =T14*S15 -> 0.486 | U15: =IF(E15=4,N15,"") | V15: =IF(E15=4,Q15,"") | W15: =IF(E15=4,T15,"") | X15: =IF(E15=4,IFERROR((LN(U15)-LN(V15))/(LN(W15)-LN(V15)),0),"") | Y15: =IF(E15=4,IF(X15>='Settings '!$B$7,"Risk A",IF(X15>='Settings '!$B$6,"Risk B","Risk C")),"") | Z15: =IF(Y15="Risk B",1,0) -> 0 | AA15: =IF(J15>='Settings '!$B$10,1,0) -> 0 | AB15: =IF(M15>='Settings '!$B$11,1,0) -> 0 | AC15: =ABS(M15-MIN(1,I15*J15*K15)) -> 0
A16: A | B16: 4 | C16: A-004 | D16: S3 | E16: 3 | F16: T1484.002 | G16: Trust Modification | H16: Business Server OnCloud | I16: 0.36 | J16: 0.1 | K16: 2 | L16: =I16*J16 -> 0.036 | M16: =MIN(1,I16*J16*K16) -> 0.072 | N16: =N15*M16 -> 0.000559872 | O16: ='Settings '!$B$8 -> 0.1 | P16: =MIN(1,I16*O16*K16) -> 0.072 | Q16: =Q15*P16 -> 0.000559872 | R16: ='Settings '!$B$9 -> 0.9 | S16: =MIN(1,I16*R16*K16) -> 0.648 | T16: =T15*S16 -> 0.314928 | U16: =IF(E16=4,N16,"") | V16: =IF(E16=4,Q16,"") | W16: =IF(E16=4,T16,"") | X16: =IF(E16=4,IFERROR((LN(U16)-LN(V16))/(LN(W16)-LN(V16)),0),"") | Y16: =IF(E16=4,IF(X16>='Settings '!$B$7,"Risk A",IF(X16>='Settings '!$B$6,"Risk B","Risk C")),"") | Z16: =IF(Y16="Risk B",1,0) -> 0 | AA16: =IF(J16>='Settings '!$B$10,1,0) -> 0 | AB16: =IF(M16>='Settings '!$B$11,1,0) -> 0 | AC16: =ABS(M16-MIN(1,I16*J16*K16)) -> 0
A17: A | B17: 4 | C17: A-004 | D17: S4 | E17: 4 | F17: T1496.004 | G17: Cloud Service Hijacking | H17: Proxy server OnCloud | I17: 0.18 | J17: 0.28 | K17: 2 | L17: =I17*J17 -> 0.0504 | M17: =MIN(1,I17*J17*K17) -> 0.1008 | N17: =N16*M17 -> 5.6435098e-05 | O17: ='Settings '!$B$8 -> 0.1 | P17: =MIN(1,I17*O17*K17) -> 0.036 | Q17: =Q16*P17 -> 2.0155392e-05 | R17: ='Settings '!$B$9 -> 0.9 | S17: =MIN(1,I17*R17*K17) -> 0.324 | T17: =T16*S17 -> 0.10203667 | U17: =IF(E17=4,N17,"") -> 5.6435098e-05 | V17: =IF(E17=4,Q17,"") -> 2.0155392e-05 | W17: =IF(E17=4,T17,"") -> 0.10203667 | X17: =IF(E17=4,IFERROR((LN(U17)-LN(V17))/(LN(W17)-LN(V17)),0),"") -> 0.12071111 | Y17: =IF(E17=4,IF(X17>='Settings '!$B$7,"Risk A",IF(X17>='Settings '!$B$6,"Risk B","Risk C")),"") -> Risk C | Z17: =IF(Y17="Risk B",1,0) -> 0 | AA17: =IF(J17>='Settings '!$B$10,1,0) -> 1 | AB17: =IF(M17>='Settings '!$B$11,1,0) -> 0 | AC17: =ABS(M17-MIN(1,I17*J17*K17)) -> 0
A18: A | B18: 5 | C18: A-005 | D18: S1 | E18: 1 | F18: T1078.004 | G18: Cloud Accounts | H18: Management Console for Business Server OnCloud | I18: 0.72 | J18: 0.1 | K18: 2 | L18: =I18*J18 -> 0.072 | M18: =MIN(1,I18*J18*K18) -> 0.144 | N18: =M18 -> 0.144 | O18: ='Settings '!$B$8 -> 0.1 | P18: =MIN(1,I18*O18*K18) -> 0.144 | Q18: =P18 -> 0.144 | R18: ='Settings '!$B$9 -> 0.9 | S18: =MIN(1,I18*R18*K18) -> 1 | T18: =S18 -> 1 | U18: =IF(E18=4,N18,"") | V18: =IF(E18=4,Q18,"") | W18: =IF(E18=4,T18,"") | X18: =IF(E18=4,IFERROR((LN(U18)-LN(V18))/(LN(W18)-LN(V18)),0),"") | Y18: =IF(E18=4,IF(X18>='Settings '!$B$7,"Risk A",IF(X18>='Settings '!$B$6,"Risk B","Risk C")),"") | Z18: =IF(Y18="Risk B",1,0) -> 0 | AA18: =IF(J18>='Settings '!$B$10,1,0) -> 0 | AB18: =IF(M18>='Settings '!$B$11,1,0) -> 0 | AC18: =ABS(M18-MIN(1,I18*J18*K18)) -> 0
A19: A | B19: 5 | C19: A-005 | D19: S2 | E19: 2 | F19: T1021.007 | G19: Cloud Services | H19: Update server OnCloud | I19: 0.36 | J19: 0.1 | K19: 1.5 | L19: =I19*J19 -> 0.036 | M19: =MIN(1,I19*J19*K19) -> 0.054 | N19: =N18*M19 -> 0.007776 | O19: ='Settings '!$B$8 -> 0.1 | P19: =MIN(1,I19*O19*K19) -> 0.054 | Q19: =Q18*P19 -> 0.007776 | R19: ='Settings '!$B$9 -> 0.9 | S19: =MIN(1,I19*R19*K19) -> 0.486 | T19: =T18*S19 -> 0.486 | U19: =IF(E19=4,N19,"") | V19: =IF(E19=4,Q19,"") | W19: =IF(E19=4,T19,"") | X19: =IF(E19=4,IFERROR((LN(U19)-LN(V19))/(LN(W19)-LN(V19)),0),"") | Y19: =IF(E19=4,IF(X19>='Settings '!$B$7,"Risk A",IF(X19>='Settings '!$B$6,"Risk B","Risk C")),"") | Z19: =IF(Y19="Risk B",1,0) -> 0 | AA19: =IF(J19>='Settings '!$B$10,1,0) -> 0 | AB19: =IF(M19>='Settings '!$B$11,1,0) -> 0 | AC19: =ABS(M19-MIN(1,I19*J19*K19)) -> 0
A20: A | B20: 5 | C20: A-005 | D20: S3 | E20: 3 | F20: T1059.009 | G20: Cloud API | H20: Business Server OnCloud | I20: 0.36 | J20: 0.1 | K20: 2 | L20: =I20*J20 -> 0.036 | M20: =MIN(1,I20*J20*K20) -> 0.072 | N20: =N19*M20 -> 0.000559872 | O20: ='Settings '!$B$8 -> 0.1 | P20: =MIN(1,I20*O20*K20) -> 0.072 | Q20: =Q19*P20 -> 0.000559872 | R20: ='Settings '!$B$9 -> 0.9 | S20: =MIN(1,I20*R20*K20) -> 0.648 | T20: =T19*S20 -> 0.314928 | U20: =IF(E20=4,N20,"") | V20: =IF(E20=4,Q20,"") | W20: =IF(E20=4,T20,"") | X20: =IF(E20=4,IFERROR((LN(U20)-LN(V20))/(LN(W20)-LN(V20)),0),"") | Y20: =IF(E20=4,IF(X20>='Settings '!$B$7,"Risk A",IF(X20>='Settings '!$B$6,"Risk B","Risk C")),"") | Z20: =IF(Y20="Risk B",1,0) -> 0 | AA20: =IF(J20>='Settings '!$B$10,1,0) -> 0 | AB20: =IF(M20>='Settings '!$B$11,1,0) -> 0 | AC20: =ABS(M20-MIN(1,I20*J20*K20)) -> 0
A21: A | B21: 5 | C21: A-005 | D21: S4 | E21: 4 | F21: T1486 | G21: Data Encrypted for Impact | H21: Proxy server OnCloud | I21: 0.9 | J21: 0.1 | K21: 2 | L21: =I21*J21 -> 0.09 | M21: =MIN(1,I21*J21*K21) -> 0.18 | N21: =N20*M21 -> 0.00010077696 | O21: ='Settings '!$B$8 -> 0.1 | P21: =MIN(1,I21*O21*K21) -> 0.18 | Q21: =Q20*P21 -> 0.00010077696 | R21: ='Settings '!$B$9 -> 0.9 | S21: =MIN(1,I21*R21*K21) -> 1 | T21: =T20*S21 -> 0.314928 | U21: =IF(E21=4,N21,"") -> 0.00010077696 | V21: =IF(E21=4,Q21,"") -> 0.00010077696 | W21: =IF(E21=4,T21,"") -> 0.314928 | X21: =IF(E21=4,IFERROR((LN(U21)-LN(V21))/(LN(W21)-LN(V21)),0),"") -> 0 | Y21: =IF(E21=4,IF(X21>='Settings '!$B$7,"Risk A",IF(X21>='Settings '!$B$6,"Risk B","Risk C")),"") -> Risk C | Z21: =IF(Y21="Risk B",1,0) -> 0 | AA21: =IF(J21>='Settings '!$B$10,1,0) -> 0 | AB21: =IF(M21>='Settings '!$B$11,1,0) -> 0 | AC21: =ABS(M21-MIN(1,I21*J21*K21)) -> 0
A22: A | B22: 6 | C22: A-006 | D22: S1 | E22: 1 | F22: T1078.004 | G22: Cloud Accounts | H22: Management Console for Business Server OnCloud | I22: 0.72 | J22: 0.1 | K22: 2 | L22: =I22*J22 -> 0.072 | M22: =MIN(1,I22*J22*K22) -> 0.144 | N22: =M22 -> 0.144 | O22: ='Settings '!$B$8 -> 0.1 | P22: =MIN(1,I22*O22*K22) -> 0.144 | Q22: =P22 -> 0.144 | R22: ='Settings '!$B$9 -> 0.9 | S22: =MIN(1,I22*R22*K22) -> 1 | T22: =S22 -> 1 | U22: =IF(E22=4,N22,"") | V22: =IF(E22=4,Q22,"") | W22: =IF(E22=4,T22,"") | X22: =IF(E22=4,IFERROR((LN(U22)-LN(V22))/(LN(W22)-LN(V22)),0),"") | Y22: =IF(E22=4,IF(X22>='Settings '!$B$7,"Risk A",IF(X22>='Settings '!$B$6,"Risk B","Risk C")),"") | Z22: =IF(Y22="Risk B",1,0) -> 0 | AA22: =IF(J22>='Settings '!$B$10,1,0) -> 0 | AB22: =IF(M22>='Settings '!$B$11,1,0) -> 0 | AC22: =ABS(M22-MIN(1,I22*J22*K22)) -> 0
A23: A | B23: 6 | C23: A-006 | D23: S2 | E23: 2 | F23: T1021.007 | G23: Cloud Services | H23: Update server OnCloud | I23: 0.36 | J23: 0.1 | K23: 1.5 | L23: =I23*J23 -> 0.036 | M23: =MIN(1,I23*J23*K23) -> 0.054 | N23: =N22*M23 -> 0.007776 | O23: ='Settings '!$B$8 -> 0.1 | P23: =MIN(1,I23*O23*K23) -> 0.054 | Q23: =Q22*P23 -> 0.007776 | R23: ='Settings '!$B$9 -> 0.9 | S23: =MIN(1,I23*R23*K23) -> 0.486 | T23: =T22*S23 -> 0.486 | U23: =IF(E23=4,N23,"") | V23: =IF(E23=4,Q23,"") | W23: =IF(E23=4,T23,"") | X23: =IF(E23=4,IFERROR((LN(U23)-LN(V23))/(LN(W23)-LN(V23)),0),"") | Y23: =IF(E23=4,IF(X23>='Settings '!$B$7,"Risk A",IF(X23>='Settings '!$B$6,"Risk B","Risk C")),"") | Z23: =IF(Y23="Risk B",1,0) -> 0 | AA23: =IF(J23>='Settings '!$B$10,1,0) -> 0 | AB23: =IF(M23>='Settings '!$B$11,1,0) -> 0 | AC23: =ABS(M23-MIN(1,I23*J23*K23)) -> 0
A24: A | B24: 6 | C24: A-006 | D24: S3 | E24: 3 | F24: T1059.009 | G24: Cloud API | H24: Business Server OnCloud | I24: 0.36 | J24: 0.1 | K24: 2 | L24: =I24*J24 -> 0.036 | M24: =MIN(1,I24*J24*K24) -> 0.072 | N24: =N23*M24 -> 0.000559872 | O24: ='Settings '!$B$8 -> 0.1 | P24: =MIN(1,I24*O24*K24) -> 0.072 | Q24: =Q23*P24 -> 0.000559872 | R24: ='Settings '!$B$9 -> 0.9 | S24: =MIN(1,I24*R24*K24) -> 0.648 | T24: =T23*S24 -> 0.314928 | U24: =IF(E24=4,N24,"") | V24: =IF(E24=4,Q24,"") | W24: =IF(E24=4,T24,"") | X24: =IF(E24=4,IFERROR((LN(U24)-LN(V24))/(LN(W24)-LN(V24)),0),"") | Y24: =IF(E24=4,IF(X24>='Settings '!$B$7,"Risk A",IF(X24>='Settings '!$B$6,"Risk B","Risk C")),"") | Z24: =IF(Y24="Risk B",1,0) -> 0 | AA24: =IF(J24>='Settings '!$B$10,1,0) -> 0 | AB24: =IF(M24>='Settings '!$B$11,1,0) -> 0 | AC24: =ABS(M24-MIN(1,I24*J24*K24)) -> 0
A25: A | B25: 6 | C25: A-006 | D25: S4 | E25: 4 | F25: T1496.001 | G25: Compute Hijacking | H25: Proxy server OnCloud | I25: 0.72 | J25: 0.28 | K25: 2 | L25: =I25*J25 -> 0.2016 | M25: =MIN(1,I25*J25*K25) -> 0.4032 | N25: =N24*M25 -> 0.00022574039 | O25: ='Settings '!$B$8 -> 0.1 | P25: =MIN(1,I25*O25*K25) -> 0.144 | Q25: =Q24*P25 -> 8.0621568e-05 | R25: ='Settings '!$B$9 -> 0.9 | S25: =MIN(1,I25*R25*K25) -> 1 | T25: =T24*S25 -> 0.314928 | U25: =IF(E25=4,N25,"") -> 0.00022574039 | V25: =IF(E25=4,Q25,"") -> 8.0621568e-05 | W25: =IF(E25=4,T25,"") -> 0.314928 | X25: =IF(E25=4,IFERROR((LN(U25)-LN(V25))/(LN(W25)-LN(V25)),0),"") -> 0.12449552 | Y25: =IF(E25=4,IF(X25>='Settings '!$B$7,"Risk A",IF(X25>='Settings '!$B$6,"Risk B","Risk C")),"") -> Risk C | Z25: =IF(Y25="Risk B",1,0) -> 0 | AA25: =IF(J25>='Settings '!$B$10,1,0) -> 1 | AB25: =IF(M25>='Settings '!$B$11,1,0) -> 1 | AC25: =ABS(M25-MIN(1,I25*J25*K25)) -> 0
A26: A | B26: 7 | C26: A-007 | D26: S1 | E26: 1 | F26: T1078.004 | G26: Cloud Accounts | H26: Management Console for Business Server OnCloud | I26: 0.72 | J26: 0.1 | K26: 2 | L26: =I26*J26 -> 0.072 | M26: =MIN(1,I26*J26*K26) -> 0.144 | N26: =M26 -> 0.144 | O26: ='Settings '!$B$8 -> 0.1 | P26: =MIN(1,I26*O26*K26) -> 0.144 | Q26: =P26 -> 0.144 | R26: ='Settings '!$B$9 -> 0.9 | S26: =MIN(1,I26*R26*K26) -> 1 | T26: =S26 -> 1 | U26: =IF(E26=4,N26,"") | V26: =IF(E26=4,Q26,"") | W26: =IF(E26=4,T26,"") | X26: =IF(E26=4,IFERROR((LN(U26)-LN(V26))/(LN(W26)-LN(V26)),0),"") | Y26: =IF(E26=4,IF(X26>='Settings '!$B$7,"Risk A",IF(X26>='Settings '!$B$6,"Risk B","Risk C")),"") | Z26: =IF(Y26="Risk B",1,0) -> 0 | AA26: =IF(J26>='Settings '!$B$10,1,0) -> 0 | AB26: =IF(M26>='Settings '!$B$11,1,0) -> 0 | AC26: =ABS(M26-MIN(1,I26*J26*K26)) -> 0
A27: A | B27: 7 | C27: A-007 | D27: S2 | E27: 2 | F27: T1021.007 | G27: Cloud Services | H27: Update server OnCloud | I27: 0.36 | J27: 0.1 | K27: 1.5 | L27: =I27*J27 -> 0.036 | M27: =MIN(1,I27*J27*K27) -> 0.054 | N27: =N26*M27 -> 0.007776 | O27: ='Settings '!$B$8 -> 0.1 | P27: =MIN(1,I27*O27*K27) -> 0.054 | Q27: =Q26*P27 -> 0.007776 | R27: ='Settings '!$B$9 -> 0.9 | S27: =MIN(1,I27*R27*K27) -> 0.486 | T27: =T26*S27 -> 0.486 | U27: =IF(E27=4,N27,"") | V27: =IF(E27=4,Q27,"") | W27: =IF(E27=4,T27,"") | X27: =IF(E27=4,IFERROR((LN(U27)-LN(V27))/(LN(W27)-LN(V27)),0),"") | Y27: =IF(E27=4,IF(X27>='Settings '!$B$7,"Risk A",IF(X27>='Settings '!$B$6,"Risk B","Risk C")),"") | Z27: =IF(Y27="Risk B",1,0) -> 0 | AA27: =IF(J27>='Settings '!$B$10,1,0) -> 0 | AB27: =IF(M27>='Settings '!$B$11,1,0) -> 0 | AC27: =ABS(M27-MIN(1,I27*J27*K27)) -> 0
A28: A | B28: 7 | C28: A-007 | D28: S3 | E28: 3 | F28: T1059.009 | G28: Cloud API | H28: Business Server OnCloud | I28: 0.36 | J28: 0.1 | K28: 2 | L28: =I28*J28 -> 0.036 | M28: =MIN(1,I28*J28*K28) -> 0.072 | N28: =N27*M28 -> 0.000559872 | O28: ='Settings '!$B$8 -> 0.1 | P28: =MIN(1,I28*O28*K28) -> 0.072 | Q28: =Q27*P28 -> 0.000559872 | R28: ='Settings '!$B$9 -> 0.9 | S28: =MIN(1,I28*R28*K28) -> 0.648 | T28: =T27*S28 -> 0.314928 | U28: =IF(E28=4,N28,"") | V28: =IF(E28=4,Q28,"") | W28: =IF(E28=4,T28,"") | X28: =IF(E28=4,IFERROR((LN(U28)-LN(V28))/(LN(W28)-LN(V28)),0),"") | Y28: =IF(E28=4,IF(X28>='Settings '!$B$7,"Risk A",IF(X28>='Settings '!$B$6,"Risk B","Risk C")),"") | Z28: =IF(Y28="Risk B",1,0) -> 0 | AA28: =IF(J28>='Settings '!$B$10,1,0) -> 0 | AB28: =IF(M28>='Settings '!$B$11,1,0) -> 0 | AC28: =ABS(M28-MIN(1,I28*J28*K28)) -> 0
A29: A | B29: 7 | C29: A-007 | D29: S4 | E29: 4 | F29: T1496.002 | G29: Bandwidth Hijacking | H29: Proxy server OnCloud | I29: 0.18 | J29: 0.28 | K29: 2 | L29: =I29*J29 -> 0.0504 | M29: =MIN(1,I29*J29*K29) -> 0.1008 | N29: =N28*M29 -> 5.6435098e-05 | O29: ='Settings '!$B$8 -> 0.1 | P29: =MIN(1,I29*O29*K29) -> 0.036 | Q29: =Q28*P29 -> 2.0155392e-05 | R29: ='Settings '!$B$9 -> 0.9 | S29: =MIN(1,I29*R29*K29) -> 0.324 | T29: =T28*S29 -> 0.10203667 | U29: =IF(E29=4,N29,"") -> 5.6435098e-05 | V29: =IF(E29=4,Q29,"") -> 2.0155392e-05 | W29: =IF(E29=4,T29,"") -> 0.10203667 | X29: =IF(E29=4,IFERROR((LN(U29)-LN(V29))/(LN(W29)-LN(V29)),0),"") -> 0.12071111 | Y29: =IF(E29=4,IF(X29>='Settings '!$B$7,"Risk A",IF(X29>='Settings '!$B$6,"Risk B","Risk C")),"") -> Risk C | Z29: =IF(Y29="Risk B",1,0) -> 0 | AA29: =IF(J29>='Settings '!$B$10,1,0) -> 1 | AB29: =IF(M29>='Settings '!$B$11,1,0) -> 0 | AC29: =ABS(M29-MIN(1,I29*J29*K29)) -> 0
A30: A | B30: 8 | C30: A-008 | D30: S1 | E30: 1 | F30: T1078.004 | G30: Cloud Accounts | H30: Management Console for Business Server OnCloud | I30: 0.72 | J30: 0.1 | K30: 2 | L30: =I30*J30 -> 0.072 | M30: =MIN(1,I30*J30*K30) -> 0.144 | N30: =M30 -> 0.144 | O30: ='Settings '!$B$8 -> 0.1 | P30: =MIN(1,I30*O30*K30) -> 0.144 | Q30: =P30 -> 0.144 | R30: ='Settings '!$B$9 -> 0.9 | S30: =MIN(1,I30*R30*K30) -> 1 | T30: =S30 -> 1 | U30: =IF(E30=4,N30,"") | V30: =IF(E30=4,Q30,"") | W30: =IF(E30=4,T30,"") | X30: =IF(E30=4,IFERROR((LN(U30)-LN(V30))/(LN(W30)-LN(V30)),0),"") | Y30: =IF(E30=4,IF(X30>='Settings '!$B$7,"Risk A",IF(X30>='Settings '!$B$6,"Risk B","Risk C")),"") | Z30: =IF(Y30="Risk B",1,0) -> 0 | AA30: =IF(J30>='Settings '!$B$10,1,0) -> 0 | AB30: =IF(M30>='Settings '!$B$11,1,0) -> 0 | AC30: =ABS(M30-MIN(1,I30*J30*K30)) -> 0
A31: A | B31: 8 | C31: A-008 | D31: S2 | E31: 2 | F31: T1021.007 | G31: Cloud Services | H31: Update server OnCloud | I31: 0.36 | J31: 0.1 | K31: 1.5 | L31: =I31*J31 -> 0.036 | M31: =MIN(1,I31*J31*K31) -> 0.054 | N31: =N30*M31 -> 0.007776 | O31: ='Settings '!$B$8 -> 0.1 | P31: =MIN(1,I31*O31*K31) -> 0.054 | Q31: =Q30*P31 -> 0.007776 | R31: ='Settings '!$B$9 -> 0.9 | S31: =MIN(1,I31*R31*K31) -> 0.486 | T31: =T30*S31 -> 0.486 | U31: =IF(E31=4,N31,"") | V31: =IF(E31=4,Q31,"") | W31: =IF(E31=4,T31,"") | X31: =IF(E31=4,IFERROR((LN(U31)-LN(V31))/(LN(W31)-LN(V31)),0),"") | Y31: =IF(E31=4,IF(X31>='Settings '!$B$7,"Risk A",IF(X31>='Settings '!$B$6,"Risk B","Risk C")),"") | Z31: =IF(Y31="Risk B",1,0) -> 0 | AA31: =IF(J31>='Settings '!$B$10,1,0) -> 0 | AB31: =IF(M31>='Settings '!$B$11,1,0) -> 0 | AC31: =ABS(M31-MIN(1,I31*J31*K31)) -> 0
A32: A | B32: 8 | C32: A-008 | D32: S3 | E32: 3 | F32: T1059.009 | G32: Cloud API | H32: Business Server OnCloud | I32: 0.36 | J32: 0.1 | K32: 2 | L32: =I32*J32 -> 0.036 | M32: =MIN(1,I32*J32*K32) -> 0.072 | N32: =N31*M32 -> 0.000559872 | O32: ='Settings '!$B$8 -> 0.1 | P32: =MIN(1,I32*O32*K32) -> 0.072 | Q32: =Q31*P32 -> 0.000559872 | R32: ='Settings '!$B$9 -> 0.9 | S32: =MIN(1,I32*R32*K32) -> 0.648 | T32: =T31*S32 -> 0.314928 | U32: =IF(E32=4,N32,"") | V32: =IF(E32=4,Q32,"") | W32: =IF(E32=4,T32,"") | X32: =IF(E32=4,IFERROR((LN(U32)-LN(V32))/(LN(W32)-LN(V32)),0),"") | Y32: =IF(E32=4,IF(X32>='Settings '!$B$7,"Risk A",IF(X32>='Settings '!$B$6,"Risk B","Risk C")),"") | Z32: =IF(Y32="Risk B",1,0) -> 0 | AA32: =IF(J32>='Settings '!$B$10,1,0) -> 0 | AB32: =IF(M32>='Settings '!$B$11,1,0) -> 0 | AC32: =ABS(M32-MIN(1,I32*J32*K32)) -> 0
A33: A | B33: 8 | C33: A-008 | D33: S4 | E33: 4 | F33: T1496.004 | G33: Cloud Service Hijacking | H33: Proxy server OnCloud | I33: 0.18 | J33: 0.28 | K33: 2 | L33: =I33*J33 -> 0.0504 | M33: =MIN(1,I33*J33*K33) -> 0.1008 | N33: =N32*M33 -> 5.6435098e-05 | O33: ='Settings '!$B$8 -> 0.1 | P33: =MIN(1,I33*O33*K33) -> 0.036 | Q33: =Q32*P33 -> 2.0155392e-05 | R33: ='Settings '!$B$9 -> 0.9 | S33: =MIN(1,I33*R33*K33) -> 0.324 | T33: =T32*S33 -> 0.10203667 | U33: =IF(E33=4,N33,"") -> 5.6435098e-05 | V33: =IF(E33=4,Q33,"") -> 2.0155392e-05 | W33: =IF(E33=4,T33,"") -> 0.10203667 | X33: =IF(E33=4,IFERROR((LN(U33)-LN(V33))/(LN(W33)-LN(V33)),0),"") -> 0.12071111 | Y33: =IF(E33=4,IF(X33>='Settings '!$B$7,"Risk A",IF(X33>='Settings '!$B$6,"Risk B","Risk C")),"") -> Risk C | Z33: =IF(Y33="Risk B",1,0) -> 0 | AA33: =IF(J33>='Settings '!$B$10,1,0) -> 1 | AB33: =IF(M33>='Settings '!$B$11,1,0) -> 0 | AC33: =ABS(M33-MIN(1,I33*J33*K33)) -> 0
A34: A | B34: 9 | C34: A-009 | D34: S1 | E34: 1 | F34: T1078.004 | G34: Cloud Accounts | H34: Management Console for Business Server OnCloud | I34: 0.72 | J34: 0.1 | K34: 2 | L34: =I34*J34 -> 0.072 | M34: =MIN(1,I34*J34*K34) -> 0.144 | N34: =M34 -> 0.144 | O34: ='Settings '!$B$8 -> 0.1 | P34: =MIN(1,I34*O34*K34) -> 0.144 | Q34: =P34 -> 0.144 | R34: ='Settings '!$B$9 -> 0.9 | S34: =MIN(1,I34*R34*K34) -> 1 | T34: =S34 -> 1 | U34: =IF(E34=4,N34,"") | V34: =IF(E34=4,Q34,"") | W34: =IF(E34=4,T34,"") | X34: =IF(E34=4,IFERROR((LN(U34)-LN(V34))/(LN(W34)-LN(V34)),0),"") | Y34: =IF(E34=4,IF(X34>='Settings '!$B$7,"Risk A",IF(X34>='Settings '!$B$6,"Risk B","Risk C")),"") | Z34: =IF(Y34="Risk B",1,0) -> 0 | AA34: =IF(J34>='Settings '!$B$10,1,0) -> 0 | AB34: =IF(M34>='Settings '!$B$11,1,0) -> 0 | AC34: =ABS(M34-MIN(1,I34*J34*K34)) -> 0
A35: A | B35: 9 | C35: A-009 | D35: S2 | E35: 2 | F35: T1021.007 | G35: Cloud Services | H35: Update server OnCloud | I35: 0.36 | J35: 0.1 | K35: 1.5 | L35: =I35*J35 -> 0.036 | M35: =MIN(1,I35*J35*K35) -> 0.054 | N35: =N34*M35 -> 0.007776 | O35: ='Settings '!$B$8 -> 0.1 | P35: =MIN(1,I35*O35*K35) -> 0.054 | Q35: =Q34*P35 -> 0.007776 | R35: ='Settings '!$B$9 -> 0.9 | S35: =MIN(1,I35*R35*K35) -> 0.486 | T35: =T34*S35 -> 0.486 | U35: =IF(E35=4,N35,"") | V35: =IF(E35=4,Q35,"") | W35: =IF(E35=4,T35,"") | X35: =IF(E35=4,IFERROR((LN(U35)-LN(V35))/(LN(W35)-LN(V35)),0),"") | Y35: =IF(E35=4,IF(X35>='Settings '!$B$7,"Risk A",IF(X35>='Settings '!$B$6,"Risk B","Risk C")),"") | Z35: =IF(Y35="Risk B",1,0) -> 0 | AA35: =IF(J35>='Settings '!$B$10,1,0) -> 0 | AB35: =IF(M35>='Settings '!$B$11,1,0) -> 0 | AC35: =ABS(M35-MIN(1,I35*J35*K35)) -> 0
A36: A | B36: 9 | C36: A-009 | D36: S3 | E36: 3 | F36: T1651 | G36: Cloud Administration Command | H36: Business Server OnCloud | I36: 0.36 | J36: 0.1 | K36: 2 | L36: =I36*J36 -> 0.036 | M36: =MIN(1,I36*J36*K36) -> 0.072 | N36: =N35*M36 -> 0.000559872 | O36: ='Settings '!$B$8 -> 0.1 | P36: =MIN(1,I36*O36*K36) -> 0.072 | Q36: =Q35*P36 -> 0.000559872 | R36: ='Settings '!$B$9 -> 0.9 | S36: =MIN(1,I36*R36*K36) -> 0.648 | T36: =T35*S36 -> 0.314928 | U36: =IF(E36=4,N36,"") | V36: =IF(E36=4,Q36,"") | W36: =IF(E36=4,T36,"") | X36: =IF(E36=4,IFERROR((LN(U36)-LN(V36))/(LN(W36)-LN(V36)),0),"") | Y36: =IF(E36=4,IF(X36>='Settings '!$B$7,"Risk A",IF(X36>='Settings '!$B$6,"Risk B","Risk C")),"") | Z36: =IF(Y36="Risk B",1,0) -> 0 | AA36: =IF(J36>='Settings '!$B$10,1,0) -> 0 | AB36: =IF(M36>='Settings '!$B$11,1,0) -> 0 | AC36: =ABS(M36-MIN(1,I36*J36*K36)) -> 0
A37: A | B37: 9 | C37: A-009 | D37: S4 | E37: 4 | F37: T1486 | G37: Data Encrypted for Impact | H37: Proxy server OnCloud | I37: 0.9 | J37: 0.1 | K37: 2 | L37: =I37*J37 -> 0.09 | M37: =MIN(1,I37*J37*K37) -> 0.18 | N37: =N36*M37 -> 0.00010077696 | O37: ='Settings '!$B$8 -> 0.1 | P37: =MIN(1,I37*O37*K37) -> 0.18 | Q37: =Q36*P37 -> 0.00010077696 | R37: ='Settings '!$B$9 -> 0.9 | S37: =MIN(1,I37*R37*K37) -> 1 | T37: =T36*S37 -> 0.314928 | U37: =IF(E37=4,N37,"") -> 0.00010077696 | V37: =IF(E37=4,Q37,"") -> 0.00010077696 | W37: =IF(E37=4,T37,"") -> 0.314928 | X37: =IF(E37=4,IFERROR((LN(U37)-LN(V37))/(LN(W37)-LN(V37)),0),"") -> 0 | Y37: =IF(E37=4,IF(X37>='Settings '!$B$7,"Risk A",IF(X37>='Settings '!$B$6,"Risk B","Risk C")),"") -> Risk C | Z37: =IF(Y37="Risk B",1,0) -> 0 | AA37: =IF(J37>='Settings '!$B$10,1,0) -> 0 | AB37: =IF(M37>='Settings '!$B$11,1,0) -> 0 | AC37: =ABS(M37-MIN(1,I37*J37*K37)) -> 0
A38: A | B38: 10 | C38: A-010 | D38: S1 | E38: 1 | F38: T1078.004 | G38: Cloud Accounts | H38: Management Console for Business Server OnCloud | I38: 0.72 | J38: 0.1 | K38: 2 | L38: =I38*J38 -> 0.072 | M38: =MIN(1,I38*J38*K38) -> 0.144 | N38: =M38 -> 0.144 | O38: ='Settings '!$B$8 -> 0.1 | P38: =MIN(1,I38*O38*K38) -> 0.144 | Q38: =P38 -> 0.144 | R38: ='Settings '!$B$9 -> 0.9 | S38: =MIN(1,I38*R38*K38) -> 1 | T38: =S38 -> 1 | U38: =IF(E38=4,N38,"") | V38: =IF(E38=4,Q38,"") | W38: =IF(E38=4,T38,"") | X38: =IF(E38=4,IFERROR((LN(U38)-LN(V38))/(LN(W38)-LN(V38)),0),"") | Y38: =IF(E38=4,IF(X38>='Settings '!$B$7,"Risk A",IF(X38>='Settings '!$B$6,"Risk B","Risk C")),"") | Z38: =IF(Y38="Risk B",1,0) -> 0 | AA38: =IF(J38>='Settings '!$B$10,1,0) -> 0 | AB38: =IF(M38>='Settings '!$B$11,1,0) -> 0 | AC38: =ABS(M38-MIN(1,I38*J38*K38)) -> 0
A39: A | B39: 10 | C39: A-010 | D39: S2 | E39: 2 | F39: T1021.007 | G39: Cloud Services | H39: Update server OnCloud | I39: 0.36 | J39: 0.1 | K39: 1.5 | L39: =I39*J39 -> 0.036 | M39: =MIN(1,I39*J39*K39) -> 0.054 | N39: =N38*M39 -> 0.007776 | O39: ='Settings '!$B$8 -> 0.1 | P39: =MIN(1,I39*O39*K39) -> 0.054 | Q39: =Q38*P39 -> 0.007776 | R39: ='Settings '!$B$9 -> 0.9 | S39: =MIN(1,I39*R39*K39) -> 0.486 | T39: =T38*S39 -> 0.486 | U39: =IF(E39=4,N39,"") | V39: =IF(E39=4,Q39,"") | W39: =IF(E39=4,T39,"") | X39: =IF(E39=4,IFERROR((LN(U39)-LN(V39))/(LN(W39)-LN(V39)),0),"") | Y39: =IF(E39=4,IF(X39>='Settings '!$B$7,"Risk A",IF(X39>='Settings '!$B$6,"Risk B","Risk C")),"") | Z39: =IF(Y39="Risk B",1,0) -> 0 | AA39: =IF(J39>='Settings '!$B$10,1,0) -> 0 | AB39: =IF(M39>='Settings '!$B$11,1,0) -> 0 | AC39: =ABS(M39-MIN(1,I39*J39*K39)) -> 0
A40: A | B40: 10 | C40: A-010 | D40: S3 | E40: 3 | F40: T1651 | G40: Cloud Administration Command | H40: Business Server OnCloud | I40: 0.36 | J40: 0.1 | K40: 2 | L40: =I40*J40 -> 0.036 | M40: =MIN(1,I40*J40*K40) -> 0.072 | N40: =N39*M40 -> 0.000559872 | O40: ='Settings '!$B$8 -> 0.1 | P40: =MIN(1,I40*O40*K40) -> 0.072 | Q40: =Q39*P40 -> 0.000559872 | R40: ='Settings '!$B$9 -> 0.9 | S40: =MIN(1,I40*R40*K40) -> 0.648 | T40: =T39*S40 -> 0.314928 | U40: =IF(E40=4,N40,"") | V40: =IF(E40=4,Q40,"") | W40: =IF(E40=4,T40,"") | X40: =IF(E40=4,IFERROR((LN(U40)-LN(V40))/(LN(W40)-LN(V40)),0),"") | Y40: =IF(E40=4,IF(X40>='Settings '!$B$7,"Risk A",IF(X40>='Settings '!$B$6,"Risk B","Risk C")),"") | Z40: =IF(Y40="Risk B",1,0) -> 0 | AA40: =IF(J40>='Settings '!$B$10,1,0) -> 0 | AB40: =IF(M40>='Settings '!$B$11,1,0) -> 0 | AC40: =ABS(M40-MIN(1,I40*J40*K40)) -> 0
...

Sheet Tree_Summary
A1: Scenario_ID | B1: AttackTree_ID | C1: AttackTree_Key | D1: Final_Row | E1: Rtree_Current | F1: Rtree_Full | G1: Rtree_Worst | H1: Log_Ratio | I1: Risk_Class | J1: Risk_B_Flag | K1: Path_Techniques | L1: Path_Assets
A2: A | B2: 1 | C2: A-001 | D2: 5 | E2: =LONG!U5 -> 0.00010077696 | F2: =LONG!V5 -> 0.00010077696 | G2: =LONG!W5 -> 0.314928 | H2: =LONG!X5 -> 0 | I2: =LONG!Y5 -> Risk C | J2: =LONG!Z5 -> 0 | K2: S1:T1078.004 Cloud Accounts -> S2:T1021.007 Cloud Services -> S3:T1484.002 Trust Modification -> S4:T1486 Data Encrypted for Impact | L2: S1:Management Console for Business Server OnCloud -> S2:Update server OnCloud -> S3:Business Server OnCloud -> S4:Proxy server OnCloud
A3: A | B3: 2 | C3: A-002 | D3: 9 | E3: =LONG!U9 -> 0.00022574039 | F3: =LONG!V9 -> 8.0621568e-05 | G3: =LONG!W9 -> 0.314928 | H3: =LONG!X9 -> 0.12449552 | I3: =LONG!Y9 -> Risk C | J3: =LONG!Z9 -> 0 | K3: S1:T1078.004 Cloud Accounts -> S2:T1021.007 Cloud Services -> S3:T1484.002 Trust Modification -> S4:T1496.001 Compute Hijacking | L3: S1:Management Console for Business Server OnCloud -> S2:Update server OnCloud -> S3:Business Server OnCloud -> S4:Proxy server OnCloud
A4: A | B4: 3 | C4: A-003 | D4: 13 | E4: =LONG!U13 -> 5.6435098e-05 | F4: =LONG!V13 -> 2.0155392e-05 | G4: =LONG!W13 -> 0.10203667 | H4: =LONG!X13 -> 0.12071111 | I4: =LONG!Y13 -> Risk C | J4: =LONG!Z13 -> 0 | K4: S1:T1078.004 Cloud Accounts -> S2:T1021.007 Cloud Services -> S3:T1484.002 Trust Modification -> S4:T1496.002 Bandwidth Hijacking | L4: S1:Management Console for Business Server OnCloud -> S2:Update server OnCloud -> S3:Business Server OnCloud -> S4:Proxy server OnCloud
A5: A | B5: 4 | C5: A-004 | D5: 17 | E5: =LONG!U17 -> 5.6435098e-05 | F5: =LONG!V17 -> 2.0155392e-05 | G5: =LONG!W17 -> 0.10203667 | H5: =LONG!X17 -> 0.12071111 | I5: =LONG!Y17 -> Risk C | J5: =LONG!Z17 -> 0 | K5: S1:T1078.004 Cloud Accounts -> S2:T1021.007 Cloud Services -> S3:T1484.002 Trust Modification -> S4:T1496.004 Cloud Service Hijacking | L5: S1:Management Console for Business Server OnCloud -> S2:Update server OnCloud -> S3:Business Server OnCloud -> S4:Proxy server OnCloud
A6: A | B6: 5 | C6: A-005 | D6: 21 | E6: =LONG!U21 -> 0.00010077696 | F6: =LONG!V21 -> 0.00010077696 | G6: =LONG!W21 -> 0.314928 | H6: =LONG!X21 -> 0 | I6: =LONG!Y21 -> Risk C | J6: =LONG!Z21 -> 0 | K6: S1:T1078.004 Cloud Accounts -> S2:T1021.007 Cloud Services -> S3:T1059.009 Cloud API -> S4:T1486 Data Encrypted for Impact | L6: S1:Management Console for Business Server OnCloud -> S2:Update server OnCloud -> S3:Business Server OnCloud -> S4:Proxy server OnCloud
A7: A | B7: 6 | C7: A-006 | D7: 25 | E7: =LONG!U25 -> 0.00022574039 | F7: =LONG!V25 -> 8.0621568e-05 | G7: =LONG!W25 -> 0.314928 | H7: =LONG!X25 -> 0.12449552 | I7: =LONG!Y25 -> Risk C | J7: =LONG!Z25 -> 0 | K7: S1:T1078.004 Cloud Accounts -> S2:T1021.007 Cloud Services -> S3:T1059.009 Cloud API -> S4:T1496.001 Compute Hijacking | L7: S1:Management Console for Business Server OnCloud -> S2:Update server OnCloud -> S3:Business Server OnCloud -> S4:Proxy server OnCloud
A8: A | B8: 7 | C8: A-007 | D8: 29 | E8: =LONG!U29 -> 5.6435098e-05 | F8: =LONG!V29 -> 2.0155392e-05 | G8: =LONG!W29 -> 0.10203667 | H8: =LONG!X29 -> 0.12071111 | I8: =LONG!Y29 -> Risk C | J8: =LONG!Z29 -> 0 | K8: S1:T1078.004 Cloud Accounts -> S2:T1021.007 Cloud Services -> S3:T1059.009 Cloud API -> S4:T1496.002 Bandwidth Hijacking | L8: S1:Management Console for Business Server OnCloud -> S2:Update server OnCloud -> S3:Business Server OnCloud -> S4:Proxy server OnCloud
A9: A | B9: 8 | C9: A-008 | D9: 33 | E9: =LONG!U33 -> 5.6435098e-05 | F9: =LONG!V33 -> 2.0155392e-05 | G9: =LONG!W33 -> 0.10203667 | H9: =LONG!X33 -> 0.12071111 | I9: =LONG!Y33 -> Risk C | J9: =LONG!Z33 -> 0 | K9: S1:T1078.004 Cloud Accounts -> S2:T1021.007 Cloud Services -> S3:T1059.009 Cloud API -> S4:T1496.004 Cloud Service Hijacking | L9: S1:Management Console for Business Server OnCloud -> S2:Update server OnCloud -> S3:Business Server OnCloud -> S4:Proxy server OnCloud
A10: A | B10: 9 | C10: A-009 | D10: 37 | E10: =LONG!U37 -> 0.00010077696 | F10: =LONG!V37 -> 0.00010077696 | G10: =LONG!W37 -> 0.314928 | H10: =LONG!X37 -> 0 | I10: =LONG!Y37 -> Risk C | J10: =LONG!Z37 -> 0 | K10: S1:T1078.004 Cloud Accounts -> S2:T1021.007 Cloud Services -> S3:T1651 Cloud Administration Command -> S4:T1486 Data Encrypted for Impact | L10: S1:Management Console for Business Server OnCloud -> S2:Update server OnCloud -> S3:Business Server OnCloud -> S4:Proxy server OnCloud
A11: A | B11: 10 | C11: A-010 | D11: 41 | E11: =LONG!U41 -> 0.00022574039 | F11: =LONG!V41 -> 8.0621568e-05 | G11: =LONG!W41 -> 0.314928 | H11: =LONG!X41 -> 0.12449552 | I11: =LONG!Y41 -> Risk C | J11: =LONG!Z41 -> 0 | K11: S1:T1078.004 Cloud Accounts -> S2:T1021.007 Cloud Services -> S3:T1651 Cloud Administration Command -> S4:T1496.001 Compute Hijacking | L11: S1:Management Console for Business Server OnCloud -> S2:Update server OnCloud -> S3:Business Server OnCloud -> S4:Proxy server OnCloud
A12: A | B12: 11 | C12: A-011 | D12: 45 | E12: =LONG!U45 -> 5.6435098e-05 | F12: =LONG!V45 -> 2.0155392e-05 | G12: =LONG!W45 -> 0.10203667 | H12: =LONG!X45 -> 0.12071111 | I12: =LONG!Y45 -> Risk C | J12: =LONG!Z45 -> 0 | K12: S1:T1078.004 Cloud Accounts -> S2:T1021.007 Cloud Services -> S3:T1651 Cloud Administration Command -> S4:T1496.002 Bandwidth Hijacking | L12: S1:Management Console for Business Server OnCloud -> S2:Update server OnCloud -> S3:Business Server OnCloud -> S4:Proxy server OnCloud
A13: A | B13: 12 | C13: A-012 | D13: 49 | E13: =LONG!U49 -> 5.6435098e-05 | F13: =LONG!V49 -> 2.0155392e-05 | G13: =LONG!W49 -> 0.10203667 | H13: =LONG!X49 -> 0.12071111 | I13: =LONG!Y49 -> Risk C | J13: =LONG!Z49 -> 0 | K13: S1:T1078.004 Cloud Accounts -> S2:T1021.007 Cloud Services -> S3:T1651 Cloud Administration Command -> S4:T1496.004 Cloud Service Hijacking | L13: S1:Management Console for Business Server OnCloud -> S2:Update server OnCloud -> S3:Business Server OnCloud -> S4:Proxy server OnCloud
A14: A | B14: 13 | C14: A-013 | D14: 53 | E14: =LONG!U53 -> 0.00010077696 | F14: =LONG!V53 -> 0.00010077696 | G14: =LONG!W53 -> 0.314928 | H14: =LONG!X53 -> 0 | I14: =LONG!Y53 -> Risk C | J14: =LONG!Z53 -> 0 | K14: S1:T1078.004 Cloud Accounts -> S2:T1021.007 Cloud Services -> S3:T1555.006 Cloud Secrets Management Stores -> S4:T1486 Data Encrypted for Impact | L14: S1:Management Console for Business Server OnCloud -> S2:Update server OnCloud -> S3:Business Server OnCloud -> S4:Proxy server OnCloud
A15: A | B15: 14 | C15: A-014 | D15: 57 | E15: =LONG!U57 -> 0.00022574039 | F15: =LONG!V57 -> 8.0621568e-05 | G15: =LONG!W57 -> 0.314928 | H15: =LONG!X57 -> 0.12449552 | I15: =LONG!Y57 -> Risk C | J15: =LONG!Z57 -> 0 | K15: S1:T1078.004 Cloud Accounts -> S2:T1021.007 Cloud Services -> S3:T1555.006 Cloud Secrets Management Stores -> S4:T1496.001 Compute Hijacking | L15: S1:Management Console for Business Server OnCloud -> S2:Update server OnCloud -> S3:Business Server OnCloud -> S4:Proxy server OnCloud
A16: A | B16: 15 | C16: A-015 | D16: 61 | E16: =LONG!U61 -> 5.6435098e-05 | F16: =LONG!V61 -> 2.0155392e-05 | G16: =LONG!W61 -> 0.10203667 | H16: =LONG!X61 -> 0.12071111 | I16: =LONG!Y61 -> Risk C | J16: =LONG!Z61 -> 0 | K16: S1:T1078.004 Cloud Accounts -> S2:T1021.007 Cloud Services -> S3:T1555.006 Cloud Secrets Management Stores -> S4:T1496.002 Bandwidth Hijacking | L16: S1:Management Console for Business Server OnCloud -> S2:Update server OnCloud -> S3:Business Server OnCloud -> S4:Proxy server OnCloud
A17: A | B17: 16 | C17: A-016 | D17: 65 | E17: =LONG!U65 -> 5.6435098e-05 | F17: =LONG!V65 -> 2.0155392e-05 | G17: =LONG!W65 -> 0.10203667 | H17: =LONG!X65 -> 0.12071111 | I17: =LONG!Y65 -> Risk C | J17: =LONG!Z65 -> 0 | K17: S1:T1078.004 Cloud Accounts -> S2:T1021.007 Cloud Services -> S3:T1555.006 Cloud Secrets Management Stores -> S4:T1496.004 Cloud Service Hijacking | L17: S1:Management Console for Business Server OnCloud -> S2:Update server OnCloud -> S3:Business Server OnCloud -> S4:Proxy server OnCloud
A18: A | B18: 17 | C18: A-017 | D18: 69 | E18: =LONG!U69 -> 0.00010077696 | F18: =LONG!V69 -> 0.00010077696 | G18: =LONG!W69 -> 0.314928 | H18: =LONG!X69 -> 0 | I18: =LONG!Y69 -> Risk C | J18: =LONG!Z69 -> 0 | K18: S1:T1078.004 Cloud Accounts -> S2:T1484.002 Trust Modification -> S3:T1484.002 Trust Modification -> S4:T1486 Data Encrypted for Impact | L18: S1:Management Console for Business Server OnCloud -> S2:Update server OnCloud -> S3:Business Server OnCloud -> S4:Proxy server OnCloud
A19: A | B19: 18 | C19: A-018 | D19: 73 | E19: =LONG!U73 -> 0.00022574039 | F19: =LONG!V73 -> 8.0621568e-05 | G19: =LONG!W73 -> 0.314928 | H19: =LONG!X73 -> 0.12449552 | I19: =LONG!Y73 -> Risk C | J19: =LONG!Z73 -> 0 | K19: S1:T1078.004 Cloud Accounts -> S2:T1484.002 Trust Modification -> S3:T1484.002 Trust Modification -> S4:T1496.001 Compute Hijacking | L19: S1:Management Console for Business Server OnCloud -> S2:Update server OnCloud -> S3:Business Server OnCloud -> S4:Proxy server OnCloud
A20: A | B20: 19 | C20: A-019 | D20: 77 | E20: =LONG!U77 -> 5.6435098e-05 | F20: =LONG!V77 -> 2.0155392e-05 | G20: =LONG!W77 -> 0.10203667 | H20: =LONG!X77 -> 0.12071111 | I20: =LONG!Y77 -> Risk C | J20: =LONG!Z77 -> 0 | K20: S1:T1078.004 Cloud Accounts -> S2:T1484.002 Trust Modification -> S3:T1484.002 Trust Modification -> S4:T1496.002 Bandwidth Hijacking | L20: S1:Management Console for Business Server OnCloud -> S2:Update server OnCloud -> S3:Business Server OnCloud -> S4:Proxy server OnCloud
A21: A | B21: 20 | C21: A-020 | D21: 81 | E21: =LONG!U81 -> 5.6435098e-05 | F21: =LONG!V81 -> 2.0155392e-05 | G21: =LONG!W81 -> 0.10203667 | H21: =LONG!X81 -> 0.12071111 | I21: =LONG!Y81 -> Risk C | J21: =LONG!Z81 -> 0 | K21: S1:T1078.004 Cloud Accounts -> S2:T1484.002 Trust Modification -> S3:T1484.002 Trust Modification -> S4:T1496.004 Cloud Service Hijacking | L21: S1:Management Console for Business Server OnCloud -> S2:Update server OnCloud -> S3:Business Server OnCloud -> S4:Proxy server OnCloud
A22: A | B22: 21 | C22: A-021 | D22: 85 | E22: =LONG!U85 -> 0.00010077696 | F22: =LONG!V85 -> 0.00010077696 | G22: =LONG!W85 -> 0.314928 | H22: =LONG!X85 -> 0 | I22: =LONG!Y85 -> Risk C | J22: =LONG!Z85 -> 0 | K22: S1:T1078.004 Cloud Accounts -> S2:T1484.002 Trust Modification -> S3:T1059.009 Cloud API -> S4:T1486 Data Encrypted for Impact | L22: S1:Management Console for Business Server OnCloud -> S2:Update server OnCloud -> S3:Business Server OnCloud -> S4:Proxy server OnCloud
A23: A | B23: 22 | C23: A-022 | D23: 89 | E23: =LONG!U89 -> 0.00022574039 | F23: =LONG!V89 -> 8.0621568e-05 | G23: =LONG!W89 -> 0.314928 | H23: =LONG!X89 -> 0.12449552 | I23: =LONG!Y89 -> Risk C | J23: =LONG!Z89 -> 0 | K23: S1:T1078.004 Cloud Accounts -> S2:T1484.002 Trust Modification -> S3:T1059.009 Cloud API -> S4:T1496.001 Compute Hijacking | L23: S1:Management Console for Business Server OnCloud -> S2:Update server OnCloud -> S3:Business Server OnCloud -> S4:Proxy server OnCloud
A24: A | B24: 23 | C24: A-023 | D24: 93 | E24: =LONG!U93 -> 5.6435098e-05 | F24: =LONG!V93 -> 2.0155392e-05 | G24: =LONG!W93 -> 0.10203667 | H24: =LONG!X93 -> 0.12071111 | I24: =LONG!Y93 -> Risk C | J24: =LONG!Z93 -> 0 | K24: S1:T1078.004 Cloud Accounts -> S2:T1484.002 Trust Modification -> S3:T1059.009 Cloud API -> S4:T1496.002 Bandwidth Hijacking | L24: S1:Management Console for Business Server OnCloud -> S2:Update server OnCloud -> S3:Business Server OnCloud -> S4:Proxy server OnCloud
A25: A | B25: 24 | C25: A-024 | D25: 97 | E25: =LONG!U97 -> 5.6435098e-05 | F25: =LONG!V97 -> 2.0155392e-05 | G25: =LONG!W97 -> 0.10203667 | H25: =LONG!X97 -> 0.12071111 | I25: =LONG!Y97 -> Risk C | J25: =LONG!Z97 -> 0 | K25: S1:T1078.004 Cloud Accounts -> S2:T1484.002 Trust Modification -> S3:T1059.009 Cloud API -> S4:T1496.004 Cloud Service Hijacking | L25: S1:Management Console for Business Server OnCloud -> S2:Update server OnCloud -> S3:Business Server OnCloud -> S4:Proxy server OnCloud
A26: A | B26: 25 | C26: A-025 | D26: 101 | E26: =LONG!U101 -> 0.00010077696 | F26: =LONG!V101 -> 0.00010077696 | G26: =LONG!W101 -> 0.314928 | H26: =LONG!X101 -> 0 | I26: =LONG!Y101 -> Risk C | J26: =LONG!Z101 -> 0 | K26: S1:T1078.004 Cloud Accounts -> S2:T1484.002 Trust Modification -> S3:T1651 Cloud Administration Command -> S4:T1486 Data Encrypted for Impact | L26: S1:Management Console for Business Server OnCloud -> S2:Update server OnCloud -> S3:Business Server OnCloud -> S4:Proxy server OnCloud
A27: A | B27: 26 | C27: A-026 | D27: 105 | E27: =LONG!U105 -> 0.00022574039 | F27: =LONG!V105 -> 8.0621568e-05 | G27: =LONG!W105 -> 0.314928 | H27: =LONG!X105 -> 0.12449552 | I27: =LONG!Y105 -> Risk C | J27: =LONG!Z105 -> 0 | K27: S1:T1078.004 Cloud Accounts -> S2:T1484.002 Trust Modification -> S3:T1651 Cloud Administration Command -> S4:T1496.001 Compute Hijacking | L27: S1:Management Console for Business Server OnCloud -> S2:Update server OnCloud -> S3:Business Server OnCloud -> S4:Proxy server OnCloud
A28: A | B28: 27 | C28: A-027 | D28: 109 | E28: =LONG!U109 -> 5.6435098e-05 | F28: =LONG!V109 -> 2.0155392e-05 | G28: =LONG!W109 -> 0.10203667 | H28: =LONG!X109 -> 0.12071111 | I28: =LONG!Y109 -> Risk C | J28: =LONG!Z109 -> 0 | K28: S1:T1078.004 Cloud Accounts -> S2:T1484.002 Trust Modification -> S3:T1651 Cloud Administration Command -> S4:T1496.002 Bandwidth Hijacking | L28: S1:Management Console for Business Server OnCloud -> S2:Update server OnCloud -> S3:Business Server OnCloud -> S4:Proxy server OnCloud
A29: A | B29: 28 | C29: A-028 | D29: 113 | E29: =LONG!U113 -> 5.6435098e-05 | F29: =LONG!V113 -> 2.0155392e-05 | G29: =LONG!W113 -> 0.10203667 | H29: =LONG!X113 -> 0.12071111 | I29: =LONG!Y113 -> Risk C | J29: =LONG!Z113 -> 0 | K29: S1:T1078.004 Cloud Accounts -> S2:T1484.002 Trust Modification -> S3:T1651 Cloud Administration Command -> S4:T1496.004 Cloud Service Hijacking | L29: S1:Management Console for Business Server OnCloud -> S2:Update server OnCloud -> S3:Business Server OnCloud -> S4:Proxy server OnCloud
A30: A | B30: 29 | C30: A-029 | D30: 117 | E30: =LONG!U117 -> 0.00010077696 | F30: =LONG!V117 -> 0.00010077696 | G30: =LONG!W117 -> 0.314928 | H30: =LONG!X117 -> 0 | I30: =LONG!Y117 -> Risk C | J30: =LONG!Z117 -> 0 | K30: S1:T1078.004 Cloud Accounts -> S2:T1484.002 Trust Modification -> S3:T1555.006 Cloud Secrets Management Stores -> S4:T1486 Data Encrypted for Impact | L30: S1:Management Console for Business Server OnCloud -> S2:Update server OnCloud -> S3:Business Server OnCloud -> S4:Proxy server OnCloud
A31: A | B31: 30 | C31: A-030 | D31: 121 | E31: =LONG!U121 -> 0.00022574039 | F31: =LONG!V121 -> 8.0621568e-05 | G31: =LONG!W121 -> 0.314928 | H31: =LONG!X121 -> 0.12449552 | I31: =LONG!Y121 -> Risk C | J31: =LONG!Z121 -> 0 | K31: S1:T1078.004 Cloud Accounts -> S2:T1484.002 Trust Modification -> S3:T1555.006 Cloud Secrets Management Stores -> S4:T1496.001 Compute Hijacking | L31: S1:Management Console for Business Server OnCloud -> S2:Update server OnCloud -> S3:Business Server OnCloud -> S4:Proxy server OnCloud
A32: A | B32: 31 | C32: A-031 | D32: 125 | E32: =LONG!U125 -> 5.6435098e-05 | F32: =LONG!V125 -> 2.0155392e-05 | G32: =LONG!W125 -> 0.10203667 | H32: =LONG!X125 -> 0.12071111 | I32: =LONG!Y125 -> Risk C | J32: =LONG!Z125 -> 0 | K32: S1:T1078.004 Cloud Accounts -> S2:T1484.002 Trust Modification -> S3:T1555.006 Cloud Secrets Management Stores -> S4:T1496.002 Bandwidth Hijacking | L32: S1:Management Console for Business Server OnCloud -> S2:Update server OnCloud -> S3:Business Server OnCloud -> S4:Proxy server OnCloud
A33: A | B33: 32 | C33: A-032 | D33: 129 | E33: =LONG!U129 -> 5.6435098e-05 | F33: =LONG!V129 -> 2.0155392e-05 | G33: =LONG!W129 -> 0.10203667 | H33: =LONG!X129 -> 0.12071111 | I33: =LONG!Y129 -> Risk C | J33: =LONG!Z129 -> 0 | K33: S1:T1078.004 Cloud Accounts -> S2:T1484.002 Trust Modification -> S3:T1555.006 Cloud Secrets Management Stores -> S4:T1496.004 Cloud Service Hijacking | L33: S1:Management Console for Business Server OnCloud -> S2:Update server OnCloud -> S3:Business Server OnCloud -> S4:Proxy server OnCloud
A34: A | B34: 33 | C34: A-033 | D34: 133 | E34: =LONG!U133 -> 0.00046357402 | F34: =LONG!V133 -> 0.00010077696 | G34: =LONG!W133 -> 0.314928 | H34: =LONG!X133 -> 0.18963842 | I34: =LONG!Y133 -> Risk C | J34: =LONG!Z133 -> 0 | K34: S1:T1078.004 Cloud Accounts -> S2:T1578.002 Create Cloud Instance -> S3:T1484.002 Trust Modification -> S4:T1486 Data Encrypted for Impact | L34: S1:Management Console for Business Server OnCloud -> S2:Update server OnCloud -> S3:Business Server OnCloud -> S4:Proxy server OnCloud
A35: A | B35: 34 | C35: A-034 | D35: 137 | E35: =LONG!U137 -> 0.0010384058 | F35: =LONG!V137 -> 8.0621568e-05 | G35: =LONG!W137 -> 0.314928 | H35: =LONG!X137 -> 0.30901727 | I35: =LONG!Y137 -> Risk C | J35: =LONG!Z137 -> 0 | K35: S1:T1078.004 Cloud Accounts -> S2:T1578.002 Create Cloud Instance -> S3:T1484.002 Trust Modification -> S4:T1496.001 Compute Hijacking | L35: S1:Management Console for Business Server OnCloud -> S2:Update server OnCloud -> S3:Business Server OnCloud -> S4:Proxy server OnCloud
A36: A | B36: 35 | C36: A-035 | D36: 141 | E36: =LONG!U141 -> 0.00025960145 | F36: =LONG!V141 -> 2.0155392e-05 | G36: =LONG!W141 -> 0.10203667 | H36: =LONG!X141 -> 0.29962378 | I36: =LONG!Y141 -> Risk C | J36: =LONG!Z141 -> 0 | K36: S1:T1078.004 Cloud Accounts -> S2:T1578.002 Create Cloud Instance -> S3:T1484.002 Trust Modification -> S4:T1496.002 Bandwidth Hijacking | L36: S1:Management Console for Business Server OnCloud -> S2:Update server OnCloud -> S3:Business Server OnCloud -> S4:Proxy server OnCloud
A37: A | B37: 36 | C37: A-036 | D37: 145 | E37: =LONG!U145 -> 0.00025960145 | F37: =LONG!V145 -> 2.0155392e-05 | G37: =LONG!W145 -> 0.10203667 | H37: =LONG!X145 -> 0.29962378 | I37: =LONG!Y145 -> Risk C | J37: =LONG!Z145 -> 0 | K37: S1:T1078.004 Cloud Accounts -> S2:T1578.002 Create Cloud Instance -> S3:T1484.002 Trust Modification -> S4:T1496.004 Cloud Service Hijacking | L37: S1:Management Console for Business Server OnCloud -> S2:Update server OnCloud -> S3:Business Server OnCloud -> S4:Proxy server OnCloud
A38: A | B38: 37 | C38: A-037 | D38: 149 | E38: =LONG!U149 -> 0.00046357402 | F38: =LONG!V149 -> 0.00010077696 | G38: =LONG!W149 -> 0.314928 | H38: =LONG!X149 -> 0.18963842 | I38: =LONG!Y149 -> Risk C | J38: =LONG!Z149 -> 0 | K38: S1:T1078.004 Cloud Accounts -> S2:T1578.002 Create Cloud Instance -> S3:T1059.009 Cloud API -> S4:T1486 Data Encrypted for Impact | L38: S1:Management Console for Business Server OnCloud -> S2:Update server OnCloud -> S3:Business Server OnCloud -> S4:Proxy server OnCloud
A39: A | B39: 38 | C39: A-038 | D39: 153 | E39: =LONG!U153 -> 0.0010384058 | F39: =LONG!V153 -> 8.0621568e-05 | G39: =LONG!W153 -> 0.314928 | H39: =LONG!X153 -> 0.30901727 | I39: =LONG!Y153 -> Risk C | J39: =LONG!Z153 -> 0 | K39: S1:T1078.004 Cloud Accounts -> S2:T1578.002 Create Cloud Instance -> S3:T1059.009 Cloud API -> S4:T1496.001 Compute Hijacking | L39: S1:Management Console for Business Server OnCloud -> S2:Update server OnCloud -> S3:Business Server OnCloud -> S4:Proxy server OnCloud
A40: A | B40: 39 | C40: A-039 | D40: 157 | E40: =LONG!U157 -> 0.00025960145 | F40: =LONG!V157 -> 2.0155392e-05 | G40: =LONG!W157 -> 0.10203667 | H40: =LONG!X157 -> 0.29962378 | I40: =LONG!Y157 -> Risk C | J40: =LONG!Z157 -> 0 | K40: S1:T1078.004 Cloud Accounts -> S2:T1578.002 Create Cloud Instance -> S3:T1059.009 Cloud API -> S4:T1496.002 Bandwidth Hijacking | L40: S1:Management Console for Business Server OnCloud -> S2:Update server OnCloud -> S3:Business Server OnCloud -> S4:Proxy server OnCloud
...

Sheet Risk_Summary
A1: Scenario_ID | B1: A
A2: Total attack trees | B2: =COUNTA(Tree_Summary!C2:C65) -> 64
A3: Risk A count | B3: =COUNTIF(Tree_Summary!I2:I65,"Risk A") -> 0
A4: Risk B count | B4: =COUNTIF(Tree_Summary!I2:I65,"Risk B") -> 0
A5: Risk C count | B5: =COUNTIF(Tree_Summary!I2:I65,"Risk C") -> 64
A6: Risk B ratio | B6: =IF(B2=0,0,B4/B2) -> 0
A7: Max Rtree Current | B7: =MAX(Tree_Summary!E2:E65) -> 0.0010384058
A8: Top Risk Tree | B8: =INDEX(Tree_Summary!C2:C65,MATCH(B7,Tree_Summary!E2:E65,0)) -> A-034
A9: Average Rtree Current | B9: =AVERAGE(Tree_Summary!E2:E65) -> 0.00021969377

Sheet Settings 
A1: Workbook | B1: SPRV_LG_LONG_scenarioA
A2: Scenario | B2: Management console privilege abuse on GovCloud and CIA impact on resident information
A3: Formula for Qi | B3: Qi = Pi × Mi
A4: Formula for Qhat_i | B4: Qhat_i = MIN(1, Pi × Mi × Ci)
A5: Formula for Ri | B5: Ri_i = Ri_(i-1) × Qhat_i ; Ri_1 = Qhat_1
A6: Risk B threshold (Log_Ratio) | B6: 0.33333333
A7: Risk A threshold (Log_Ratio) | B7: 0.66666667
A8: Full mitigation Mi | B8: 0.1
A9: Worst case Mi | B9: 0.9
A10: High Mi flag threshold | B10: 0.28
A11: High Qhat flag threshold | B11: 0.4
A13: Ci conversion table
A14: Level | B14: Ci coefficient | C14: Influence | D14: Condition
A15: 1 | B15: 1 | C15: No influence | D15: Previous step does not affect the next step
A16: 2 | B16: 1.2 | C16: Minor influence | D16: Information acquisition slightly increases next-step success
A17: 3 | B17: 1.35 | C17: Moderate influence | D17: Acquired credentials/privileges can be reused in the next step
A18: 4 | B18: 1.5 | C18: Strong influence | D18: Credential/privilege/admin acquisition greatly increases next-step success
A19: 5 | B19: 2 | C19: Maximum influence | D19: Admin/cloud-control rights are almost fully obtained before the next step

Sheet Data_Dictionary
A1: Column | B1: Definition
A2: Pi | B2: Attack reproducibility rate based on MITRE frequency scoring.
A3: Mi_Current | B3: Defense failure rate under the guideline-compliant condition.
A4: Ci | B4: Propagation influence coefficient converted from the 5-level influence table.
A5: Qi_Current | B5: Pi × Mi_Current.
A6: Qhat_i_Current | B6: MIN(1, Pi × Mi_Current × Ci).
A7: Ri_Current | B7: Cumulative attack path reachability under guideline-compliant condition.
A8: Rtree_Current | B8: Final-step Ri_Current for the attack tree.
A9: Rtree_Full | B9: Final-step Ri under full mitigation reference condition, Mi=0.1.
A10: Rtree_Worst | B10: Final-step Ri under no mitigation reference condition, Mi=0.9.
A11: Log_Ratio | B11: Relative position of current Rtree between full mitigation and worst-case references.
A12: Risk_Class | B12: Risk A/B/C classification based on Log_Ratio thresholds.
