Workbook

Sheet ScenarioB_Attack_Paths_IPA_2025
A1: No | B1: Step1_TechniqueID | C1: Step1_TargetAsset | D1: description | E1: Business Impact | F1: Threat | G1: Mitigation | H1: Vulnerability | I1: Risk Score | J1: 対策根拠（既知脆弱性） | K1: Step2_TechniqueID | L1: Step2_TargetAsset | M1: description | N1: Business Impact | O1: Threat | P1: Mitigation | Q1: Vulnerability | R1: Risk Score | S1: 対策根拠 | T1: Step3_TechniqueID | U1: Step3_TargetAsset | V1: description | W1: Business Impact | X1: Threat | Y1: Mitigation | Z1: Vulnerability | AA1: Risk Score | AB1: 対策根拠 | AC1: Step4_TechniqueID | AD1: Step4_TargetAsset | AE1: description | AF1: Business Impact | AG1: Threat | AH1: Mitigation | AI1: Vulnerability | AJ1: Risk Score | AK1: 対策根拠 | AL1: Business Impact | AM1: Threat | AN1: Mitigation | AO1: Vulnerability | AP1: Risk Score | AQ1: 判定根拠
A2: 1 | B2: =SPRV_Source_For_Formulas!D2 | C2: VDI Auth server | D2: 外出先からSASE経由でVDI Auth Serverにアクセスする職員の通信を狙い、Citrix Gatewayの既知の脆弱性（例：CVE-2019-19781 など）を悪用して認証バイパスを実行。正規ユーザになりすまし、庁内ネットワークへの初期侵入に成功。 | E2: 3 | F2: 2 | G2: =IF(SPRV_Source_For_Formulas!G2<=0.2,3,IF(SPRV_Source_For_Formulas!G2<=0.5,2,1)) | H2: =4-G2 | I2: =IF(AND(E2=3,F2*H2>=6),"A",IF(AND(E2=3,F2*H2>=3),"B",IF(AND(E2=3,F2*H2>=1),"C",""))) | J2: 根拠（既知脆弱性への限定対応とβ’モデル基準）： 既知脆弱性に対する対策は技術・運用の両面で確立可能 総務省β’モデル「3.2.3 脆弱性管理」では、重大脆弱性に対し「48時間以内にパッチ適用」などのSLAを定めることが推奨されている。 さらに、「脆弱性の収集 → 影響評価 → 優先順位付け → 修正 → 再確認」の脆弱性管理ライフサイクルが整備されていれば、CVE-2019-19781のような既知の脆弱性はカバー可能。 SASE＋WAF＋ZTNAによる多層防御が機能すれば、侵入リスクは大幅に軽減 WAFにおける既知の攻撃シグネチャ対応は一般的であり、IDS/IPSやEDRとの組み合わせで侵入前に阻止できる。 SASEにおけるZTNAの導入により、「未認証端末からの直接到達不可」「職員IDベースの接続制御」「MDMによる端末衛生チェック」が可能。 構成管理や攻撃面最小化（attack surface reduction）も含めた対応が前提 公開Webアプリに対する構成管理（例：DMZ分離、最小限ポート公開、不要機能無効化等）が実施されていれば、既知脆弱性を突かれる余地は少ない。 | K2: =SPRV_Source_For_Formulas!D3 | L2: VDI Auth server | M2: 不正クラウドインスタンスを生成 し、VDI環境全体の制御奪取や横展開を図る | N2: 3 | O2: 2 | P2: =IF(SPRV_Source_For_Formulas!G3<=0.2,3,IF(SPRV_Source_For_Formulas!G3<=0.5,2,1)) | Q2: =4-P2 | R2: =IF(AND(N2=3,O2*Q2>=6),"A",IF(AND(N2=3,O2*Q2>=3),"B",IF(AND(N2=3,O2*Q2>=1),"C",""))) | S2: | 評価観点 | 状況・施策内容 | 評価 | | -------------- | -------------------------------------------- | ------ | | 認証管理（MFA, STS） | Step1対策としてMFA・ZTNA導入済。管理コンソールへの操作は多要素認証必須。 | ★★★（3） | | 権限管理（IAM） | VDI AuthサーバにEC2生成権限は原則付与されていない。ただし一部例外運用が残存。 | ★★☆（2） | | インスタンス作成監視 | CloudTrailでAPI呼び出し監視有効。SIEMと連携し異常通知あり。 | ★★★（3） | | ガードレール制御 | 承認フローは未整備。Terraform/IaCでの標準化はあるが手動例外ルールあり。 | ★★☆（2） | | 構成ミス検出自動化 | CSPM導入済。SSPMは試験導入段階で一部検知カバー不足。 | ★★☆（2） | | 監査と事後対応 | 月次監査と外部監査あり。監査範囲はアカウント・IAM主体でリソース生成は網羅性に欠ける。 | ★★☆（2） |→ 総合評価：2.3 → 切り下げて「レベル2」 | T2: =SPRV_Source_For_Formulas!D4 | U2: VDI server | V2: Step1で VDI Auth Serverを突破 し、Step2で 不正クラウドインスタンス生成（T1578.002） に成功した攻撃者は、VDI環境全体を制御するために クラウド管理コマンドを直接行使 。 想定される操作例は以下の通り： クラウド管理API/CLIを使用してVDI Serverの設定変更を実行 仮想NIC設定を変更してC2通信を許可 ストレージスナップショットを外部リージョンへ転送 認証関連構成を改変 VDIログオンポリシーを緩和 管理者アカウントの権限を昇格 痕跡隠蔽 監査ログを削除または外部に退避し検知回避 VDI Serverの構成を一時的に復旧させ、運用担当者に異常を気づかせない → 攻撃の本質は、クラウド環境の“正規管理操作”を不正に実行してVDI基盤を乗っ取る点にあり、検知困難性が非常に高いのが特徴 | W2: 3 | X2: 2 | Y2: =IF(SPRV_Source_For_Formulas!G4<=0.2,3,IF(SPRV_Source_For_Formulas!G4<=0.5,2,1)) | Z2: =4-Y2 | AA2: =IF(AND(W2=3,X2*Z2>=6),"A",IF(AND(W2=3,X2*Z2>=3),"B",IF(AND(W2=3,X2*Z2>=1),"C",""))) | AB2: | 評価観点 | 状況・施策内容 | 評価 | | -------------- | ------------------------------------------------ | ------ | | 認証管理（MFA, STS） | 管理操作にMFA必須、STSトークン利用。攻撃者が認証を突破した場合は正規操作に見える点が残る。 | ★★★（3） | | ログ監査・改ざん防止 | CloudTrail＋WORMで保存されているが、リアルタイム監視が不完全。 | ★★☆（2） | | 管理コマンドの承認フロー | 一部は二重承認あり。ただし運用効率優先で例外許可が散見。 | ★★☆（2） | | IaCによる設定固定 | Terraform導入済だが、一部手動操作が許容されている。 | ★★☆（2） | | SSPM・逸脱検知 | CSPM導入済、SSPMは未導入。異常なAPI操作の自動検知は一部不足。 | ★★☆（2） | | 監査と外部確認 | 月次の内部監査あり。外部監査は年1回。管理コマンドの網羅的確認までは実施されていない。 | ★★☆（2） |→ 総合評価：2.1 → 切り下げて「レベル2」 | AC2: =SPRV_Source_For_Formulas!D5 | AD2: My Number Administrative System on GovCloud | AE2: クラウド上の権限昇格・API権限を濫用し、コンピューティングリソース（仮想マシンやPaaS）を乗っ取って暗号資産マイニングやDDoSリレーに悪用。 | AF2: 3 | AG2: 2 | AH2: =IF(SPRV_Source_For_Formulas!G5<=0.2,3,IF(SPRV_Source_For_Formulas!G5<=0.5,2,1)) | AI2: =4-AH2 | AJ2: =IF(AND(AF2=3,AG2*AI2>=6),"A",IF(AND(AF2=3,AG2*AI2>=3),"B",IF(AND(AF2=3,AG2*AI2>=1),"C",""))) | AK2: β’モデル＋ガバメントクラウド資料にてIAM最小権限、API監査、CSPM運用が整備されていれば、有効性は高い。ただし初期検知遅延やアラート無視等には注意が必要。 | AL2: =MAX(E2,N2,W2,AF2) | AM2: 2 | AN2: =MAX(G2,P2,Y2,AH2) | AO2: =4-AN2 | AP2: =IF(AND(AL2=3,AM2*AO2>=6),"A",IF(AND(AL2=3,AM2*AO2>=3),"B",IF(AND(AL2=3,AM2*AO2>=1),"C",""))) | AQ2: ="Scenario-level Threat=2; Step1="&I2&" Step2="&R2&" Step3="&AA2&" Step4="&AJ2&" ; Overall Threat fixed=2, Max Mitigation="&AN2&" => Overall="&AP2
A3: 2 | B3: =SPRV_Source_For_Formulas!D6 | C3: VDI Auth server | D3: 外出先からSASE経由でVDI Auth Serverにアクセスする職員の通信を狙い、Citrix Gatewayの既知の脆弱性（例：CVE-2019-19781 など）を悪用して認証バイパスを実行。正規ユーザになりすまし、庁内ネットワークへの初期侵入に成功。 | E3: 3 | F3: 2 | G3: =IF(SPRV_Source_For_Formulas!G6<=0.2,3,IF(SPRV_Source_For_Formulas!G6<=0.5,2,1)) | H3: =4-G3 | I3: =IF(AND(E3=3,F3*H3>=6),"A",IF(AND(E3=3,F3*H3>=3),"B",IF(AND(E3=3,F3*H3>=1),"C",""))) | J3: 根拠（既知脆弱性への限定対応とβ’モデル基準）： 既知脆弱性に対する対策は技術・運用の両面で確立可能 総務省β’モデル「3.2.3 脆弱性管理」では、重大脆弱性に対し「48時間以内にパッチ適用」などのSLAを定めることが推奨されている。 さらに、「脆弱性の収集 → 影響評価 → 優先順位付け → 修正 → 再確認」の脆弱性管理ライフサイクルが整備されていれば、CVE-2019-19781のような既知の脆弱性はカバー可能。 SASE＋WAF＋ZTNAによる多層防御が機能すれば、侵入リスクは大幅に軽減 WAFにおける既知の攻撃シグネチャ対応は一般的であり、IDS/IPSやEDRとの組み合わせで侵入前に阻止できる。 SASEにおけるZTNAの導入により、「未認証端末からの直接到達不可」「職員IDベースの接続制御」「MDMによる端末衛生チェック」が可能。 構成管理や攻撃面最小化（attack surface reduction）も含めた対応が前提 公開Webアプリに対する構成管理（例：DMZ分離、最小限ポート公開、不要機能無効化等）が実施されていれば、既知脆弱性を突かれる余地は少ない。 | K3: =SPRV_Source_For_Formulas!D7 | L3: VDI Auth server | M3: 不正クラウドインスタンスを生成 し、VDI環境全体の制御奪取や横展開を図る | N3: 3 | O3: 2 | P3: =IF(SPRV_Source_For_Formulas!G7<=0.2,3,IF(SPRV_Source_For_Formulas!G7<=0.5,2,1)) | Q3: =4-P3 | R3: =IF(AND(N3=3,O3*Q3>=6),"A",IF(AND(N3=3,O3*Q3>=3),"B",IF(AND(N3=3,O3*Q3>=1),"C",""))) | S3: | 評価観点 | 状況・施策内容 | 評価 | | -------------- | -------------------------------------------- | ------ | | 認証管理（MFA, STS） | Step1対策としてMFA・ZTNA導入済。管理コンソールへの操作は多要素認証必須。 | ★★★（3） | | 権限管理（IAM） | VDI AuthサーバにEC2生成権限は原則付与されていない。ただし一部例外運用が残存。 | ★★☆（2） | | インスタンス作成監視 | CloudTrailでAPI呼び出し監視有効。SIEMと連携し異常通知あり。 | ★★★（3） | | ガードレール制御 | 承認フローは未整備。Terraform/IaCでの標準化はあるが手動例外ルールあり。 | ★★☆（2） | | 構成ミス検出自動化 | CSPM導入済。SSPMは試験導入段階で一部検知カバー不足。 | ★★☆（2） | | 監査と事後対応 | 月次監査と外部監査あり。監査範囲はアカウント・IAM主体でリソース生成は網羅性に欠ける。 | ★★☆（2） |→ 総合評価：2.3 → 切り下げて「レベル2」 | T3: =SPRV_Source_For_Formulas!D8 | U3: VDI server | V3: Step1で VDI Auth Serverを突破 し、Step2で 不正クラウドインスタンス生成（T1578.002） に成功した攻撃者は、VDI環境全体を制御するために クラウド管理コマンドを直接行使 。 想定される操作例は以下の通り： クラウド管理API/CLIを使用してVDI Serverの設定変更を実行 仮想NIC設定を変更してC2通信を許可 ストレージスナップショットを外部リージョンへ転送 認証関連構成を改変 VDIログオンポリシーを緩和 管理者アカウントの権限を昇格 痕跡隠蔽 監査ログを削除または外部に退避し検知回避 VDI Serverの構成を一時的に復旧させ、運用担当者に異常を気づかせない → 攻撃の本質は、クラウド環境の“正規管理操作”を不正に実行してVDI基盤を乗っ取る点にあり、検知困難性が非常に高いのが特徴 | W3: 3 | X3: 2 | Y3: =IF(SPRV_Source_For_Formulas!G8<=0.2,3,IF(SPRV_Source_For_Formulas!G8<=0.5,2,1)) | Z3: =4-Y3 | AA3: =IF(AND(W3=3,X3*Z3>=6),"A",IF(AND(W3=3,X3*Z3>=3),"B",IF(AND(W3=3,X3*Z3>=1),"C",""))) | AB3: | 評価観点 | 状況・施策内容 | 評価 | | -------------- | ------------------------------------------------ | ------ | | 認証管理（MFA, STS） | 管理操作にMFA必須、STSトークン利用。攻撃者が認証を突破した場合は正規操作に見える点が残る。 | ★★★（3） | | ログ監査・改ざん防止 | CloudTrail＋WORMで保存されているが、リアルタイム監視が不完全。 | ★★☆（2） | | 管理コマンドの承認フロー | 一部は二重承認あり。ただし運用効率優先で例外許可が散見。 | ★★☆（2） | | IaCによる設定固定 | Terraform導入済だが、一部手動操作が許容されている。 | ★★☆（2） | | SSPM・逸脱検知 | CSPM導入済、SSPMは未導入。異常なAPI操作の自動検知は一部不足。 | ★★☆（2） | | 監査と外部確認 | 月次の内部監査あり。外部監査は年1回。管理コマンドの網羅的確認までは実施されていない。 | ★★☆（2） |→ 総合評価：2.1 → 切り下げて「レベル2」 | AC3: =SPRV_Source_For_Formulas!D9 | AD3: My Number Administrative System on GovCloud | AE3: 仮想マシンに対するアクセス権を不正取得し、演算リソースを密かに使用して不正目的（例：マイニング、リバースシェル）に利用。 | AF3: 3 | AG3: 2 | AH3: =IF(SPRV_Source_For_Formulas!G9<=0.2,3,IF(SPRV_Source_For_Formulas!G9<=0.5,2,1)) | AI3: =4-AH3 | AJ3: =IF(AND(AF3=3,AG3*AI3>=6),"A",IF(AND(AF3=3,AG3*AI3>=3),"B",IF(AND(AF3=3,AG3*AI3>=1),"C",""))) | AK3: 仮想マシンに対するネットワーク分離、IAM制御、ログ監視により不正操作の抑止・検知が可能。推奨対策と合致。 | AL3: =MAX(E3,N3,W3,AF3) | AM3: 2 | AN3: =MAX(G3,P3,Y3,AH3) | AO3: =4-AN3 | AP3: =IF(AND(AL3=3,AM3*AO3>=6),"A",IF(AND(AL3=3,AM3*AO3>=3),"B",IF(AND(AL3=3,AM3*AO3>=1),"C",""))) | AQ3: ="Scenario-level Threat=2; Step1="&I3&" Step2="&R3&" Step3="&AA3&" Step4="&AJ3&" ; Overall Threat fixed=2, Max Mitigation="&AN3&" => Overall="&AP3
A4: 3 | B4: =SPRV_Source_For_Formulas!D10 | C4: VDI Auth server | D4: 外出先からSASE経由でVDI Auth Serverにアクセスする職員の通信を狙い、Citrix Gatewayの既知の脆弱性（例：CVE-2019-19781 など）を悪用して認証バイパスを実行。正規ユーザになりすまし、庁内ネットワークへの初期侵入に成功。 | E4: 3 | F4: 2 | G4: =IF(SPRV_Source_For_Formulas!G10<=0.2,3,IF(SPRV_Source_For_Formulas!G10<=0.5,2,1)) | H4: =4-G4 | I4: =IF(AND(E4=3,F4*H4>=6),"A",IF(AND(E4=3,F4*H4>=3),"B",IF(AND(E4=3,F4*H4>=1),"C",""))) | J4: 根拠（既知脆弱性への限定対応とβ’モデル基準）： 既知脆弱性に対する対策は技術・運用の両面で確立可能 総務省β’モデル「3.2.3 脆弱性管理」では、重大脆弱性に対し「48時間以内にパッチ適用」などのSLAを定めることが推奨されている。 さらに、「脆弱性の収集 → 影響評価 → 優先順位付け → 修正 → 再確認」の脆弱性管理ライフサイクルが整備されていれば、CVE-2019-19781のような既知の脆弱性はカバー可能。 SASE＋WAF＋ZTNAによる多層防御が機能すれば、侵入リスクは大幅に軽減 WAFにおける既知の攻撃シグネチャ対応は一般的であり、IDS/IPSやEDRとの組み合わせで侵入前に阻止できる。 SASEにおけるZTNAの導入により、「未認証端末からの直接到達不可」「職員IDベースの接続制御」「MDMによる端末衛生チェック」が可能。 構成管理や攻撃面最小化（attack surface reduction）も含めた対応が前提 公開Webアプリに対する構成管理（例：DMZ分離、最小限ポート公開、不要機能無効化等）が実施されていれば、既知脆弱性を突かれる余地は少ない。 | K4: =SPRV_Source_For_Formulas!D11 | L4: VDI Auth server | M4: 不正クラウドインスタンスを生成 し、VDI環境全体の制御奪取や横展開を図る | N4: 3 | O4: 2 | P4: =IF(SPRV_Source_For_Formulas!G11<=0.2,3,IF(SPRV_Source_For_Formulas!G11<=0.5,2,1)) | Q4: =4-P4 | R4: =IF(AND(N4=3,O4*Q4>=6),"A",IF(AND(N4=3,O4*Q4>=3),"B",IF(AND(N4=3,O4*Q4>=1),"C",""))) | S4: | 評価観点 | 状況・施策内容 | 評価 | | -------------- | -------------------------------------------- | ------ | | 認証管理（MFA, STS） | Step1対策としてMFA・ZTNA導入済。管理コンソールへの操作は多要素認証必須。 | ★★★（3） | | 権限管理（IAM） | VDI AuthサーバにEC2生成権限は原則付与されていない。ただし一部例外運用が残存。 | ★★☆（2） | | インスタンス作成監視 | CloudTrailでAPI呼び出し監視有効。SIEMと連携し異常通知あり。 | ★★★（3） | | ガードレール制御 | 承認フローは未整備。Terraform/IaCでの標準化はあるが手動例外ルールあり。 | ★★☆（2） | | 構成ミス検出自動化 | CSPM導入済。SSPMは試験導入段階で一部検知カバー不足。 | ★★☆（2） | | 監査と事後対応 | 月次監査と外部監査あり。監査範囲はアカウント・IAM主体でリソース生成は網羅性に欠ける。 | ★★☆（2） |→ 総合評価：2.3 → 切り下げて「レベル2」 | T4: =SPRV_Source_For_Formulas!D12 | U4: VDI server | V4: Step1で VDI Auth Serverを突破 し、Step2で 不正クラウドインスタンス生成（T1578.002） に成功した攻撃者は、VDI環境全体を制御するために クラウド管理コマンドを直接行使 。 想定される操作例は以下の通り： クラウド管理API/CLIを使用してVDI Serverの設定変更を実行 仮想NIC設定を変更してC2通信を許可 ストレージスナップショットを外部リージョンへ転送 認証関連構成を改変 VDIログオンポリシーを緩和 管理者アカウントの権限を昇格 痕跡隠蔽 監査ログを削除または外部に退避し検知回避 VDI Serverの構成を一時的に復旧させ、運用担当者に異常を気づかせない → 攻撃の本質は、クラウド環境の“正規管理操作”を不正に実行してVDI基盤を乗っ取る点にあり、検知困難性が非常に高いのが特徴 | W4: 3 | X4: 2 | Y4: =IF(SPRV_Source_For_Formulas!G12<=0.2,3,IF(SPRV_Source_For_Formulas!G12<=0.5,2,1)) | Z4: =4-Y4 | AA4: =IF(AND(W4=3,X4*Z4>=6),"A",IF(AND(W4=3,X4*Z4>=3),"B",IF(AND(W4=3,X4*Z4>=1),"C",""))) | AB4: | 評価観点 | 状況・施策内容 | 評価 | | -------------- | ------------------------------------------------ | ------ | | 認証管理（MFA, STS） | 管理操作にMFA必須、STSトークン利用。攻撃者が認証を突破した場合は正規操作に見える点が残る。 | ★★★（3） | | ログ監査・改ざん防止 | CloudTrail＋WORMで保存されているが、リアルタイム監視が不完全。 | ★★☆（2） | | 管理コマンドの承認フロー | 一部は二重承認あり。ただし運用効率優先で例外許可が散見。 | ★★☆（2） | | IaCによる設定固定 | Terraform導入済だが、一部手動操作が許容されている。 | ★★☆（2） | | SSPM・逸脱検知 | CSPM導入済、SSPMは未導入。異常なAPI操作の自動検知は一部不足。 | ★★☆（2） | | 監査と外部確認 | 月次の内部監査あり。外部監査は年1回。管理コマンドの網羅的確認までは実施されていない。 | ★★☆（2） |→ 総合評価：2.1 → 切り下げて「レベル2」 | AC4: =SPRV_Source_For_Formulas!D13 | AD4: My Number Administrative System on GovCloud | AE4: 攻撃手法の具体化 Step1〜Step3を経て攻撃者は VDI Auth → VDI Serverを経由し、クラウド管理権限を取得済み。 この状態で、攻撃者は My Number System上の業務データを暗号化し、業務停止やデータロックアウトを引き起こす。 想定される攻撃シナリオは以下： クラウド管理API／CLIを利用して、DBボリュームやストレージ（EBS, Blob, RDS等）を強制暗号化。 新しいKMSキーを攻撃者側で生成・割当し、既存キーを削除または無効化。 OSレベルでスクリプトを投入し、ファイルシステム全体を暗号化（Linux LUKS, Windows BitLocker等）。 Cloud Snapshotやバックアップを削除／無効化し、復旧不能状態に誘導。 結果として、マイナンバー業務全体が停止し、行政サービスに甚大な影響が発生する。 | AF4: 3 | AG4: 2 | AH4: =IF(SPRV_Source_For_Formulas!G13<=0.2,3,IF(SPRV_Source_For_Formulas!G13<=0.5,2,1)) | AI4: =4-AH4 | AJ4: =IF(AND(AF4=3,AG4*AI4>=6),"A",IF(AND(AF4=3,AG4*AI4>=3),"B",IF(AND(AF4=3,AG4*AI4>=1),"C",""))) | AK4: | 評価観点 | 状況・施策内容 | 評価 | | ----------------- | ------------------------------------------------------------ | ------ | | データ暗号化制御 | KMSによる暗号化・権限分離は導入済。ただし攻撃者が管理者権限を奪取した場合、正規の暗号化APIを利用され迂回可能。 | ★★☆（2） | | バックアップとリストア体制 | バックアップは定期取得されているが、スナップショット削除防止機能（Vault Lock等）は未導入で、削除耐性に弱点。 | ★★☆（2） | | API監視・検知 | CloudTrail＋SIEMで監査は有効。しかし暗号化コマンドやスナップショット削除のリアルタイム検知ルールは不完全。 | ★★☆（2） | | 承認フロー | 通常業務での暗号化設定変更は承認必須だが、緊急対応・管理者例外が存在し、悪用される可能性を残している。 | ★★☆（2） | | **CSPM／CIEM逸脱検知** | CSPMは導入済。だが暗号化操作やバックアップ削除の挙動検知は限定的。CIEMによる権限逸脱検知も一部のみ適用。 | ★★☆（2） |→総合評価：２ | AL4: =MAX(E4,N4,W4,AF4) | AM4: 2 | AN4: =MAX(G4,P4,Y4,AH4) | AO4: =4-AN4 | AP4: =IF(AND(AL4=3,AM4*AO4>=6),"A",IF(AND(AL4=3,AM4*AO4>=3),"B",IF(AND(AL4=3,AM4*AO4>=1),"C",""))) | AQ4: ="Scenario-level Threat=2; Step1="&I4&" Step2="&R4&" Step3="&AA4&" Step4="&AJ4&" ; Overall Threat fixed=2, Max Mitigation="&AN4&" => Overall="&AP4
A5: 4 | B5: =SPRV_Source_For_Formulas!D14 | C5: VDI Auth server | D5: 外出先からSASE経由でVDI Auth Serverにアクセスする職員の通信を狙い、Citrix Gatewayの既知の脆弱性（例：CVE-2019-19781 など）を悪用して認証バイパスを実行。正規ユーザになりすまし、庁内ネットワークへの初期侵入に成功。 | E5: 3 | F5: 2 | G5: =IF(SPRV_Source_For_Formulas!G14<=0.2,3,IF(SPRV_Source_For_Formulas!G14<=0.5,2,1)) | H5: =4-G5 | I5: =IF(AND(E5=3,F5*H5>=6),"A",IF(AND(E5=3,F5*H5>=3),"B",IF(AND(E5=3,F5*H5>=1),"C",""))) | J5: 根拠（既知脆弱性への限定対応とβ’モデル基準）： 既知脆弱性に対する対策は技術・運用の両面で確立可能 総務省β’モデル「3.2.3 脆弱性管理」では、重大脆弱性に対し「48時間以内にパッチ適用」などのSLAを定めることが推奨されている。 さらに、「脆弱性の収集 → 影響評価 → 優先順位付け → 修正 → 再確認」の脆弱性管理ライフサイクルが整備されていれば、CVE-2019-19781のような既知の脆弱性はカバー可能。 SASE＋WAF＋ZTNAによる多層防御が機能すれば、侵入リスクは大幅に軽減 WAFにおける既知の攻撃シグネチャ対応は一般的であり、IDS/IPSやEDRとの組み合わせで侵入前に阻止できる。 SASEにおけるZTNAの導入により、「未認証端末からの直接到達不可」「職員IDベースの接続制御」「MDMによる端末衛生チェック」が可能。 構成管理や攻撃面最小化（attack surface reduction）も含めた対応が前提 公開Webアプリに対する構成管理（例：DMZ分離、最小限ポート公開、不要機能無効化等）が実施されていれば、既知脆弱性を突かれる余地は少ない。 | K5: =SPRV_Source_For_Formulas!D15 | L5: VDI Auth server | M5: 不正クラウドインスタンスを生成 し、VDI環境全体の制御奪取や横展開を図る | N5: 3 | O5: 2 | P5: =IF(SPRV_Source_For_Formulas!G15<=0.2,3,IF(SPRV_Source_For_Formulas!G15<=0.5,2,1)) | Q5: =4-P5 | R5: =IF(AND(N5=3,O5*Q5>=6),"A",IF(AND(N5=3,O5*Q5>=3),"B",IF(AND(N5=3,O5*Q5>=1),"C",""))) | S5: | 評価観点 | 状況・施策内容 | 評価 | | -------------- | -------------------------------------------- | ------ | | 認証管理（MFA, STS） | Step1対策としてMFA・ZTNA導入済。管理コンソールへの操作は多要素認証必須。 | ★★★（3） | | 権限管理（IAM） | VDI AuthサーバにEC2生成権限は原則付与されていない。ただし一部例外運用が残存。 | ★★☆（2） | | インスタンス作成監視 | CloudTrailでAPI呼び出し監視有効。SIEMと連携し異常通知あり。 | ★★★（3） | | ガードレール制御 | 承認フローは未整備。Terraform/IaCでの標準化はあるが手動例外ルールあり。 | ★★☆（2） | | 構成ミス検出自動化 | CSPM導入済。SSPMは試験導入段階で一部検知カバー不足。 | ★★☆（2） | | 監査と事後対応 | 月次監査と外部監査あり。監査範囲はアカウント・IAM主体でリソース生成は網羅性に欠ける。 | ★★☆（2） |→ 総合評価：2.3 → 切り下げて「レベル2」 | T5: =SPRV_Source_For_Formulas!D16 | U5: VDI server | V5: Step1で VDI Auth Serverを突破 し、Step2で 不正クラウドインスタンス生成（T1578.002） に成功した攻撃者は、VDI環境全体を制御するために クラウド管理コマンドを直接行使 。 想定される操作例は以下の通り： クラウド管理API/CLIを使用してVDI Serverの設定変更を実行 仮想NIC設定を変更してC2通信を許可 ストレージスナップショットを外部リージョンへ転送 認証関連構成を改変 VDIログオンポリシーを緩和 管理者アカウントの権限を昇格 痕跡隠蔽 監査ログを削除または外部に退避し検知回避 VDI Serverの構成を一時的に復旧させ、運用担当者に異常を気づかせない → 攻撃の本質は、クラウド環境の“正規管理操作”を不正に実行してVDI基盤を乗っ取る点にあり、検知困難性が非常に高いのが特徴 | W5: 3 | X5: 2 | Y5: =IF(SPRV_Source_For_Formulas!G16<=0.2,3,IF(SPRV_Source_For_Formulas!G16<=0.5,2,1)) | Z5: =4-Y5 | AA5: =IF(AND(W5=3,X5*Z5>=6),"A",IF(AND(W5=3,X5*Z5>=3),"B",IF(AND(W5=3,X5*Z5>=1),"C",""))) | AB5: | 評価観点 | 状況・施策内容 | 評価 | | -------------- | ------------------------------------------------ | ------ | | 認証管理（MFA, STS） | 管理操作にMFA必須、STSトークン利用。攻撃者が認証を突破した場合は正規操作に見える点が残る。 | ★★★（3） | | ログ監査・改ざん防止 | CloudTrail＋WORMで保存されているが、リアルタイム監視が不完全。 | ★★☆（2） | | 管理コマンドの承認フロー | 一部は二重承認あり。ただし運用効率優先で例外許可が散見。 | ★★☆（2） | | IaCによる設定固定 | Terraform導入済だが、一部手動操作が許容されている。 | ★★☆（2） | | SSPM・逸脱検知 | CSPM導入済、SSPMは未導入。異常なAPI操作の自動検知は一部不足。 | ★★☆（2） | | 監査と外部確認 | 月次の内部監査あり。外部監査は年1回。管理コマンドの網羅的確認までは実施されていない。 | ★★☆（2） |→ 総合評価：2.1 → 切り下げて「レベル2」 | AC5: =SPRV_Source_For_Formulas!D17 | AD5: My Number Administrative System on GovCloud | AE5: 攻撃手法の具体化 Step1〜Step3で VDI Auth Server → VDI Server に侵入済みの攻撃者は、最終段階として マイナンバー事務系システムのリソース（特に帯域幅）を不正利用 。 攻撃の具体例： マイナンバーシステム上で稼働する VM／コンテナに不正ソフトを導入し、外部DDoS攻撃の踏み台として帯域を消費。 内部帯域を過剰利用し、正規業務処理の遅延や停止を誘発。 帯域消費によりクラウド課金を膨張させ、経済的損害を与える。 通信トラフィックに混在させて、C2通信やデータ流出を隠蔽。 → この攻撃は 「可用性の破壊」と「リソース濫用」 の両面を狙っており、暗号化攻撃（T1486）と比べても検知が難しい特徴がある。 | AF5: 3 | AG5: 2 | AH5: =IF(SPRV_Source_For_Formulas!G17<=0.2,3,IF(SPRV_Source_For_Formulas!G17<=0.5,2,1)) | AI5: =4-AH5 | AJ5: =IF(AND(AF5=3,AG5*AI5>=6),"A",IF(AND(AF5=3,AG5*AI5>=3),"B",IF(AND(AF5=3,AG5*AI5>=1),"C",""))) | AK5: | 評価観点 | 状況・施策内容 | 評価 | | -------------- | ---------------------------------------------------- | ------ | | 帯域使用監視・検知 | CloudWatch／Monitor等で帯域監視は実施。ただしリアルタイム異常検知ルールは一部未整備。 | ★★☆（2） | | DDoS対策 | 一般的なDDoS対策サービスは契約済。ただし全トラフィック網羅ではなく、業務系ネットワークの一部対象外。 | ★★☆（2） | | 出口通信制御 | Proxy・FWルールで外部接続制御済。ただしVDI経由トラフィックは例外許容ケースあり。 | ★★☆（2） | | CSPM／CIEMによる検知 | 過剰権限は定期監査されるが、自動検知ルールは不十分。帯域逸脱の直接検知機能は限定的。 | ★★☆（2） | | 監査と課金異常モニタリング | 月次監査とクラウド課金監視あり。ただし異常利用を即座にアラート化する仕組みは未導入。 | ★★☆（2） |→ 総合評価：2.0 → レベル2 | AL5: =MAX(E5,N5,W5,AF5) | AM5: 2 | AN5: =MAX(G5,P5,Y5,AH5) | AO5: =4-AN5 | AP5: =IF(AND(AL5=3,AM5*AO5>=6),"A",IF(AND(AL5=3,AM5*AO5>=3),"B",IF(AND(AL5=3,AM5*AO5>=1),"C",""))) | AQ5: ="Scenario-level Threat=2; Step1="&I5&" Step2="&R5&" Step3="&AA5&" Step4="&AJ5&" ; Overall Threat fixed=2, Max Mitigation="&AN5&" => Overall="&AP5
A6: 5 | B6: =SPRV_Source_For_Formulas!D18 | C6: VDI Auth server | D6: 外出先からSASE経由でVDI Auth Serverにアクセスする職員の通信を狙い、Citrix Gatewayの既知の脆弱性（例：CVE-2019-19781 など）を悪用して認証バイパスを実行。正規ユーザになりすまし、庁内ネットワークへの初期侵入に成功。 | E6: 3 | F6: 2 | G6: =IF(SPRV_Source_For_Formulas!G18<=0.2,3,IF(SPRV_Source_For_Formulas!G18<=0.5,2,1)) | H6: =4-G6 | I6: =IF(AND(E6=3,F6*H6>=6),"A",IF(AND(E6=3,F6*H6>=3),"B",IF(AND(E6=3,F6*H6>=1),"C",""))) | J6: 根拠（既知脆弱性への限定対応とβ’モデル基準）： 既知脆弱性に対する対策は技術・運用の両面で確立可能 総務省β’モデル「3.2.3 脆弱性管理」では、重大脆弱性に対し「48時間以内にパッチ適用」などのSLAを定めることが推奨されている。 さらに、「脆弱性の収集 → 影響評価 → 優先順位付け → 修正 → 再確認」の脆弱性管理ライフサイクルが整備されていれば、CVE-2019-19781のような既知の脆弱性はカバー可能。 SASE＋WAF＋ZTNAによる多層防御が機能すれば、侵入リスクは大幅に軽減 WAFにおける既知の攻撃シグネチャ対応は一般的であり、IDS/IPSやEDRとの組み合わせで侵入前に阻止できる。 SASEにおけるZTNAの導入により、「未認証端末からの直接到達不可」「職員IDベースの接続制御」「MDMによる端末衛生チェック」が可能。 構成管理や攻撃面最小化（attack surface reduction）も含めた対応が前提 公開Webアプリに対する構成管理（例：DMZ分離、最小限ポート公開、不要機能無効化等）が実施されていれば、既知脆弱性を突かれる余地は少ない。 | K6: =SPRV_Source_For_Formulas!D19 | L6: VDI Auth server | M6: 不正クラウドインスタンスを生成 し、VDI環境全体の制御奪取や横展開を図る | N6: 3 | O6: 2 | P6: =IF(SPRV_Source_For_Formulas!G19<=0.2,3,IF(SPRV_Source_For_Formulas!G19<=0.5,2,1)) | Q6: =4-P6 | R6: =IF(AND(N6=3,O6*Q6>=6),"A",IF(AND(N6=3,O6*Q6>=3),"B",IF(AND(N6=3,O6*Q6>=1),"C",""))) | S6: | 評価観点 | 状況・施策内容 | 評価 | | -------------- | -------------------------------------------- | ------ | | 認証管理（MFA, STS） | Step1対策としてMFA・ZTNA導入済。管理コンソールへの操作は多要素認証必須。 | ★★★（3） | | 権限管理（IAM） | VDI AuthサーバにEC2生成権限は原則付与されていない。ただし一部例外運用が残存。 | ★★☆（2） | | インスタンス作成監視 | CloudTrailでAPI呼び出し監視有効。SIEMと連携し異常通知あり。 | ★★★（3） | | ガードレール制御 | 承認フローは未整備。Terraform/IaCでの標準化はあるが手動例外ルールあり。 | ★★☆（2） | | 構成ミス検出自動化 | CSPM導入済。SSPMは試験導入段階で一部検知カバー不足。 | ★★☆（2） | | 監査と事後対応 | 月次監査と外部監査あり。監査範囲はアカウント・IAM主体でリソース生成は網羅性に欠ける。 | ★★☆（2） |→ 総合評価：2.3 → 切り下げて「レベル2」 | T6: =SPRV_Source_For_Formulas!D20 | U6: VDI server | V6: 攻撃者は Step1・Step2 で VDI Auth Serverに侵入 → 不正クラウドインスタンス作成 に成功。次のStep3では、VDI Serverに保存されているクラウドシークレット管理ストアへのアクセスを悪用します。 具体的な攻撃手法は以下： VDI Serverや関連アプリが利用する Secrets Manager／Key Vault／環境変数ストア を探索。 APIキー、VDI管理者アカウントのパスワード、DB認証情報、トークン等を抽出。 これらのSecretsを用いて、VDI管理コンソールや下位システムへ追加侵入。 認証情報を悪用して横展開や持続的アクセスを確立。 → 特にVDIサーバは「認証の中枢」であるため、Secretsが奪取されると他の全職員アカウントへの侵入ルートに直結するリスクがあります。 | W6: 3 | X6: 2 | Y6: =IF(SPRV_Source_For_Formulas!G20<=0.2,3,IF(SPRV_Source_For_Formulas!G20<=0.5,2,1)) | Z6: =4-Y6 | AA6: =IF(AND(W6=3,X6*Z6>=6),"A",IF(AND(W6=3,X6*Z6>=3),"B",IF(AND(W6=3,X6*Z6>=1),"C",""))) | AB6: | 評価観点 | 状況・施策内容 | 評価 | | ---------------- | ----------------------------------------------- | ------ | | Secretsアクセス制御 | IAMで細粒度制御は導入済。ただし一部広範囲ロールが残存。 | ★★☆（2） | | 暗号化とKMSキー管理 | KMSで暗号化され、鍵は別IAMで管理。 | ★★★（3） | | アクセス監査と検知 | CloudTrail＋SIEMで監査可能だが、Secrets読み取りアラートが遅延検知ベース。 | ★★☆（2） | | Secretsローテーション運用 | 一部自動化済み（APIキー等）、DB認証情報は手動更新が残る。 | ★★☆（2） | | SSPM・逸脱検知 | CSPM導入済、SSPMは未導入で逸脱検知は限定的。 | ★★☆（2） | | 承認フロー・監査 | 外部委託者操作は承認必須。内部管理者操作は承認不要ケースあり。 | ★★☆（2） |→ 総合評価：2.2 → 切り下げて「レベル2」 | AC6: =SPRV_Source_For_Formulas!D21 | AD6: My Number Administrative System on GovCloud | AE6: クラウドサービス全体の乗っ取り。 | AF6: 3 | AG6: 2 | AH6: =IF(SPRV_Source_For_Formulas!G21<=0.2,3,IF(SPRV_Source_For_Formulas!G21<=0.5,2,1)) | AI6: =4-AH6 | AJ6: =IF(AND(AF6=3,AG6*AI6>=6),"A",IF(AND(AF6=3,AG6*AI6>=3),"B",IF(AND(AF6=3,AG6*AI6>=1),"C",""))) | AK6: β’モデル＋ガバメントクラウド資料にてIAM最小権限、API監査、CSPM運用が整備されていれば、有効性は高い。ただし初期検知遅延やアラート無視等には注意が必要。 | AL6: =MAX(E6,N6,W6,AF6) | AM6: 2 | AN6: =MAX(G6,P6,Y6,AH6) | AO6: =4-AN6 | AP6: =IF(AND(AL6=3,AM6*AO6>=6),"A",IF(AND(AL6=3,AM6*AO6>=3),"B",IF(AND(AL6=3,AM6*AO6>=1),"C",""))) | AQ6: ="Scenario-level Threat=2; Step1="&I6&" Step2="&R6&" Step3="&AA6&" Step4="&AJ6&" ; Overall Threat fixed=2, Max Mitigation="&AN6&" => Overall="&AP6
A7: 6 | B7: =SPRV_Source_For_Formulas!D22 | C7: VDI Auth server | D7: 外出先からSASE経由でVDI Auth Serverにアクセスする職員の通信を狙い、Citrix Gatewayの既知の脆弱性（例：CVE-2019-19781 など）を悪用して認証バイパスを実行。正規ユーザになりすまし、庁内ネットワークへの初期侵入に成功。 | E7: 3 | F7: 2 | G7: =IF(SPRV_Source_For_Formulas!G22<=0.2,3,IF(SPRV_Source_For_Formulas!G22<=0.5,2,1)) | H7: =4-G7 | I7: =IF(AND(E7=3,F7*H7>=6),"A",IF(AND(E7=3,F7*H7>=3),"B",IF(AND(E7=3,F7*H7>=1),"C",""))) | J7: 根拠（既知脆弱性への限定対応とβ’モデル基準）： 既知脆弱性に対する対策は技術・運用の両面で確立可能 総務省β’モデル「3.2.3 脆弱性管理」では、重大脆弱性に対し「48時間以内にパッチ適用」などのSLAを定めることが推奨されている。 さらに、「脆弱性の収集 → 影響評価 → 優先順位付け → 修正 → 再確認」の脆弱性管理ライフサイクルが整備されていれば、CVE-2019-19781のような既知の脆弱性はカバー可能。 SASE＋WAF＋ZTNAによる多層防御が機能すれば、侵入リスクは大幅に軽減 WAFにおける既知の攻撃シグネチャ対応は一般的であり、IDS/IPSやEDRとの組み合わせで侵入前に阻止できる。 SASEにおけるZTNAの導入により、「未認証端末からの直接到達不可」「職員IDベースの接続制御」「MDMによる端末衛生チェック」が可能。 構成管理や攻撃面最小化（attack surface reduction）も含めた対応が前提 公開Webアプリに対する構成管理（例：DMZ分離、最小限ポート公開、不要機能無効化等）が実施されていれば、既知脆弱性を突かれる余地は少ない。 | K7: =SPRV_Source_For_Formulas!D23 | L7: VDI Auth server | M7: 不正クラウドインスタンスを生成 し、VDI環境全体の制御奪取や横展開を図る | N7: 3 | O7: 2 | P7: =IF(SPRV_Source_For_Formulas!G23<=0.2,3,IF(SPRV_Source_For_Formulas!G23<=0.5,2,1)) | Q7: =4-P7 | R7: =IF(AND(N7=3,O7*Q7>=6),"A",IF(AND(N7=3,O7*Q7>=3),"B",IF(AND(N7=3,O7*Q7>=1),"C",""))) | S7: | 評価観点 | 状況・施策内容 | 評価 | | -------------- | -------------------------------------------- | ------ | | 認証管理（MFA, STS） | Step1対策としてMFA・ZTNA導入済。管理コンソールへの操作は多要素認証必須。 | ★★★（3） | | 権限管理（IAM） | VDI AuthサーバにEC2生成権限は原則付与されていない。ただし一部例外運用が残存。 | ★★☆（2） | | インスタンス作成監視 | CloudTrailでAPI呼び出し監視有効。SIEMと連携し異常通知あり。 | ★★★（3） | | ガードレール制御 | 承認フローは未整備。Terraform/IaCでの標準化はあるが手動例外ルールあり。 | ★★☆（2） | | 構成ミス検出自動化 | CSPM導入済。SSPMは試験導入段階で一部検知カバー不足。 | ★★☆（2） | | 監査と事後対応 | 月次監査と外部監査あり。監査範囲はアカウント・IAM主体でリソース生成は網羅性に欠ける。 | ★★☆（2） |→ 総合評価：2.3 → 切り下げて「レベル2」 | T7: =SPRV_Source_For_Formulas!D24 | U7: VDI server | V7: 攻撃者は Step1・Step2 で VDI Auth Serverに侵入 → 不正クラウドインスタンス作成 に成功。次のStep3では、VDI Serverに保存されているクラウドシークレット管理ストアへのアクセスを悪用します。 具体的な攻撃手法は以下： VDI Serverや関連アプリが利用する Secrets Manager／Key Vault／環境変数ストア を探索。 APIキー、VDI管理者アカウントのパスワード、DB認証情報、トークン等を抽出。 これらのSecretsを用いて、VDI管理コンソールや下位システムへ追加侵入。 認証情報を悪用して横展開や持続的アクセスを確立。 → 特にVDIサーバは「認証の中枢」であるため、Secretsが奪取されると他の全職員アカウントへの侵入ルートに直結するリスクがあります。 | W7: 3 | X7: 2 | Y7: =IF(SPRV_Source_For_Formulas!G24<=0.2,3,IF(SPRV_Source_For_Formulas!G24<=0.5,2,1)) | Z7: =4-Y7 | AA7: =IF(AND(W7=3,X7*Z7>=6),"A",IF(AND(W7=3,X7*Z7>=3),"B",IF(AND(W7=3,X7*Z7>=1),"C",""))) | AB7: | 評価観点 | 状況・施策内容 | 評価 | | ---------------- | ----------------------------------------------- | ------ | | Secretsアクセス制御 | IAMで細粒度制御は導入済。ただし一部広範囲ロールが残存。 | ★★☆（2） | | 暗号化とKMSキー管理 | KMSで暗号化され、鍵は別IAMで管理。 | ★★★（3） | | アクセス監査と検知 | CloudTrail＋SIEMで監査可能だが、Secrets読み取りアラートが遅延検知ベース。 | ★★☆（2） | | Secretsローテーション運用 | 一部自動化済み（APIキー等）、DB認証情報は手動更新が残る。 | ★★☆（2） | | SSPM・逸脱検知 | CSPM導入済、SSPMは未導入で逸脱検知は限定的。 | ★★☆（2） | | 承認フロー・監査 | 外部委託者操作は承認必須。内部管理者操作は承認不要ケースあり。 | ★★☆（2） |→ 総合評価：2.2 → 切り下げて「レベル2」 | AC7: =SPRV_Source_For_Formulas!D25 | AD7: My Number Administrative System on GovCloud | AE7: 漏洩した認証情報や横展開で取得した権限を用いて、GovCloud上の仮想マシンを不正利用（例：暗号資産マイニング）。 | AF7: 3 | AG7: 2 | AH7: =IF(SPRV_Source_For_Formulas!G25<=0.2,3,IF(SPRV_Source_For_Formulas!G25<=0.5,2,1)) | AI7: =4-AH7 | AJ7: =IF(AND(AF7=3,AG7*AI7>=6),"A",IF(AND(AF7=3,AG7*AI7>=3),"B",IF(AND(AF7=3,AG7*AI7>=1),"C",""))) | AK7: 仮想マシンに対するネットワーク分離、IAM制御、ログ監視により不正操作の抑止・検知が可能。推奨対策と合致。 | AL7: =MAX(E7,N7,W7,AF7) | AM7: 2 | AN7: =MAX(G7,P7,Y7,AH7) | AO7: =4-AN7 | AP7: =IF(AND(AL7=3,AM7*AO7>=6),"A",IF(AND(AL7=3,AM7*AO7>=3),"B",IF(AND(AL7=3,AM7*AO7>=1),"C",""))) | AQ7: ="Scenario-level Threat=2; Step1="&I7&" Step2="&R7&" Step3="&AA7&" Step4="&AJ7&" ; Overall Threat fixed=2, Max Mitigation="&AN7&" => Overall="&AP7
A8: 7 | B8: =SPRV_Source_For_Formulas!D26 | C8: VDI Auth server | D8: 外出先からSASE経由でVDI Auth Serverにアクセスする職員の通信を狙い、Citrix Gatewayの既知の脆弱性（例：CVE-2019-19781 など）を悪用して認証バイパスを実行。正規ユーザになりすまし、庁内ネットワークへの初期侵入に成功。 | E8: 3 | F8: 2 | G8: =IF(SPRV_Source_For_Formulas!G26<=0.2,3,IF(SPRV_Source_For_Formulas!G26<=0.5,2,1)) | H8: =4-G8 | I8: =IF(AND(E8=3,F8*H8>=6),"A",IF(AND(E8=3,F8*H8>=3),"B",IF(AND(E8=3,F8*H8>=1),"C",""))) | J8: 根拠（既知脆弱性への限定対応とβ’モデル基準）： 既知脆弱性に対する対策は技術・運用の両面で確立可能 総務省β’モデル「3.2.3 脆弱性管理」では、重大脆弱性に対し「48時間以内にパッチ適用」などのSLAを定めることが推奨されている。 さらに、「脆弱性の収集 → 影響評価 → 優先順位付け → 修正 → 再確認」の脆弱性管理ライフサイクルが整備されていれば、CVE-2019-19781のような既知の脆弱性はカバー可能。 SASE＋WAF＋ZTNAによる多層防御が機能すれば、侵入リスクは大幅に軽減 WAFにおける既知の攻撃シグネチャ対応は一般的であり、IDS/IPSやEDRとの組み合わせで侵入前に阻止できる。 SASEにおけるZTNAの導入により、「未認証端末からの直接到達不可」「職員IDベースの接続制御」「MDMによる端末衛生チェック」が可能。 構成管理や攻撃面最小化（attack surface reduction）も含めた対応が前提 公開Webアプリに対する構成管理（例：DMZ分離、最小限ポート公開、不要機能無効化等）が実施されていれば、既知脆弱性を突かれる余地は少ない。 | K8: =SPRV_Source_For_Formulas!D27 | L8: VDI Auth server | M8: 不正クラウドインスタンスを生成 し、VDI環境全体の制御奪取や横展開を図る | N8: 3 | O8: 2 | P8: =IF(SPRV_Source_For_Formulas!G27<=0.2,3,IF(SPRV_Source_For_Formulas!G27<=0.5,2,1)) | Q8: =4-P8 | R8: =IF(AND(N8=3,O8*Q8>=6),"A",IF(AND(N8=3,O8*Q8>=3),"B",IF(AND(N8=3,O8*Q8>=1),"C",""))) | S8: | 評価観点 | 状況・施策内容 | 評価 | | -------------- | -------------------------------------------- | ------ | | 認証管理（MFA, STS） | Step1対策としてMFA・ZTNA導入済。管理コンソールへの操作は多要素認証必須。 | ★★★（3） | | 権限管理（IAM） | VDI AuthサーバにEC2生成権限は原則付与されていない。ただし一部例外運用が残存。 | ★★☆（2） | | インスタンス作成監視 | CloudTrailでAPI呼び出し監視有効。SIEMと連携し異常通知あり。 | ★★★（3） | | ガードレール制御 | 承認フローは未整備。Terraform/IaCでの標準化はあるが手動例外ルールあり。 | ★★☆（2） | | 構成ミス検出自動化 | CSPM導入済。SSPMは試験導入段階で一部検知カバー不足。 | ★★☆（2） | | 監査と事後対応 | 月次監査と外部監査あり。監査範囲はアカウント・IAM主体でリソース生成は網羅性に欠ける。 | ★★☆（2） |→ 総合評価：2.3 → 切り下げて「レベル2」 | T8: =SPRV_Source_For_Formulas!D28 | U8: VDI server | V8: 攻撃者は Step1・Step2 で VDI Auth Serverに侵入 → 不正クラウドインスタンス作成 に成功。次のStep3では、VDI Serverに保存されているクラウドシークレット管理ストアへのアクセスを悪用します。 具体的な攻撃手法は以下： VDI Serverや関連アプリが利用する Secrets Manager／Key Vault／環境変数ストア を探索。 APIキー、VDI管理者アカウントのパスワード、DB認証情報、トークン等を抽出。 これらのSecretsを用いて、VDI管理コンソールや下位システムへ追加侵入。 認証情報を悪用して横展開や持続的アクセスを確立。 → 特にVDIサーバは「認証の中枢」であるため、Secretsが奪取されると他の全職員アカウントへの侵入ルートに直結するリスクがあります。 | W8: 3 | X8: 2 | Y8: =IF(SPRV_Source_For_Formulas!G28<=0.2,3,IF(SPRV_Source_For_Formulas!G28<=0.5,2,1)) | Z8: =4-Y8 | AA8: =IF(AND(W8=3,X8*Z8>=6),"A",IF(AND(W8=3,X8*Z8>=3),"B",IF(AND(W8=3,X8*Z8>=1),"C",""))) | AB8: | 評価観点 | 状況・施策内容 | 評価 | | ---------------- | ----------------------------------------------- | ------ | | Secretsアクセス制御 | IAMで細粒度制御は導入済。ただし一部広範囲ロールが残存。 | ★★☆（2） | | 暗号化とKMSキー管理 | KMSで暗号化され、鍵は別IAMで管理。 | ★★★（3） | | アクセス監査と検知 | CloudTrail＋SIEMで監査可能だが、Secrets読み取りアラートが遅延検知ベース。 | ★★☆（2） | | Secretsローテーション運用 | 一部自動化済み（APIキー等）、DB認証情報は手動更新が残る。 | ★★☆（2） | | SSPM・逸脱検知 | CSPM導入済、SSPMは未導入で逸脱検知は限定的。 | ★★☆（2） | | 承認フロー・監査 | 外部委託者操作は承認必須。内部管理者操作は承認不要ケースあり。 | ★★☆（2） |→ 総合評価：2.2 → 切り下げて「レベル2」 | AC8: =SPRV_Source_For_Formulas!D29 | AD8: My Number Administrative System on GovCloud | AE8: 攻撃手法の具体化 Step1〜Step3を経て攻撃者は VDI Auth → VDI Serverを経由し、クラウド管理権限を取得済み。 この状態で、攻撃者は My Number System上の業務データを暗号化し、業務停止やデータロックアウトを引き起こす。 想定される攻撃シナリオは以下： クラウド管理API／CLIを利用して、DBボリュームやストレージ（EBS, Blob, RDS等）を強制暗号化。 新しいKMSキーを攻撃者側で生成・割当し、既存キーを削除または無効化。 OSレベルでスクリプトを投入し、ファイルシステム全体を暗号化（Linux LUKS, Windows BitLocker等）。 Cloud Snapshotやバックアップを削除／無効化し、復旧不能状態に誘導。 結果として、マイナンバー業務全体が停止し、行政サービスに甚大な影響が発生する。 | AF8: 3 | AG8: 2 | AH8: =IF(SPRV_Source_For_Formulas!G29<=0.2,3,IF(SPRV_Source_For_Formulas!G29<=0.5,2,1)) | AI8: =4-AH8 | AJ8: =IF(AND(AF8=3,AG8*AI8>=6),"A",IF(AND(AF8=3,AG8*AI8>=3),"B",IF(AND(AF8=3,AG8*AI8>=1),"C",""))) | AK8: | 評価観点 | 状況・施策内容 | 評価 | | ----------------- | ------------------------------------------------------------ | ------ | | データ暗号化制御 | KMSによる暗号化・権限分離は導入済。ただし攻撃者が管理者権限を奪取した場合、正規の暗号化APIを利用され迂回可能。 | ★★☆（2） | | バックアップとリストア体制 | バックアップは定期取得されているが、スナップショット削除防止機能（Vault Lock等）は未導入で、削除耐性に弱点。 | ★★☆（2） | | API監視・検知 | CloudTrail＋SIEMで監査は有効。しかし暗号化コマンドやスナップショット削除のリアルタイム検知ルールは不完全。 | ★★☆（2） | | 承認フロー | 通常業務での暗号化設定変更は承認必須だが、緊急対応・管理者例外が存在し、悪用される可能性を残している。 | ★★☆（2） | | **CSPM／CIEM逸脱検知** | CSPMは導入済。だが暗号化操作やバックアップ削除の挙動検知は限定的。CIEMによる権限逸脱検知も一部のみ適用。 | ★★☆（2） |→総合評価：２ | AL8: =MAX(E8,N8,W8,AF8) | AM8: 2 | AN8: =MAX(G8,P8,Y8,AH8) | AO8: =4-AN8 | AP8: =IF(AND(AL8=3,AM8*AO8>=6),"A",IF(AND(AL8=3,AM8*AO8>=3),"B",IF(AND(AL8=3,AM8*AO8>=1),"C",""))) | AQ8: ="Scenario-level Threat=2; Step1="&I8&" Step2="&R8&" Step3="&AA8&" Step4="&AJ8&" ; Overall Threat fixed=2, Max Mitigation="&AN8&" => Overall="&AP8
A9: 8 | B9: =SPRV_Source_For_Formulas!D30 | C9: VDI Auth server | D9: 外出先からSASE経由でVDI Auth Serverにアクセスする職員の通信を狙い、Citrix Gatewayの既知の脆弱性（例：CVE-2019-19781 など）を悪用して認証バイパスを実行。正規ユーザになりすまし、庁内ネットワークへの初期侵入に成功。 | E9: 3 | F9: 2 | G9: =IF(SPRV_Source_For_Formulas!G30<=0.2,3,IF(SPRV_Source_For_Formulas!G30<=0.5,2,1)) | H9: =4-G9 | I9: =IF(AND(E9=3,F9*H9>=6),"A",IF(AND(E9=3,F9*H9>=3),"B",IF(AND(E9=3,F9*H9>=1),"C",""))) | J9: 根拠（既知脆弱性への限定対応とβ’モデル基準）： 既知脆弱性に対する対策は技術・運用の両面で確立可能 総務省β’モデル「3.2.3 脆弱性管理」では、重大脆弱性に対し「48時間以内にパッチ適用」などのSLAを定めることが推奨されている。 さらに、「脆弱性の収集 → 影響評価 → 優先順位付け → 修正 → 再確認」の脆弱性管理ライフサイクルが整備されていれば、CVE-2019-19781のような既知の脆弱性はカバー可能。 SASE＋WAF＋ZTNAによる多層防御が機能すれば、侵入リスクは大幅に軽減 WAFにおける既知の攻撃シグネチャ対応は一般的であり、IDS/IPSやEDRとの組み合わせで侵入前に阻止できる。 SASEにおけるZTNAの導入により、「未認証端末からの直接到達不可」「職員IDベースの接続制御」「MDMによる端末衛生チェック」が可能。 構成管理や攻撃面最小化（attack surface reduction）も含めた対応が前提 公開Webアプリに対する構成管理（例：DMZ分離、最小限ポート公開、不要機能無効化等）が実施されていれば、既知脆弱性を突かれる余地は少ない。 | K9: =SPRV_Source_For_Formulas!D31 | L9: VDI Auth server | M9: 不正クラウドインスタンスを生成 し、VDI環境全体の制御奪取や横展開を図る | N9: 3 | O9: 2 | P9: =IF(SPRV_Source_For_Formulas!G31<=0.2,3,IF(SPRV_Source_For_Formulas!G31<=0.5,2,1)) | Q9: =4-P9 | R9: =IF(AND(N9=3,O9*Q9>=6),"A",IF(AND(N9=3,O9*Q9>=3),"B",IF(AND(N9=3,O9*Q9>=1),"C",""))) | S9: | 評価観点 | 状況・施策内容 | 評価 | | -------------- | -------------------------------------------- | ------ | | 認証管理（MFA, STS） | Step1対策としてMFA・ZTNA導入済。管理コンソールへの操作は多要素認証必須。 | ★★★（3） | | 権限管理（IAM） | VDI AuthサーバにEC2生成権限は原則付与されていない。ただし一部例外運用が残存。 | ★★☆（2） | | インスタンス作成監視 | CloudTrailでAPI呼び出し監視有効。SIEMと連携し異常通知あり。 | ★★★（3） | | ガードレール制御 | 承認フローは未整備。Terraform/IaCでの標準化はあるが手動例外ルールあり。 | ★★☆（2） | | 構成ミス検出自動化 | CSPM導入済。SSPMは試験導入段階で一部検知カバー不足。 | ★★☆（2） | | 監査と事後対応 | 月次監査と外部監査あり。監査範囲はアカウント・IAM主体でリソース生成は網羅性に欠ける。 | ★★☆（2） |→ 総合評価：2.3 → 切り下げて「レベル2」 | T9: =SPRV_Source_For_Formulas!D32 | U9: VDI server | V9: 攻撃者は Step1・Step2 で VDI Auth Serverに侵入 → 不正クラウドインスタンス作成 に成功。次のStep3では、VDI Serverに保存されているクラウドシークレット管理ストアへのアクセスを悪用します。 具体的な攻撃手法は以下： VDI Serverや関連アプリが利用する Secrets Manager／Key Vault／環境変数ストア を探索。 APIキー、VDI管理者アカウントのパスワード、DB認証情報、トークン等を抽出。 これらのSecretsを用いて、VDI管理コンソールや下位システムへ追加侵入。 認証情報を悪用して横展開や持続的アクセスを確立。 → 特にVDIサーバは「認証の中枢」であるため、Secretsが奪取されると他の全職員アカウントへの侵入ルートに直結するリスクがあります。 | W9: 3 | X9: 2 | Y9: =IF(SPRV_Source_For_Formulas!G32<=0.2,3,IF(SPRV_Source_For_Formulas!G32<=0.5,2,1)) | Z9: =4-Y9 | AA9: =IF(AND(W9=3,X9*Z9>=6),"A",IF(AND(W9=3,X9*Z9>=3),"B",IF(AND(W9=3,X9*Z9>=1),"C",""))) | AB9: | 評価観点 | 状況・施策内容 | 評価 | | ---------------- | ----------------------------------------------- | ------ | | Secretsアクセス制御 | IAMで細粒度制御は導入済。ただし一部広範囲ロールが残存。 | ★★☆（2） | | 暗号化とKMSキー管理 | KMSで暗号化され、鍵は別IAMで管理。 | ★★★（3） | | アクセス監査と検知 | CloudTrail＋SIEMで監査可能だが、Secrets読み取りアラートが遅延検知ベース。 | ★★☆（2） | | Secretsローテーション運用 | 一部自動化済み（APIキー等）、DB認証情報は手動更新が残る。 | ★★☆（2） | | SSPM・逸脱検知 | CSPM導入済、SSPMは未導入で逸脱検知は限定的。 | ★★☆（2） | | 承認フロー・監査 | 外部委託者操作は承認必須。内部管理者操作は承認不要ケースあり。 | ★★☆（2） |→ 総合評価：2.2 → 切り下げて「レベル2」 | AC9: =SPRV_Source_For_Formulas!D33 | AD9: My Number Administrative System on GovCloud | AE9: 攻撃手法の具体化 Step1〜Step3で VDI Auth Server → VDI Server に侵入済みの攻撃者は、最終段階として マイナンバー事務系システムのリソース（特に帯域幅）を不正利用 。 攻撃の具体例： マイナンバーシステム上で稼働する VM／コンテナに不正ソフトを導入し、外部DDoS攻撃の踏み台として帯域を消費。 内部帯域を過剰利用し、正規業務処理の遅延や停止を誘発。 帯域消費によりクラウド課金を膨張させ、経済的損害を与える。 通信トラフィックに混在させて、C2通信やデータ流出を隠蔽。 → この攻撃は 「可用性の破壊」と「リソース濫用」 の両面を狙っており、暗号化攻撃（T1486）と比べても検知が難しい特徴がある。 | AF9: 3 | AG9: 2 | AH9: =IF(SPRV_Source_For_Formulas!G33<=0.2,3,IF(SPRV_Source_For_Formulas!G33<=0.5,2,1)) | AI9: =4-AH9 | AJ9: =IF(AND(AF9=3,AG9*AI9>=6),"A",IF(AND(AF9=3,AG9*AI9>=3),"B",IF(AND(AF9=3,AG9*AI9>=1),"C",""))) | AK9: | 評価観点 | 状況・施策内容 | 評価 | | -------------- | ---------------------------------------------------- | ------ | | 帯域使用監視・検知 | CloudWatch／Monitor等で帯域監視は実施。ただしリアルタイム異常検知ルールは一部未整備。 | ★★☆（2） | | DDoS対策 | 一般的なDDoS対策サービスは契約済。ただし全トラフィック網羅ではなく、業務系ネットワークの一部対象外。 | ★★☆（2） | | 出口通信制御 | Proxy・FWルールで外部接続制御済。ただしVDI経由トラフィックは例外許容ケースあり。 | ★★☆（2） | | CSPM／CIEMによる検知 | 過剰権限は定期監査されるが、自動検知ルールは不十分。帯域逸脱の直接検知機能は限定的。 | ★★☆（2） | | 監査と課金異常モニタリング | 月次監査とクラウド課金監視あり。ただし異常利用を即座にアラート化する仕組みは未導入。 | ★★☆（2） |→ 総合評価：2.0 → レベル2 | AL9: =MAX(E9,N9,W9,AF9) | AM9: 2 | AN9: =MAX(G9,P9,Y9,AH9) | AO9: =4-AN9 | AP9: =IF(AND(AL9=3,AM9*AO9>=6),"A",IF(AND(AL9=3,AM9*AO9>=3),"B",IF(AND(AL9=3,AM9*AO9>=1),"C",""))) | AQ9: ="Scenario-level Threat=2; Step1="&I9&" Step2="&R9&" Step3="&AA9&" Step4="&AJ9&" ; Overall Threat fixed=2, Max Mitigation="&AN9&" => Overall="&AP9
A10: 9 | B10: =SPRV_Source_For_Formulas!D34 | C10: VDI Auth server | D10: 外出先からSASE経由でVDI Auth Serverにアクセスする職員の通信を狙い、Citrix Gatewayの既知の脆弱性（例：CVE-2019-19781 など）を悪用して認証バイパスを実行。正規ユーザになりすまし、庁内ネットワークへの初期侵入に成功。 | E10: 3 | F10: 2 | G10: =IF(SPRV_Source_For_Formulas!G34<=0.2,3,IF(SPRV_Source_For_Formulas!G34<=0.5,2,1)) | H10: =4-G10 | I10: =IF(AND(E10=3,F10*H10>=6),"A",IF(AND(E10=3,F10*H10>=3),"B",IF(AND(E10=3,F10*H10>=1),"C",""))) | J10: 根拠（既知脆弱性への限定対応とβ’モデル基準）： 既知脆弱性に対する対策は技術・運用の両面で確立可能 総務省β’モデル「3.2.3 脆弱性管理」では、重大脆弱性に対し「48時間以内にパッチ適用」などのSLAを定めることが推奨されている。 さらに、「脆弱性の収集 → 影響評価 → 優先順位付け → 修正 → 再確認」の脆弱性管理ライフサイクルが整備されていれば、CVE-2019-19781のような既知の脆弱性はカバー可能。 SASE＋WAF＋ZTNAによる多層防御が機能すれば、侵入リスクは大幅に軽減 WAFにおける既知の攻撃シグネチャ対応は一般的であり、IDS/IPSやEDRとの組み合わせで侵入前に阻止できる。 SASEにおけるZTNAの導入により、「未認証端末からの直接到達不可」「職員IDベースの接続制御」「MDMによる端末衛生チェック」が可能。 構成管理や攻撃面最小化（attack surface reduction）も含めた対応が前提 公開Webアプリに対する構成管理（例：DMZ分離、最小限ポート公開、不要機能無効化等）が実施されていれば、既知脆弱性を突かれる余地は少ない。 | K10: =SPRV_Source_For_Formulas!D35 | L10: VDI Auth server | M10: 不正クラウドインスタンスを生成 し、VDI環境全体の制御奪取や横展開を図る | N10: 3 | O10: 2 | P10: =IF(SPRV_Source_For_Formulas!G35<=0.2,3,IF(SPRV_Source_For_Formulas!G35<=0.5,2,1)) | Q10: =4-P10 | R10: =IF(AND(N10=3,O10*Q10>=6),"A",IF(AND(N10=3,O10*Q10>=3),"B",IF(AND(N10=3,O10*Q10>=1),"C",""))) | S10: | 評価観点 | 状況・施策内容 | 評価 | | -------------- | -------------------------------------------- | ------ | | 認証管理（MFA, STS） | Step1対策としてMFA・ZTNA導入済。管理コンソールへの操作は多要素認証必須。 | ★★★（3） | | 権限管理（IAM） | VDI AuthサーバにEC2生成権限は原則付与されていない。ただし一部例外運用が残存。 | ★★☆（2） | | インスタンス作成監視 | CloudTrailでAPI呼び出し監視有効。SIEMと連携し異常通知あり。 | ★★★（3） | | ガードレール制御 | 承認フローは未整備。Terraform/IaCでの標準化はあるが手動例外ルールあり。 | ★★☆（2） | | 構成ミス検出自動化 | CSPM導入済。SSPMは試験導入段階で一部検知カバー不足。 | ★★☆（2） | | 監査と事後対応 | 月次監査と外部監査あり。監査範囲はアカウント・IAM主体でリソース生成は網羅性に欠ける。 | ★★☆（2） |→ 総合評価：2.3 → 切り下げて「レベル2」 | T10: =SPRV_Source_For_Formulas!D36 | U10: VDI server | V10: クラウドAPI（AWS CLI等）を悪用し、スクリプトでクラウド環境へ不正指令を自動送信。 | W10: 3 | X10: 2 | Y10: =IF(SPRV_Source_For_Formulas!G36<=0.2,3,IF(SPRV_Source_For_Formulas!G36<=0.5,2,1)) | Z10: =4-Y10 | AA10: =IF(AND(W10=3,X10*Z10>=6),"A",IF(AND(W10=3,X10*Z10>=3),"B",IF(AND(W10=3,X10*Z10>=1),"C",""))) | AB10: β’モデル「3.3.6 コマンド実行制御」や「3.2.3 脆弱性管理」、Cloud API利用は正規用途でもあり、異常操作の見分けが困難、CSPMやSIEMによる振る舞い監視が必要だが完全ではない | AC10: =SPRV_Source_For_Formulas!D37 | AD10: My Number Administrative System on GovCloud | AE10: 不正スクリプトによって、複数のクラウドサービスインスタンスを乗っ取り、他攻撃の踏み台や外部攻撃に悪用。 | AF10: 3 | AG10: 2 | AH10: =IF(SPRV_Source_For_Formulas!G37<=0.2,3,IF(SPRV_Source_For_Formulas!G37<=0.5,2,1)) | AI10: =4-AH10 | AJ10: =IF(AND(AF10=3,AG10*AI10>=6),"A",IF(AND(AF10=3,AG10*AI10>=3),"B",IF(AND(AF10=3,AG10*AI10>=1),"C",""))) | AK10: β’モデル＋ガバメントクラウド資料にてIAM最小権限、API監査、CSPM運用が整備されていれば、有効性は高い。ただし初期検知遅延やアラート無視等には注意が必要。 | AL10: =MAX(E10,N10,W10,AF10) | AM10: 2 | AN10: =MAX(G10,P10,Y10,AH10) | AO10: =4-AN10 | AP10: =IF(AND(AL10=3,AM10*AO10>=6),"A",IF(AND(AL10=3,AM10*AO10>=3),"B",IF(AND(AL10=3,AM10*AO10>=1),"C",""))) | AQ10: ="Scenario-level Threat=2; Step1="&I10&" Step2="&R10&" Step3="&AA10&" Step4="&AJ10&" ; Overall Threat fixed=2, Max Mitigation="&AN10&" => Overall="&AP10
A11: 10 | B11: =SPRV_Source_For_Formulas!D38 | C11: VDI Auth server | D11: 外出先からSASE経由でVDI Auth Serverにアクセスする職員の通信を狙い、Citrix Gatewayの既知の脆弱性（例：CVE-2019-19781 など）を悪用して認証バイパスを実行。正規ユーザになりすまし、庁内ネットワークへの初期侵入に成功。 | E11: 3 | F11: 2 | G11: =IF(SPRV_Source_For_Formulas!G38<=0.2,3,IF(SPRV_Source_For_Formulas!G38<=0.5,2,1)) | H11: =4-G11 | I11: =IF(AND(E11=3,F11*H11>=6),"A",IF(AND(E11=3,F11*H11>=3),"B",IF(AND(E11=3,F11*H11>=1),"C",""))) | J11: 根拠（既知脆弱性への限定対応とβ’モデル基準）： 既知脆弱性に対する対策は技術・運用の両面で確立可能 総務省β’モデル「3.2.3 脆弱性管理」では、重大脆弱性に対し「48時間以内にパッチ適用」などのSLAを定めることが推奨されている。 さらに、「脆弱性の収集 → 影響評価 → 優先順位付け → 修正 → 再確認」の脆弱性管理ライフサイクルが整備されていれば、CVE-2019-19781のような既知の脆弱性はカバー可能。 SASE＋WAF＋ZTNAによる多層防御が機能すれば、侵入リスクは大幅に軽減 WAFにおける既知の攻撃シグネチャ対応は一般的であり、IDS/IPSやEDRとの組み合わせで侵入前に阻止できる。 SASEにおけるZTNAの導入により、「未認証端末からの直接到達不可」「職員IDベースの接続制御」「MDMによる端末衛生チェック」が可能。 構成管理や攻撃面最小化（attack surface reduction）も含めた対応が前提 公開Webアプリに対する構成管理（例：DMZ分離、最小限ポート公開、不要機能無効化等）が実施されていれば、既知脆弱性を突かれる余地は少ない。 | K11: =SPRV_Source_For_Formulas!D39 | L11: VDI Auth server | M11: 不正クラウドインスタンスを生成 し、VDI環境全体の制御奪取や横展開を図る | N11: 3 | O11: 2 | P11: =IF(SPRV_Source_For_Formulas!G39<=0.2,3,IF(SPRV_Source_For_Formulas!G39<=0.5,2,1)) | Q11: =4-P11 | R11: =IF(AND(N11=3,O11*Q11>=6),"A",IF(AND(N11=3,O11*Q11>=3),"B",IF(AND(N11=3,O11*Q11>=1),"C",""))) | S11: | 評価観点 | 状況・施策内容 | 評価 | | -------------- | -------------------------------------------- | ------ | | 認証管理（MFA, STS） | Step1対策としてMFA・ZTNA導入済。管理コンソールへの操作は多要素認証必須。 | ★★★（3） | | 権限管理（IAM） | VDI AuthサーバにEC2生成権限は原則付与されていない。ただし一部例外運用が残存。 | ★★☆（2） | | インスタンス作成監視 | CloudTrailでAPI呼び出し監視有効。SIEMと連携し異常通知あり。 | ★★★（3） | | ガードレール制御 | 承認フローは未整備。Terraform/IaCでの標準化はあるが手動例外ルールあり。 | ★★☆（2） | | 構成ミス検出自動化 | CSPM導入済。SSPMは試験導入段階で一部検知カバー不足。 | ★★☆（2） | | 監査と事後対応 | 月次監査と外部監査あり。監査範囲はアカウント・IAM主体でリソース生成は網羅性に欠ける。 | ★★☆（2） |→ 総合評価：2.3 → 切り下げて「レベル2」 | T11: =SPRV_Source_For_Formulas!D40 | U11: VDI server | V11: クラウドAPI（AWS CLI等）を悪用し、スクリプトでクラウド環境へ不正指令を自動送信。 | W11: 3 | X11: 2 | Y11: =IF(SPRV_Source_For_Formulas!G40<=0.2,3,IF(SPRV_Source_For_Formulas!G40<=0.5,2,1)) | Z11: =4-Y11 | AA11: =IF(AND(W11=3,X11*Z11>=6),"A",IF(AND(W11=3,X11*Z11>=3),"B",IF(AND(W11=3,X11*Z11>=1),"C",""))) | AB11: β’モデル「3.3.6 コマンド実行制御」や「3.2.3 脆弱性管理」、Cloud API利用は正規用途でもあり、異常操作の見分けが困難、CSPMやSIEMによる振る舞い監視が必要だが完全ではない | AC11: =SPRV_Source_For_Formulas!D41 | AD11: My Number Administrative System on GovCloud | AE11: スクリプト経由で取得したクラウドリソースを、計算資源として不正使用。DDoS用のC2インフラ構築に用いる例もあり。 | AF11: 3 | AG11: 2 | AH11: =IF(SPRV_Source_For_Formulas!G41<=0.2,3,IF(SPRV_Source_For_Formulas!G41<=0.5,2,1)) | AI11: =4-AH11 | AJ11: =IF(AND(AF11=3,AG11*AI11>=6),"A",IF(AND(AF11=3,AG11*AI11>=3),"B",IF(AND(AF11=3,AG11*AI11>=1),"C",""))) | AK11: 仮想マシンに対するネットワーク分離、IAM制御、ログ監視により不正操作の抑止・検知が可能。推奨対策と合致。 | AL11: =MAX(E11,N11,W11,AF11) | AM11: 2 | AN11: =MAX(G11,P11,Y11,AH11) | AO11: =4-AN11 | AP11: =IF(AND(AL11=3,AM11*AO11>=6),"A",IF(AND(AL11=3,AM11*AO11>=3),"B",IF(AND(AL11=3,AM11*AO11>=1),"C",""))) | AQ11: ="Scenario-level Threat=2; Step1="&I11&" Step2="&R11&" Step3="&AA11&" Step4="&AJ11&" ; Overall Threat fixed=2, Max Mitigation="&AN11&" => Overall="&AP11
A12: 11 | B12: =SPRV_Source_For_Formulas!D42 | C12: VDI Auth server | D12: 外出先からSASE経由でVDI Auth Serverにアクセスする職員の通信を狙い、Citrix Gatewayの既知の脆弱性（例：CVE-2019-19781 など）を悪用して認証バイパスを実行。正規ユーザになりすまし、庁内ネットワークへの初期侵入に成功。 | E12: 3 | F12: 2 | G12: =IF(SPRV_Source_For_Formulas!G42<=0.2,3,IF(SPRV_Source_For_Formulas!G42<=0.5,2,1)) | H12: =4-G12 | I12: =IF(AND(E12=3,F12*H12>=6),"A",IF(AND(E12=3,F12*H12>=3),"B",IF(AND(E12=3,F12*H12>=1),"C",""))) | J12: 根拠（既知脆弱性への限定対応とβ’モデル基準）： 既知脆弱性に対する対策は技術・運用の両面で確立可能 総務省β’モデル「3.2.3 脆弱性管理」では、重大脆弱性に対し「48時間以内にパッチ適用」などのSLAを定めることが推奨されている。 さらに、「脆弱性の収集 → 影響評価 → 優先順位付け → 修正 → 再確認」の脆弱性管理ライフサイクルが整備されていれば、CVE-2019-19781のような既知の脆弱性はカバー可能。 SASE＋WAF＋ZTNAによる多層防御が機能すれば、侵入リスクは大幅に軽減 WAFにおける既知の攻撃シグネチャ対応は一般的であり、IDS/IPSやEDRとの組み合わせで侵入前に阻止できる。 SASEにおけるZTNAの導入により、「未認証端末からの直接到達不可」「職員IDベースの接続制御」「MDMによる端末衛生チェック」が可能。 構成管理や攻撃面最小化（attack surface reduction）も含めた対応が前提 公開Webアプリに対する構成管理（例：DMZ分離、最小限ポート公開、不要機能無効化等）が実施されていれば、既知脆弱性を突かれる余地は少ない。 | K12: =SPRV_Source_For_Formulas!D43 | L12: VDI Auth server | M12: 不正クラウドインスタンスを生成 し、VDI環境全体の制御奪取や横展開を図る | N12: 3 | O12: 2 | P12: =IF(SPRV_Source_For_Formulas!G43<=0.2,3,IF(SPRV_Source_For_Formulas!G43<=0.5,2,1)) | Q12: =4-P12 | R12: =IF(AND(N12=3,O12*Q12>=6),"A",IF(AND(N12=3,O12*Q12>=3),"B",IF(AND(N12=3,O12*Q12>=1),"C",""))) | S12: | 評価観点 | 状況・施策内容 | 評価 | | -------------- | -------------------------------------------- | ------ | | 認証管理（MFA, STS） | Step1対策としてMFA・ZTNA導入済。管理コンソールへの操作は多要素認証必須。 | ★★★（3） | | 権限管理（IAM） | VDI AuthサーバにEC2生成権限は原則付与されていない。ただし一部例外運用が残存。 | ★★☆（2） | | インスタンス作成監視 | CloudTrailでAPI呼び出し監視有効。SIEMと連携し異常通知あり。 | ★★★（3） | | ガードレール制御 | 承認フローは未整備。Terraform/IaCでの標準化はあるが手動例外ルールあり。 | ★★☆（2） | | 構成ミス検出自動化 | CSPM導入済。SSPMは試験導入段階で一部検知カバー不足。 | ★★☆（2） | | 監査と事後対応 | 月次監査と外部監査あり。監査範囲はアカウント・IAM主体でリソース生成は網羅性に欠ける。 | ★★☆（2） |→ 総合評価：2.3 → 切り下げて「レベル2」 | T12: =SPRV_Source_For_Formulas!D44 | U12: VDI server | V12: クラウドAPI（AWS CLI等）を悪用し、スクリプトでクラウド環境へ不正指令を自動送信。 | W12: 3 | X12: 2 | Y12: =IF(SPRV_Source_For_Formulas!G44<=0.2,3,IF(SPRV_Source_For_Formulas!G44<=0.5,2,1)) | Z12: =4-Y12 | AA12: =IF(AND(W12=3,X12*Z12>=6),"A",IF(AND(W12=3,X12*Z12>=3),"B",IF(AND(W12=3,X12*Z12>=1),"C",""))) | AB12: β’モデル「3.3.6 コマンド実行制御」や「3.2.3 脆弱性管理」、Cloud API利用は正規用途でもあり、異常操作の見分けが困難、CSPMやSIEMによる振る舞い監視が必要だが完全ではない | AC12: =SPRV_Source_For_Formulas!D45 | AD12: My Number Administrative System on GovCloud | AE12: 攻撃手法の具体化 Step1〜Step3を経て攻撃者は VDI Auth → VDI Serverを経由し、クラウド管理権限を取得済み。 この状態で、攻撃者は My Number System上の業務データを暗号化し、業務停止やデータロックアウトを引き起こす。 想定される攻撃シナリオは以下： クラウド管理API／CLIを利用して、DBボリュームやストレージ（EBS, Blob, RDS等）を強制暗号化。 新しいKMSキーを攻撃者側で生成・割当し、既存キーを削除または無効化。 OSレベルでスクリプトを投入し、ファイルシステム全体を暗号化（Linux LUKS, Windows BitLocker等）。 Cloud Snapshotやバックアップを削除／無効化し、復旧不能状態に誘導。 結果として、マイナンバー業務全体が停止し、行政サービスに甚大な影響が発生する。 | AF12: 3 | AG12: 2 | AH12: =IF(SPRV_Source_For_Formulas!G45<=0.2,3,IF(SPRV_Source_For_Formulas!G45<=0.5,2,1)) | AI12: =4-AH12 | AJ12: =IF(AND(AF12=3,AG12*AI12>=6),"A",IF(AND(AF12=3,AG12*AI12>=3),"B",IF(AND(AF12=3,AG12*AI12>=1),"C",""))) | AK12: | 評価観点 | 状況・施策内容 | 評価 | | ----------------- | ------------------------------------------------------------ | ------ | | データ暗号化制御 | KMSによる暗号化・権限分離は導入済。ただし攻撃者が管理者権限を奪取した場合、正規の暗号化APIを利用され迂回可能。 | ★★☆（2） | | バックアップとリストア体制 | バックアップは定期取得されているが、スナップショット削除防止機能（Vault Lock等）は未導入で、削除耐性に弱点。 | ★★☆（2） | | API監視・検知 | CloudTrail＋SIEMで監査は有効。しかし暗号化コマンドやスナップショット削除のリアルタイム検知ルールは不完全。 | ★★☆（2） | | 承認フロー | 通常業務での暗号化設定変更は承認必須だが、緊急対応・管理者例外が存在し、悪用される可能性を残している。 | ★★☆（2） | | **CSPM／CIEM逸脱検知** | CSPMは導入済。だが暗号化操作やバックアップ削除の挙動検知は限定的。CIEMによる権限逸脱検知も一部のみ適用。 | ★★☆（2） |→総合評価：２ | AL12: =MAX(E12,N12,W12,AF12) | AM12: 2 | AN12: =MAX(G12,P12,Y12,AH12) | AO12: =4-AN12 | AP12: =IF(AND(AL12=3,AM12*AO12>=6),"A",IF(AND(AL12=3,AM12*AO12>=3),"B",IF(AND(AL12=3,AM12*AO12>=1),"C",""))) | AQ12: ="Scenario-level Threat=2; Step1="&I12&" Step2="&R12&" Step3="&AA12&" Step4="&AJ12&" ; Overall Threat fixed=2, Max Mitigation="&AN12&" => Overall="&AP12
A13: 12 | B13: =SPRV_Source_For_Formulas!D46 | C13: VDI Auth server | D13: 外出先からSASE経由でVDI Auth Serverにアクセスする職員の通信を狙い、Citrix Gatewayの既知の脆弱性（例：CVE-2019-19781 など）を悪用して認証バイパスを実行。正規ユーザになりすまし、庁内ネットワークへの初期侵入に成功。 | E13: 3 | F13: 2 | G13: =IF(SPRV_Source_For_Formulas!G46<=0.2,3,IF(SPRV_Source_For_Formulas!G46<=0.5,2,1)) | H13: =4-G13 | I13: =IF(AND(E13=3,F13*H13>=6),"A",IF(AND(E13=3,F13*H13>=3),"B",IF(AND(E13=3,F13*H13>=1),"C",""))) | J13: 根拠（既知脆弱性への限定対応とβ’モデル基準）： 既知脆弱性に対する対策は技術・運用の両面で確立可能 総務省β’モデル「3.2.3 脆弱性管理」では、重大脆弱性に対し「48時間以内にパッチ適用」などのSLAを定めることが推奨されている。 さらに、「脆弱性の収集 → 影響評価 → 優先順位付け → 修正 → 再確認」の脆弱性管理ライフサイクルが整備されていれば、CVE-2019-19781のような既知の脆弱性はカバー可能。 SASE＋WAF＋ZTNAによる多層防御が機能すれば、侵入リスクは大幅に軽減 WAFにおける既知の攻撃シグネチャ対応は一般的であり、IDS/IPSやEDRとの組み合わせで侵入前に阻止できる。 SASEにおけるZTNAの導入により、「未認証端末からの直接到達不可」「職員IDベースの接続制御」「MDMによる端末衛生チェック」が可能。 構成管理や攻撃面最小化（attack surface reduction）も含めた対応が前提 公開Webアプリに対する構成管理（例：DMZ分離、最小限ポート公開、不要機能無効化等）が実施されていれば、既知脆弱性を突かれる余地は少ない。 | K13: =SPRV_Source_For_Formulas!D47 | L13: VDI Auth server | M13: 不正クラウドインスタンスを生成 し、VDI環境全体の制御奪取や横展開を図る | N13: 3 | O13: 2 | P13: =IF(SPRV_Source_For_Formulas!G47<=0.2,3,IF(SPRV_Source_For_Formulas!G47<=0.5,2,1)) | Q13: =4-P13 | R13: =IF(AND(N13=3,O13*Q13>=6),"A",IF(AND(N13=3,O13*Q13>=3),"B",IF(AND(N13=3,O13*Q13>=1),"C",""))) | S13: | 評価観点 | 状況・施策内容 | 評価 | | -------------- | -------------------------------------------- | ------ | | 認証管理（MFA, STS） | Step1対策としてMFA・ZTNA導入済。管理コンソールへの操作は多要素認証必須。 | ★★★（3） | | 権限管理（IAM） | VDI AuthサーバにEC2生成権限は原則付与されていない。ただし一部例外運用が残存。 | ★★☆（2） | | インスタンス作成監視 | CloudTrailでAPI呼び出し監視有効。SIEMと連携し異常通知あり。 | ★★★（3） | | ガードレール制御 | 承認フローは未整備。Terraform/IaCでの標準化はあるが手動例外ルールあり。 | ★★☆（2） | | 構成ミス検出自動化 | CSPM導入済。SSPMは試験導入段階で一部検知カバー不足。 | ★★☆（2） | | 監査と事後対応 | 月次監査と外部監査あり。監査範囲はアカウント・IAM主体でリソース生成は網羅性に欠ける。 | ★★☆（2） |→ 総合評価：2.3 → 切り下げて「レベル2」 | T13: =SPRV_Source_For_Formulas!D48 | U13: VDI server | V13: クラウドAPI（AWS CLI等）を悪用し、スクリプトでクラウド環境へ不正指令を自動送信。 | W13: 3 | X13: 2 | Y13: =IF(SPRV_Source_For_Formulas!G48<=0.2,3,IF(SPRV_Source_For_Formulas!G48<=0.5,2,1)) | Z13: =4-Y13 | AA13: =IF(AND(W13=3,X13*Z13>=6),"A",IF(AND(W13=3,X13*Z13>=3),"B",IF(AND(W13=3,X13*Z13>=1),"C",""))) | AB13: β’モデル「3.3.6 コマンド実行制御」や「3.2.3 脆弱性管理」、Cloud API利用は正規用途でもあり、異常操作の見分けが困難、CSPMやSIEMによる振る舞い監視が必要だが完全ではない | AC13: =SPRV_Source_For_Formulas!D49 | AD13: My Number Administrative System on GovCloud | AE13: 攻撃手法の具体化 Step1〜Step3で VDI Auth Server → VDI Server に侵入済みの攻撃者は、最終段階として マイナンバー事務系システムのリソース（特に帯域幅）を不正利用 。 攻撃の具体例： マイナンバーシステム上で稼働する VM／コンテナに不正ソフトを導入し、外部DDoS攻撃の踏み台として帯域を消費。 内部帯域を過剰利用し、正規業務処理の遅延や停止を誘発。 帯域消費によりクラウド課金を膨張させ、経済的損害を与える。 通信トラフィックに混在させて、C2通信やデータ流出を隠蔽。 → この攻撃は 「可用性の破壊」と「リソース濫用」 の両面を狙っており、暗号化攻撃（T1486）と比べても検知が難しい特徴がある。 | AF13: 3 | AG13: 2 | AH13: =IF(SPRV_Source_For_Formulas!G49<=0.2,3,IF(SPRV_Source_For_Formulas!G49<=0.5,2,1)) | AI13: =4-AH13 | AJ13: =IF(AND(AF13=3,AG13*AI13>=6),"A",IF(AND(AF13=3,AG13*AI13>=3),"B",IF(AND(AF13=3,AG13*AI13>=1),"C",""))) | AK13: | 評価観点 | 状況・施策内容 | 評価 | | -------------- | ---------------------------------------------------- | ------ | | 帯域使用監視・検知 | CloudWatch／Monitor等で帯域監視は実施。ただしリアルタイム異常検知ルールは一部未整備。 | ★★☆（2） | | DDoS対策 | 一般的なDDoS対策サービスは契約済。ただし全トラフィック網羅ではなく、業務系ネットワークの一部対象外。 | ★★☆（2） | | 出口通信制御 | Proxy・FWルールで外部接続制御済。ただしVDI経由トラフィックは例外許容ケースあり。 | ★★☆（2） | | CSPM／CIEMによる検知 | 過剰権限は定期監査されるが、自動検知ルールは不十分。帯域逸脱の直接検知機能は限定的。 | ★★☆（2） | | 監査と課金異常モニタリング | 月次監査とクラウド課金監視あり。ただし異常利用を即座にアラート化する仕組みは未導入。 | ★★☆（2） |→ 総合評価：2.0 → レベル2 | AL13: =MAX(E13,N13,W13,AF13) | AM13: 2 | AN13: =MAX(G13,P13,Y13,AH13) | AO13: =4-AN13 | AP13: =IF(AND(AL13=3,AM13*AO13>=6),"A",IF(AND(AL13=3,AM13*AO13>=3),"B",IF(AND(AL13=3,AM13*AO13>=1),"C",""))) | AQ13: ="Scenario-level Threat=2; Step1="&I13&" Step2="&R13&" Step3="&AA13&" Step4="&AJ13&" ; Overall Threat fixed=2, Max Mitigation="&AN13&" => Overall="&AP13
A14: 13 | B14: =SPRV_Source_For_Formulas!D50 | C14: VDI Auth server | D14: 外出先からSASE経由でVDI Auth Serverにアクセスする職員の通信を狙い、Citrix Gatewayの既知の脆弱性（例：CVE-2019-19781 など）を悪用して認証バイパスを実行。正規ユーザになりすまし、庁内ネットワークへの初期侵入に成功。 | E14: 3 | F14: 2 | G14: =IF(SPRV_Source_For_Formulas!G50<=0.2,3,IF(SPRV_Source_For_Formulas!G50<=0.5,2,1)) | H14: =4-G14 | I14: =IF(AND(E14=3,F14*H14>=6),"A",IF(AND(E14=3,F14*H14>=3),"B",IF(AND(E14=3,F14*H14>=1),"C",""))) | J14: 根拠（既知脆弱性への限定対応とβ’モデル基準）： 既知脆弱性に対する対策は技術・運用の両面で確立可能 総務省β’モデル「3.2.3 脆弱性管理」では、重大脆弱性に対し「48時間以内にパッチ適用」などのSLAを定めることが推奨されている。 さらに、「脆弱性の収集 → 影響評価 → 優先順位付け → 修正 → 再確認」の脆弱性管理ライフサイクルが整備されていれば、CVE-2019-19781のような既知の脆弱性はカバー可能。 SASE＋WAF＋ZTNAによる多層防御が機能すれば、侵入リスクは大幅に軽減 WAFにおける既知の攻撃シグネチャ対応は一般的であり、IDS/IPSやEDRとの組み合わせで侵入前に阻止できる。 SASEにおけるZTNAの導入により、「未認証端末からの直接到達不可」「職員IDベースの接続制御」「MDMによる端末衛生チェック」が可能。 構成管理や攻撃面最小化（attack surface reduction）も含めた対応が前提 公開Webアプリに対する構成管理（例：DMZ分離、最小限ポート公開、不要機能無効化等）が実施されていれば、既知脆弱性を突かれる余地は少ない。 | K14: =SPRV_Source_For_Formulas!D51 | L14: VDI Auth server | M14: 不正クラウドインスタンスを生成 し、VDI環境全体の制御奪取や横展開を図る | N14: 3 | O14: 2 | P14: =IF(SPRV_Source_For_Formulas!G51<=0.2,3,IF(SPRV_Source_For_Formulas!G51<=0.5,2,1)) | Q14: =4-P14 | R14: =IF(AND(N14=3,O14*Q14>=6),"A",IF(AND(N14=3,O14*Q14>=3),"B",IF(AND(N14=3,O14*Q14>=1),"C",""))) | S14: | 評価観点 | 状況・施策内容 | 評価 | | -------------- | -------------------------------------------- | ------ | | 認証管理（MFA, STS） | Step1対策としてMFA・ZTNA導入済。管理コンソールへの操作は多要素認証必須。 | ★★★（3） | | 権限管理（IAM） | VDI AuthサーバにEC2生成権限は原則付与されていない。ただし一部例外運用が残存。 | ★★☆（2） | | インスタンス作成監視 | CloudTrailでAPI呼び出し監視有効。SIEMと連携し異常通知あり。 | ★★★（3） | | ガードレール制御 | 承認フローは未整備。Terraform/IaCでの標準化はあるが手動例外ルールあり。 | ★★☆（2） | | 構成ミス検出自動化 | CSPM導入済。SSPMは試験導入段階で一部検知カバー不足。 | ★★☆（2） | | 監査と事後対応 | 月次監査と外部監査あり。監査範囲はアカウント・IAM主体でリソース生成は網羅性に欠ける。 | ★★☆（2） |→ 総合評価：2.3 → 切り下げて「レベル2」 | T14: =SPRV_Source_For_Formulas!D52 | U14: VDI server | V14: Azure ADやIAMの信頼関係ポリシーを改変し、他テナントや管理者権限への横展開を狙う。 | W14: 3 | X14: 2 | Y14: =IF(SPRV_Source_For_Formulas!G52<=0.2,3,IF(SPRV_Source_For_Formulas!G52<=0.5,2,1)) | Z14: =4-Y14 | AA14: =IF(AND(W14=3,X14*Z14>=6),"A",IF(AND(W14=3,X14*Z14>=3),"B",IF(AND(W14=3,X14*Z14>=1),"C",""))) | AB14: β’モデル： 「3.3.1 権限管理」「3.3.5 設定変更検知」「3.4.1 操作記録」等。 補足評価：GPO改変は一度権限を奪取された後に、正規操作として行われる可能性が高く、検知・阻止が難しい。 特にVDI環境などでは検知の即時性に限界があるため、評価「2（低）」は妥当。 | AC14: =SPRV_Source_For_Formulas!D53 | AD14: My Number Administrative System on GovCloud | AE14: 信頼関係改変で取得したクラウド権限を用い、複数クラウドサービスを乗っ取り攻撃基盤化。 | AF14: 3 | AG14: 2 | AH14: =IF(SPRV_Source_For_Formulas!G53<=0.2,3,IF(SPRV_Source_For_Formulas!G53<=0.5,2,1)) | AI14: =4-AH14 | AJ14: =IF(AND(AF14=3,AG14*AI14>=6),"A",IF(AND(AF14=3,AG14*AI14>=3),"B",IF(AND(AF14=3,AG14*AI14>=1),"C",""))) | AK14: β’モデル＋ガバメントクラウド資料にてIAM最小権限、API監査、CSPM運用が整備されていれば、有効性は高い。ただし初期検知遅延やアラート無視等には注意が必要。 | AL14: =MAX(E14,N14,W14,AF14) | AM14: 2 | AN14: =MAX(G14,P14,Y14,AH14) | AO14: =4-AN14 | AP14: =IF(AND(AL14=3,AM14*AO14>=6),"A",IF(AND(AL14=3,AM14*AO14>=3),"B",IF(AND(AL14=3,AM14*AO14>=1),"C",""))) | AQ14: ="Scenario-level Threat=2; Step1="&I14&" Step2="&R14&" Step3="&AA14&" Step4="&AJ14&" ; Overall Threat fixed=2, Max Mitigation="&AN14&" => Overall="&AP14
A15: 14 | B15: =SPRV_Source_For_Formulas!D54 | C15: VDI Auth server | D15: 外出先からSASE経由でVDI Auth Serverにアクセスする職員の通信を狙い、Citrix Gatewayの既知の脆弱性（例：CVE-2019-19781 など）を悪用して認証バイパスを実行。正規ユーザになりすまし、庁内ネットワークへの初期侵入に成功。 | E15: 3 | F15: 2 | G15: =IF(SPRV_Source_For_Formulas!G54<=0.2,3,IF(SPRV_Source_For_Formulas!G54<=0.5,2,1)) | H15: =4-G15 | I15: =IF(AND(E15=3,F15*H15>=6),"A",IF(AND(E15=3,F15*H15>=3),"B",IF(AND(E15=3,F15*H15>=1),"C",""))) | J15: 根拠（既知脆弱性への限定対応とβ’モデル基準）： 既知脆弱性に対する対策は技術・運用の両面で確立可能 総務省β’モデル「3.2.3 脆弱性管理」では、重大脆弱性に対し「48時間以内にパッチ適用」などのSLAを定めることが推奨されている。 さらに、「脆弱性の収集 → 影響評価 → 優先順位付け → 修正 → 再確認」の脆弱性管理ライフサイクルが整備されていれば、CVE-2019-19781のような既知の脆弱性はカバー可能。 SASE＋WAF＋ZTNAによる多層防御が機能すれば、侵入リスクは大幅に軽減 WAFにおける既知の攻撃シグネチャ対応は一般的であり、IDS/IPSやEDRとの組み合わせで侵入前に阻止できる。 SASEにおけるZTNAの導入により、「未認証端末からの直接到達不可」「職員IDベースの接続制御」「MDMによる端末衛生チェック」が可能。 構成管理や攻撃面最小化（attack surface reduction）も含めた対応が前提 公開Webアプリに対する構成管理（例：DMZ分離、最小限ポート公開、不要機能無効化等）が実施されていれば、既知脆弱性を突かれる余地は少ない。 | K15: =SPRV_Source_For_Formulas!D55 | L15: VDI Auth server | M15: 不正クラウドインスタンスを生成 し、VDI環境全体の制御奪取や横展開を図る | N15: 3 | O15: 2 | P15: =IF(SPRV_Source_For_Formulas!G55<=0.2,3,IF(SPRV_Source_For_Formulas!G55<=0.5,2,1)) | Q15: =4-P15 | R15: =IF(AND(N15=3,O15*Q15>=6),"A",IF(AND(N15=3,O15*Q15>=3),"B",IF(AND(N15=3,O15*Q15>=1),"C",""))) | S15: | 評価観点 | 状況・施策内容 | 評価 | | -------------- | -------------------------------------------- | ------ | | 認証管理（MFA, STS） | Step1対策としてMFA・ZTNA導入済。管理コンソールへの操作は多要素認証必須。 | ★★★（3） | | 権限管理（IAM） | VDI AuthサーバにEC2生成権限は原則付与されていない。ただし一部例外運用が残存。 | ★★☆（2） | | インスタンス作成監視 | CloudTrailでAPI呼び出し監視有効。SIEMと連携し異常通知あり。 | ★★★（3） | | ガードレール制御 | 承認フローは未整備。Terraform/IaCでの標準化はあるが手動例外ルールあり。 | ★★☆（2） | | 構成ミス検出自動化 | CSPM導入済。SSPMは試験導入段階で一部検知カバー不足。 | ★★☆（2） | | 監査と事後対応 | 月次監査と外部監査あり。監査範囲はアカウント・IAM主体でリソース生成は網羅性に欠ける。 | ★★☆（2） |→ 総合評価：2.3 → 切り下げて「レベル2」 | T15: =SPRV_Source_For_Formulas!D56 | U15: VDI server | V15: Azure ADやIAMの信頼関係ポリシーを改変し、他テナントや管理者権限への横展開を狙う。 | W15: 3 | X15: 2 | Y15: =IF(SPRV_Source_For_Formulas!G56<=0.2,3,IF(SPRV_Source_For_Formulas!G56<=0.5,2,1)) | Z15: =4-Y15 | AA15: =IF(AND(W15=3,X15*Z15>=6),"A",IF(AND(W15=3,X15*Z15>=3),"B",IF(AND(W15=3,X15*Z15>=1),"C",""))) | AB15: β’モデル：「3.3.1 権限管理」「3.3.5 設定変更検知」「3.4.1 操作記録」等。 補足評価：GPO改変は一度権限を奪取された後に、正規操作として行われる可能性が高く、検知・阻止が難しい。 特にVDI環境などでは検知の即時性に限界があるため、対策有効率評価「1（低）」は妥当。 | AC15: =SPRV_Source_For_Formulas!D57 | AD15: My Number Administrative System on GovCloud | AE15: クラウドインスタンスにマルウェアを展開し、計算リソースを違法マイニングや外部DDoSに悪用。 | AF15: 3 | AG15: 2 | AH15: =IF(SPRV_Source_For_Formulas!G57<=0.2,3,IF(SPRV_Source_For_Formulas!G57<=0.5,2,1)) | AI15: =4-AH15 | AJ15: =IF(AND(AF15=3,AG15*AI15>=6),"A",IF(AND(AF15=3,AG15*AI15>=3),"B",IF(AND(AF15=3,AG15*AI15>=1),"C",""))) | AK15: 仮想マシンに対するネットワーク分離、IAM制御、ログ監視により不正操作の抑止・検知が可能。推奨対策と合致。 | AL15: =MAX(E15,N15,W15,AF15) | AM15: 2 | AN15: =MAX(G15,P15,Y15,AH15) | AO15: =4-AN15 | AP15: =IF(AND(AL15=3,AM15*AO15>=6),"A",IF(AND(AL15=3,AM15*AO15>=3),"B",IF(AND(AL15=3,AM15*AO15>=1),"C",""))) | AQ15: ="Scenario-level Threat=2; Step1="&I15&" Step2="&R15&" Step3="&AA15&" Step4="&AJ15&" ; Overall Threat fixed=2, Max Mitigation="&AN15&" => Overall="&AP15
A16: 15 | B16: =SPRV_Source_For_Formulas!D58 | C16: VDI Auth server | D16: 外出先からSASE経由でVDI Auth Serverにアクセスする職員の通信を狙い、Citrix Gatewayの既知の脆弱性（例：CVE-2019-19781 など）を悪用して認証バイパスを実行。正規ユーザになりすまし、庁内ネットワークへの初期侵入に成功。 | E16: 3 | F16: 2 | G16: =IF(SPRV_Source_For_Formulas!G58<=0.2,3,IF(SPRV_Source_For_Formulas!G58<=0.5,2,1)) | H16: =4-G16 | I16: =IF(AND(E16=3,F16*H16>=6),"A",IF(AND(E16=3,F16*H16>=3),"B",IF(AND(E16=3,F16*H16>=1),"C",""))) | J16: 根拠（既知脆弱性への限定対応とβ’モデル基準）： 既知脆弱性に対する対策は技術・運用の両面で確立可能 総務省β’モデル「3.2.3 脆弱性管理」では、重大脆弱性に対し「48時間以内にパッチ適用」などのSLAを定めることが推奨されている。 さらに、「脆弱性の収集 → 影響評価 → 優先順位付け → 修正 → 再確認」の脆弱性管理ライフサイクルが整備されていれば、CVE-2019-19781のような既知の脆弱性はカバー可能。 SASE＋WAF＋ZTNAによる多層防御が機能すれば、侵入リスクは大幅に軽減 WAFにおける既知の攻撃シグネチャ対応は一般的であり、IDS/IPSやEDRとの組み合わせで侵入前に阻止できる。 SASEにおけるZTNAの導入により、「未認証端末からの直接到達不可」「職員IDベースの接続制御」「MDMによる端末衛生チェック」が可能。 構成管理や攻撃面最小化（attack surface reduction）も含めた対応が前提 公開Webアプリに対する構成管理（例：DMZ分離、最小限ポート公開、不要機能無効化等）が実施されていれば、既知脆弱性を突かれる余地は少ない。 | K16: =SPRV_Source_For_Formulas!D59 | L16: VDI Auth server | M16: 不正クラウドインスタンスを生成 し、VDI環境全体の制御奪取や横展開を図る | N16: 3 | O16: 2 | P16: =IF(SPRV_Source_For_Formulas!G59<=0.2,3,IF(SPRV_Source_For_Formulas!G59<=0.5,2,1)) | Q16: =4-P16 | R16: =IF(AND(N16=3,O16*Q16>=6),"A",IF(AND(N16=3,O16*Q16>=3),"B",IF(AND(N16=3,O16*Q16>=1),"C",""))) | S16: | 評価観点 | 状況・施策内容 | 評価 | | -------------- | -------------------------------------------- | ------ | | 認証管理（MFA, STS） | Step1対策としてMFA・ZTNA導入済。管理コンソールへの操作は多要素認証必須。 | ★★★（3） | | 権限管理（IAM） | VDI AuthサーバにEC2生成権限は原則付与されていない。ただし一部例外運用が残存。 | ★★☆（2） | | インスタンス作成監視 | CloudTrailでAPI呼び出し監視有効。SIEMと連携し異常通知あり。 | ★★★（3） | | ガードレール制御 | 承認フローは未整備。Terraform/IaCでの標準化はあるが手動例外ルールあり。 | ★★☆（2） | | 構成ミス検出自動化 | CSPM導入済。SSPMは試験導入段階で一部検知カバー不足。 | ★★☆（2） | | 監査と事後対応 | 月次監査と外部監査あり。監査範囲はアカウント・IAM主体でリソース生成は網羅性に欠ける。 | ★★☆（2） |→ 総合評価：2.3 → 切り下げて「レベル2」 | T16: =SPRV_Source_For_Formulas!D60 | U16: VDI server | V16: Azure ADやIAMの信頼関係ポリシーを改変し、他テナントや管理者権限への横展開を狙う。 | W16: 3 | X16: 2 | Y16: =IF(SPRV_Source_For_Formulas!G60<=0.2,3,IF(SPRV_Source_For_Formulas!G60<=0.5,2,1)) | Z16: =4-Y16 | AA16: =IF(AND(W16=3,X16*Z16>=6),"A",IF(AND(W16=3,X16*Z16>=3),"B",IF(AND(W16=3,X16*Z16>=1),"C",""))) | AB16: β’モデル： 「3.3.1 権限管理」「3.3.5 設定変更検知」「3.4.1 操作記録」等。 補足評価： GPO改変は一度権限を奪取された後に、正規操作として行われる可能性が高く、検知・阻止が難しい。 特にVDI環境などでは検知の即時性に限界があるため、評価「2（低）」は妥当。 | AC16: =SPRV_Source_For_Formulas!D61 | AD16: My Number Administrative System on GovCloud | AE16: 攻撃手法の具体化 Step1〜Step3を経て攻撃者は VDI Auth → VDI Serverを経由し、クラウド管理権限を取得済み。 この状態で、攻撃者は My Number System上の業務データを暗号化し、業務停止やデータロックアウトを引き起こす。 想定される攻撃シナリオは以下： クラウド管理API／CLIを利用して、DBボリュームやストレージ（EBS, Blob, RDS等）を強制暗号化。 新しいKMSキーを攻撃者側で生成・割当し、既存キーを削除または無効化。 OSレベルでスクリプトを投入し、ファイルシステム全体を暗号化（Linux LUKS, Windows BitLocker等）。 Cloud Snapshotやバックアップを削除／無効化し、復旧不能状態に誘導。 結果として、マイナンバー業務全体が停止し、行政サービスに甚大な影響が発生する。 | AF16: 3 | AG16: 2 | AH16: =IF(SPRV_Source_For_Formulas!G61<=0.2,3,IF(SPRV_Source_For_Formulas!G61<=0.5,2,1)) | AI16: =4-AH16 | AJ16: =IF(AND(AF16=3,AG16*AI16>=6),"A",IF(AND(AF16=3,AG16*AI16>=3),"B",IF(AND(AF16=3,AG16*AI16>=1),"C",""))) | AK16: | 評価観点 | 状況・施策内容 | 評価 | | ----------------- | ------------------------------------------------------------ | ------ | | データ暗号化制御 | KMSによる暗号化・権限分離は導入済。ただし攻撃者が管理者権限を奪取した場合、正規の暗号化APIを利用され迂回可能。 | ★★☆（2） | | バックアップとリストア体制 | バックアップは定期取得されているが、スナップショット削除防止機能（Vault Lock等）は未導入で、削除耐性に弱点。 | ★★☆（2） | | API監視・検知 | CloudTrail＋SIEMで監査は有効。しかし暗号化コマンドやスナップショット削除のリアルタイム検知ルールは不完全。 | ★★☆（2） | | 承認フロー | 通常業務での暗号化設定変更は承認必須だが、緊急対応・管理者例外が存在し、悪用される可能性を残している。 | ★★☆（2） | | **CSPM／CIEM逸脱検知** | CSPMは導入済。だが暗号化操作やバックアップ削除の挙動検知は限定的。CIEMによる権限逸脱検知も一部のみ適用。 | ★★☆（2） |→総合評価：２ | AL16: =MAX(E16,N16,W16,AF16) | AM16: 2 | AN16: =MAX(G16,P16,Y16,AH16) | AO16: =4-AN16 | AP16: =IF(AND(AL16=3,AM16*AO16>=6),"A",IF(AND(AL16=3,AM16*AO16>=3),"B",IF(AND(AL16=3,AM16*AO16>=1),"C",""))) | AQ16: ="Scenario-level Threat=2; Step1="&I16&" Step2="&R16&" Step3="&AA16&" Step4="&AJ16&" ; Overall Threat fixed=2, Max Mitigation="&AN16&" => Overall="&AP16
