Workbook

Sheet ScenarioC_Attack_Tree_64Combina
A1: Step1_TechniqueID | B1: description | D1: Business Impact | E1: Threat | F1: Mitigation | G1: Vulnerability | H1: Risk Score | I1: 対策根拠（既知脆弱性） | J1: Step2_TechniqueID | K1: description | L1: Business Impact | M1: Threat | N1: Mitigation | O1: Vulnerability | P1: Risk Score | Q1: 対策根拠（既知脆弱性） | R1: Step3_TechniqueID | S1: description | T1: Business Impact | U1: Threat | V1: Mitigation | W1: Vulnerability | X1: Risk Score | Y1: 対策根拠（既知脆弱性） | Z1: Step4_TechniqueID | AA1: description | AB1: Business Impact | AC1: Threat | AD1: Mitigation | AE1: Vulnerability | AF1: Risk Score | AG1: 対策根拠（既知脆弱性） | AP1: Business Impact | AQ1: Threat | AR1: Vulnerability | AS1: Mitigation | AT1: Risk Score | AU1: 判定根拠
A2: =SPRV_Source_For_Formulas!D2 -> T1189 | B2: 攻撃手法の具体化 運用管理者が、日常的に利用する 業務関連Webポータル／ガバメントクラウド管理サイト にアクセス。 攻撃者がWebサイトを改ざんし、マルウェアを仕込んでいる。 管理者が 閲覧またはファイルをダウンロードするだけで自動的にマルウェア感染。 結果として： 管理者端末を初期感染させ、GovCloud管理コンソールへの認証情報（セッションCookie、MFAトークン等）を窃取 その後の クラウドリソース操作権限の奪取 に直結。 | D2: 3 | E2: 1 | F2: =IF(SPRV_Source_For_Formulas!G2<=0.2,3,IF(SPRV_Source_For_Formulas!G2<=0.5,2,1)) -> 3 | G2: =4-F2 -> 1 | H2: =IF(AND(D2=3,E2*G2>=6),"A",IF(AND(D2=3,E2*G2>=3),"B",IF(AND(D2=3,E2*G2>=1),"C",""))) -> C | I2: | 評価観点 | 状況・施策内容 | 評価 | | ----------------- | -------------------------------------------------- | ------ | | エンドポイント防御（EDR/AV） | EDR導入済み、シグネチャ更新自動化。未知マルウェアにはふるまい検知依存。 | ★★★（3） | | Webフィルタリング／改ざん検知 | SWG導入済。不審サイト遮断可能。ただし正規業務ポータル改ざんのゼロデイ検知は困難。 | ★★☆（2） | | パッチ管理／ソフト更新 | ブラウザ・OSはMDMで強制更新。48時間以内に重大パッチ適用（β’モデル準拠）。 | ★★★（3） | | アクセス制御（ZTNA） | 管理端末以外からのアクセスは不可。職員ID＋MFA必須。ただし端末感染時のセッション乗っ取りは残る。 | ★★☆（2） | | ログ監視・SOC連携 | SOC監視下にあり、端末挙動ログをSIEMで分析。ただし初期感染段階での即時検知は限定的。 | ★★☆（2） |→ 総合評価：2.4 → 切り上げて レベル3 | J2: =SPRV_Source_For_Formulas!D3 -> T1578.002 | K2: クラウド管理権限を悪用し、Update Serverと同一VPC内または他VPCに不正なクラウドインスタンス（C2やバックドア用）を作成し、横展開を試みる | L2: 3 | M2: 1 | N2: =IF(SPRV_Source_For_Formulas!G3<=0.2,3,IF(SPRV_Source_For_Formulas!G3<=0.5,2,1)) -> 2 | O2: =4-N2 -> 2 | P2: =IF(AND(L2=3,M2*O2>=6),"A",IF(AND(L2=3,M2*O2>=3),"B",IF(AND(L2=3,M2*O2>=1),"C",""))) -> C | Q2: 評価観点 評価内容 評価 認証管理 Step1でMFA導入・監視ログ・アラート通知設定済み ★★★（3） 権限管理（IAM） 管理者権限の最小化、RBAC運用、Update ServerのIAMロールも定期監査対象 ★★★（3） インスタンス作成の監視 CloudTrail相当のログ収集有効化とSIEM連携、異常インスタンス作成アラート設定 ★★★（3） ガードレール制御 テンプレート制限・事前承認フロー未導入（自動インスタンス作成が可能な設定あり） ★★☆（2） 構成ミスの検出自動化 CSPMは導入済、ただしSSPMは未導入 ★★☆（2） 監査と事後対応 月次の操作監査あり。外部監査は年1回 ★★☆（2） → 総合評価：2.5 → 切り上げて 3（レベル3） | R2: =SPRV_Source_For_Formulas!D4 -> T1651 | S2: クラウドAPI/CLIを利用してマイナンバー系業務システムに対し、スナップショット取得・設定変更・証拠隠滅などの攻撃的管理コマンドを実行 | T2: 3 | U2: 1 | V2: =IF(SPRV_Source_For_Formulas!G4<=0.2,3,IF(SPRV_Source_For_Formulas!G4<=0.5,2,1)) -> 3 | W2: =4-V2 -> 1 | X2: =IF(AND(T2=3,U2*W2>=6),"A",IF(AND(T2=3,U2*W2>=3),"B",IF(AND(T2=3,U2*W2>=1),"C",""))) -> C | Y2: | 評価項目 | 状況・施策内容 | 評価 | | ----------- | ------------------------------------------------------------ | ------ | | 認証管理（MFA） | CLI/APIアクセスにもMFA必須。IAMユーザではなくロールベースの一時トークンを使用 | ★★★（3） | | ログ監視・改ざん防止 | CloudTrail＋WORMストレージでログ改ざん防止。ただし外部SIEM連携は一部の操作のみ対象 | ★★☆（2） | | 操作の定型化 | TerraformによるInfrastructure as Codeはマイナンバー系でも導入済。ただし一部GUI設定残存 | ★★☆（2） | | RBACとワークフロー | 管理者権限の委譲に承認フローあり。CLI操作には内部発番のチケット必要 | ★★★（3） | | 検知・リアルタイム対応 | GuardDuty相当の異常API検知機能は未導入（導入予定あり） | ★☆☆（1） |→ 総合評価：2.2 → 切り下げて ★★（2） | Z2: =SPRV_Source_For_Formulas!D5 -> T1486 | AA2: クラウドリソース（仮想マシン等）を乗っ取り、暗号資産マイニング/DDoS中継に悪用。 | AB2: 3 | AC2: 1 | AD2: =IF(SPRV_Source_For_Formulas!G5<=0.2,3,IF(SPRV_Source_For_Formulas!G5<=0.5,2,1)) -> 3 | AE2: =4-AD2 -> 1 | AF2: =IF(AND(AB2=3,AC2*AE2>=6),"A",IF(AND(AB2=3,AC2*AE2>=3),"B",IF(AND(AB2=3,AC2*AE2>=1),"C",""))) -> C | AG2: CSPMによるリソース使用率監視、アラート設定が有効（β’3.4.3相当）。 | AP2: =MAX(D2,L2,T2,AB2) -> 3 | AQ2: 1 | AR2: =4-AS2 -> 1 | AS2: =MAX(F2,N2,V2,AD2) -> 3 | AT2: =IF(AND(AP2=3,AQ2*AR2>=6),"A",IF(AND(AP2=3,AQ2*AR2>=3),"B",IF(AND(AP2=3,AQ2*AR2>=1),"C",""))) -> C | AU2: ="Scenario-level Threat=1; Step1="&H2&" Step2="&P2&" Step3="&X2&" Step4="&AF2&" ; Overall Threat fixed=1, Max Mitigation="&AS2&" => Overall="&AT2 -> Scenario-level Threat=1; Step1=C Step2=C Step3=C Step4=C ; Overall Threat fixed=1, Max Mitigation=3 => Overall=C
A3: =SPRV_Source_For_Formulas!D6 -> T1189 | B3: 攻撃手法の具体化 運用管理者が、日常的に利用する 業務関連Webポータル／ガバメントクラウド管理サイト にアクセス。 攻撃者がWebサイトを改ざんし、マルウェアを仕込んでいる。 管理者が 閲覧またはファイルをダウンロードするだけで自動的にマルウェア感染。 結果として： 管理者端末を初期感染させ、GovCloud管理コンソールへの認証情報（セッションCookie、MFAトークン等）を窃取 その後の クラウドリソース操作権限の奪取 に直結。 | D3: 3 | E3: 1 | F3: =IF(SPRV_Source_For_Formulas!G6<=0.2,3,IF(SPRV_Source_For_Formulas!G6<=0.5,2,1)) -> 3 | G3: =4-F3 -> 1 | H3: =IF(AND(D3=3,E3*G3>=6),"A",IF(AND(D3=3,E3*G3>=3),"B",IF(AND(D3=3,E3*G3>=1),"C",""))) -> C | I3: | 評価観点 | 状況・施策内容 | 評価 | | ----------------- | -------------------------------------------------- | ------ | | エンドポイント防御（EDR/AV） | EDR導入済み、シグネチャ更新自動化。未知マルウェアにはふるまい検知依存。 | ★★★（3） | | Webフィルタリング／改ざん検知 | SWG導入済。不審サイト遮断可能。ただし正規業務ポータル改ざんのゼロデイ検知は困難。 | ★★☆（2） | | パッチ管理／ソフト更新 | ブラウザ・OSはMDMで強制更新。48時間以内に重大パッチ適用（β’モデル準拠）。 | ★★★（3） | | アクセス制御（ZTNA） | 管理端末以外からのアクセスは不可。職員ID＋MFA必須。ただし端末感染時のセッション乗っ取りは残る。 | ★★☆（2） | | ログ監視・SOC連携 | SOC監視下にあり、端末挙動ログをSIEMで分析。ただし初期感染段階での即時検知は限定的。 | ★★☆（2） |→ 総合評価：2.4 → 切り上げて レベル3 | J3: =SPRV_Source_For_Formulas!D7 -> T1578.002 | K3: クラウド管理権限を悪用し、Update Serverと同一VPC内または他VPCに不正なクラウドインスタンス（C2やバックドア用）を作成し、横展開を試みる | L3: 3 | M3: 1 | N3: =IF(SPRV_Source_For_Formulas!G7<=0.2,3,IF(SPRV_Source_For_Formulas!G7<=0.5,2,1)) -> 2 | O3: =4-N3 -> 2 | P3: =IF(AND(L3=3,M3*O3>=6),"A",IF(AND(L3=3,M3*O3>=3),"B",IF(AND(L3=3,M3*O3>=1),"C",""))) -> C | Q3: 評価観点 評価内容 評価 認証管理 Step1でMFA導入・監視ログ・アラート通知設定済み ★★★（3） 権限管理（IAM） 管理者権限の最小化、RBAC運用、Update ServerのIAMロールも定期監査対象 ★★★（3） インスタンス作成の監視 CloudTrail相当のログ収集有効化とSIEM連携、異常インスタンス作成アラート設定 ★★★（3） ガードレール制御 テンプレート制限・事前承認フロー未導入（自動インスタンス作成が可能な設定あり） ★★☆（2） 構成ミスの検出自動化 CSPMは導入済、ただしSSPMは未導入 ★★☆（2） 監査と事後対応 月次の操作監査あり。外部監査は年1回 ★★☆（2） → 総合評価：2.5 → 切り上げて 3（レベル3） | R3: =SPRV_Source_For_Formulas!D8 -> T1651 | S3: クラウドAPI/CLIを利用してマイナンバー系業務システムに対し、スナップショット取得・設定変更・証拠隠滅などの攻撃的管理コマンドを実行 | T3: 3 | U3: 1 | V3: =IF(SPRV_Source_For_Formulas!G8<=0.2,3,IF(SPRV_Source_For_Formulas!G8<=0.5,2,1)) -> 3 | W3: =4-V3 -> 1 | X3: =IF(AND(T3=3,U3*W3>=6),"A",IF(AND(T3=3,U3*W3>=3),"B",IF(AND(T3=3,U3*W3>=1),"C",""))) -> C | Y3: | 評価項目 | 状況・施策内容 | 評価 | | ----------- | ------------------------------------------------------------ | ------ | | 認証管理（MFA） | CLI/APIアクセスにもMFA必須。IAMユーザではなくロールベースの一時トークンを使用 | ★★★（3） | | ログ監視・改ざん防止 | CloudTrail＋WORMストレージでログ改ざん防止。ただし外部SIEM連携は一部の操作のみ対象 | ★★☆（2） | | 操作の定型化 | TerraformによるInfrastructure as Codeはマイナンバー系でも導入済。ただし一部GUI設定残存 | ★★☆（2） | | RBACとワークフロー | 管理者権限の委譲に承認フローあり。CLI操作には内部発番のチケット必要 | ★★★（3） | | 検知・リアルタイム対応 | GuardDuty相当の異常API検知機能は未導入（導入予定あり） | ★☆☆（1） |→ 総合評価：2.2 → 切り下げて ★★（2） | Z3: =SPRV_Source_For_Formulas!D9 -> T1496.001 | AA3: 計算リソースを秘匿的に不正利用（Compute Hijacking）。 | AB3: 3 | AC3: 1 | AD3: =IF(SPRV_Source_For_Formulas!G9<=0.2,3,IF(SPRV_Source_For_Formulas!G9<=0.5,2,1)) -> 2 | AE3: =4-AD3 -> 2 | AF3: =IF(AND(AB3=3,AC3*AE3>=6),"A",IF(AND(AB3=3,AC3*AE3>=3),"B",IF(AND(AB3=3,AC3*AE3>=1),"C",""))) -> C | AG3: モニタリング＋しきい値制限（Azure Monitor等）で抑止可能。 | AP3: =MAX(D3,L3,T3,AB3) -> 3 | AQ3: 1 | AR3: =4-AS3 -> 1 | AS3: =MAX(F3,N3,V3,AD3) -> 3 | AT3: =IF(AND(AP3=3,AQ3*AR3>=6),"A",IF(AND(AP3=3,AQ3*AR3>=3),"B",IF(AND(AP3=3,AQ3*AR3>=1),"C",""))) -> C | AU3: ="Scenario-level Threat=1; Step1="&H3&" Step2="&P3&" Step3="&X3&" Step4="&AF3&" ; Overall Threat fixed=1, Max Mitigation="&AS3&" => Overall="&AT3 -> Scenario-level Threat=1; Step1=C Step2=C Step3=C Step4=C ; Overall Threat fixed=1, Max Mitigation=3 => Overall=C
A4: =SPRV_Source_For_Formulas!D10 -> T1189 | B4: 攻撃手法の具体化 運用管理者が、日常的に利用する 業務関連Webポータル／ガバメントクラウド管理サイト にアクセス。 攻撃者がWebサイトを改ざんし、マルウェアを仕込んでいる。 管理者が 閲覧またはファイルをダウンロードするだけで自動的にマルウェア感染。 結果として： 管理者端末を初期感染させ、GovCloud管理コンソールへの認証情報（セッションCookie、MFAトークン等）を窃取 その後の クラウドリソース操作権限の奪取 に直結。 | D4: 3 | E4: 1 | F4: =IF(SPRV_Source_For_Formulas!G10<=0.2,3,IF(SPRV_Source_For_Formulas!G10<=0.5,2,1)) -> 3 | G4: =4-F4 -> 1 | H4: =IF(AND(D4=3,E4*G4>=6),"A",IF(AND(D4=3,E4*G4>=3),"B",IF(AND(D4=3,E4*G4>=1),"C",""))) -> C | I4: | 評価観点 | 状況・施策内容 | 評価 | | ----------------- | -------------------------------------------------- | ------ | | エンドポイント防御（EDR/AV） | EDR導入済み、シグネチャ更新自動化。未知マルウェアにはふるまい検知依存。 | ★★★（3） | | Webフィルタリング／改ざん検知 | SWG導入済。不審サイト遮断可能。ただし正規業務ポータル改ざんのゼロデイ検知は困難。 | ★★☆（2） | | パッチ管理／ソフト更新 | ブラウザ・OSはMDMで強制更新。48時間以内に重大パッチ適用（β’モデル準拠）。 | ★★★（3） | | アクセス制御（ZTNA） | 管理端末以外からのアクセスは不可。職員ID＋MFA必須。ただし端末感染時のセッション乗っ取りは残る。 | ★★☆（2） | | ログ監視・SOC連携 | SOC監視下にあり、端末挙動ログをSIEMで分析。ただし初期感染段階での即時検知は限定的。 | ★★☆（2） |→ 総合評価：2.4 → 切り上げて レベル3 | J4: =SPRV_Source_For_Formulas!D11 -> T1578.002 | K4: クラウド管理権限を悪用し、Update Serverと同一VPC内または他VPCに不正なクラウドインスタンス（C2やバックドア用）を作成し、横展開を試みる | L4: 3 | M4: 1 | N4: =IF(SPRV_Source_For_Formulas!G11<=0.2,3,IF(SPRV_Source_For_Formulas!G11<=0.5,2,1)) -> 2 | O4: =4-N4 -> 2 | P4: =IF(AND(L4=3,M4*O4>=6),"A",IF(AND(L4=3,M4*O4>=3),"B",IF(AND(L4=3,M4*O4>=1),"C",""))) -> C | Q4: 評価観点 評価内容 評価 認証管理 Step1でMFA導入・監視ログ・アラート通知設定済み ★★★（3） 権限管理（IAM） 管理者権限の最小化、RBAC運用、Update ServerのIAMロールも定期監査対象 ★★★（3） インスタンス作成の監視 CloudTrail相当のログ収集有効化とSIEM連携、異常インスタンス作成アラート設定 ★★★（3） ガードレール制御 テンプレート制限・事前承認フロー未導入（自動インスタンス作成が可能な設定あり） ★★☆（2） 構成ミスの検出自動化 CSPMは導入済、ただしSSPMは未導入 ★★☆（2） 監査と事後対応 月次の操作監査あり。外部監査は年1回 ★★☆（2） → 総合評価：2.5 → 切り上げて 3（レベル3） | R4: =SPRV_Source_For_Formulas!D12 -> T1651 | S4: クラウドAPI/CLIを利用してマイナンバー系業務システムに対し、スナップショット取得・設定変更・証拠隠滅などの攻撃的管理コマンドを実行 | T4: 3 | U4: 1 | V4: =IF(SPRV_Source_For_Formulas!G12<=0.2,3,IF(SPRV_Source_For_Formulas!G12<=0.5,2,1)) -> 3 | W4: =4-V4 -> 1 | X4: =IF(AND(T4=3,U4*W4>=6),"A",IF(AND(T4=3,U4*W4>=3),"B",IF(AND(T4=3,U4*W4>=1),"C",""))) -> C | Y4: | 評価項目 | 状況・施策内容 | 評価 | | ----------- | ------------------------------------------------------------ | ------ | | 認証管理（MFA） | CLI/APIアクセスにもMFA必須。IAMユーザではなくロールベースの一時トークンを使用 | ★★★（3） | | ログ監視・改ざん防止 | CloudTrail＋WORMストレージでログ改ざん防止。ただし外部SIEM連携は一部の操作のみ対象 | ★★☆（2） | | 操作の定型化 | TerraformによるInfrastructure as Codeはマイナンバー系でも導入済。ただし一部GUI設定残存 | ★★☆（2） | | RBACとワークフロー | 管理者権限の委譲に承認フローあり。CLI操作には内部発番のチケット必要 | ★★★（3） | | 検知・リアルタイム対応 | GuardDuty相当の異常API検知機能は未導入（導入予定あり） | ★☆☆（1） |→ 総合評価：2.2 → 切り下げて ★★（2） | Z4: =SPRV_Source_For_Formulas!D13 -> T1496.004 | AA4: クラウドAPI経由で Proxy Server on GovCloud に対して以下を実施： EC2/EBSなどのストレージを暗号化（KMSキーを使って再暗号化またはKMSキーを削除） OSレベルでスクリプトを投入し、ボリュームをBitLockerやLinuxのLUKS等で暗号化 システムログやスナップショットの削除による復旧妨害 IAMの一時的制御権を用いた“復旧阻止”工作 ガバメントクラウド内で復旧オプションが封じられた状態にされることで、実質的なデータロックアウトが生じる。 | AB4: 3 | AC4: 1 | AD4: =IF(SPRV_Source_For_Formulas!G13<=0.2,3,IF(SPRV_Source_For_Formulas!G13<=0.5,2,1)) -> 2 | AE4: =4-AD4 -> 2 | AF4: =IF(AND(AB4=3,AC4*AE4>=6),"A",IF(AND(AB4=3,AC4*AE4>=3),"B",IF(AND(AB4=3,AC4*AE4>=1),"C",""))) -> C | AG4: | 評価観点 | 評価内容 | 評価 | | ------------- | ---------------------------------------------------- | ------ | | データ暗号化制御 | KMSのアクセス制御やEBS暗号化ポリシーは一部導入。ただしProxy Server単体の制御は未記載。 | ★★☆（2） | | ログ・スナップショット保全 | CloudTrailログ保全は一部設定あり。スナップショット削除阻止や整合性保全策は記載なし。 | ★★☆（2） | | API実行制御 | Step3でAPI攻撃が成立済のため、IAM/API制御に抜けあり。SSPM未導入。 | ★☆☆（1） |→ 総合評価：1.7 → 切り捨てて「レベル1」 | AP4: =MAX(D4,L4,T4,AB4) -> 3 | AQ4: 1 | AR4: =4-AS4 -> 1 | AS4: =MAX(F4,N4,V4,AD4) -> 3 | AT4: =IF(AND(AP4=3,AQ4*AR4>=6),"A",IF(AND(AP4=3,AQ4*AR4>=3),"B",IF(AND(AP4=3,AQ4*AR4>=1),"C",""))) -> C | AU4: ="Scenario-level Threat=1; Step1="&H4&" Step2="&P4&" Step3="&X4&" Step4="&AF4&" ; Overall Threat fixed=1, Max Mitigation="&AS4&" => Overall="&AT4 -> Scenario-level Threat=1; Step1=C Step2=C Step3=C Step4=C ; Overall Threat fixed=1, Max Mitigation=3 => Overall=C
A5: =SPRV_Source_For_Formulas!D14 -> T1189 | B5: 攻撃手法の具体化 運用管理者が、日常的に利用する 業務関連Webポータル／ガバメントクラウド管理サイト にアクセス。 攻撃者がWebサイトを改ざんし、マルウェアを仕込んでいる。 管理者が 閲覧またはファイルをダウンロードするだけで自動的にマルウェア感染。 結果として： 管理者端末を初期感染させ、GovCloud管理コンソールへの認証情報（セッションCookie、MFAトークン等）を窃取 その後の クラウドリソース操作権限の奪取 に直結。 | D5: 3 | E5: 1 | F5: =IF(SPRV_Source_For_Formulas!G14<=0.2,3,IF(SPRV_Source_For_Formulas!G14<=0.5,2,1)) -> 3 | G5: =4-F5 -> 1 | H5: =IF(AND(D5=3,E5*G5>=6),"A",IF(AND(D5=3,E5*G5>=3),"B",IF(AND(D5=3,E5*G5>=1),"C",""))) -> C | I5: | 評価観点 | 状況・施策内容 | 評価 | | ----------------- | -------------------------------------------------- | ------ | | エンドポイント防御（EDR/AV） | EDR導入済み、シグネチャ更新自動化。未知マルウェアにはふるまい検知依存。 | ★★★（3） | | Webフィルタリング／改ざん検知 | SWG導入済。不審サイト遮断可能。ただし正規業務ポータル改ざんのゼロデイ検知は困難。 | ★★☆（2） | | パッチ管理／ソフト更新 | ブラウザ・OSはMDMで強制更新。48時間以内に重大パッチ適用（β’モデル準拠）。 | ★★★（3） | | アクセス制御（ZTNA） | 管理端末以外からのアクセスは不可。職員ID＋MFA必須。ただし端末感染時のセッション乗っ取りは残る。 | ★★☆（2） | | ログ監視・SOC連携 | SOC監視下にあり、端末挙動ログをSIEMで分析。ただし初期感染段階での即時検知は限定的。 | ★★☆（2） |→ 総合評価：2.4 → 切り上げて レベル3 | J5: =SPRV_Source_For_Formulas!D15 -> T1578.002 | K5: クラウド管理権限を悪用し、Update Serverと同一VPC内または他VPCに不正なクラウドインスタンス（C2やバックドア用）を作成し、横展開を試みる | L5: 3 | M5: 1 | N5: =IF(SPRV_Source_For_Formulas!G15<=0.2,3,IF(SPRV_Source_For_Formulas!G15<=0.5,2,1)) -> 2 | O5: =4-N5 -> 2 | P5: =IF(AND(L5=3,M5*O5>=6),"A",IF(AND(L5=3,M5*O5>=3),"B",IF(AND(L5=3,M5*O5>=1),"C",""))) -> C | Q5: 評価観点 評価内容 評価 認証管理 Step1でMFA導入・監視ログ・アラート通知設定済み ★★★（3） 権限管理（IAM） 管理者権限の最小化、RBAC運用、Update ServerのIAMロールも定期監査対象 ★★★（3） インスタンス作成の監視 CloudTrail相当のログ収集有効化とSIEM連携、異常インスタンス作成アラート設定 ★★★（3） ガードレール制御 テンプレート制限・事前承認フロー未導入（自動インスタンス作成が可能な設定あり） ★★☆（2） 構成ミスの検出自動化 CSPMは導入済、ただしSSPMは未導入 ★★☆（2） 監査と事後対応 月次の操作監査あり。外部監査は年1回 ★★☆（2） → 総合評価：2.5 → 切り上げて 3（レベル3） | R5: =SPRV_Source_For_Formulas!D16 -> T1651 | S5: クラウドAPI/CLIを利用してマイナンバー系業務システムに対し、スナップショット取得・設定変更・証拠隠滅などの攻撃的管理コマンドを実行 | T5: 3 | U5: 1 | V5: =IF(SPRV_Source_For_Formulas!G16<=0.2,3,IF(SPRV_Source_For_Formulas!G16<=0.5,2,1)) -> 3 | W5: =4-V5 -> 1 | X5: =IF(AND(T5=3,U5*W5>=6),"A",IF(AND(T5=3,U5*W5>=3),"B",IF(AND(T5=3,U5*W5>=1),"C",""))) -> C | Y5: | 評価項目 | 状況・施策内容 | 評価 | | ----------- | ------------------------------------------------------------ | ------ | | 認証管理（MFA） | CLI/APIアクセスにもMFA必須。IAMユーザではなくロールベースの一時トークンを使用 | ★★★（3） | | ログ監視・改ざん防止 | CloudTrail＋WORMストレージでログ改ざん防止。ただし外部SIEM連携は一部の操作のみ対象 | ★★☆（2） | | 操作の定型化 | TerraformによるInfrastructure as Codeはマイナンバー系でも導入済。ただし一部GUI設定残存 | ★★☆（2） | | RBACとワークフロー | 管理者権限の委譲に承認フローあり。CLI操作には内部発番のチケット必要 | ★★★（3） | | 検知・リアルタイム対応 | GuardDuty相当の異常API検知機能は未導入（導入予定あり） | ★☆☆（1） |→ 総合評価：2.2 → 切り下げて ★★（2） | Z5: =SPRV_Source_For_Formulas!D17 -> T1496.002 | AA5: 侵入済みのクラウド環境において、プロキシサーバの帯域を意図的に消費（例：大量データ送信、仮想マイニングノードの設置など）することで、ガバメントクラウドやVPN経路の通信品質を劣化させ、他の通信遅延・業務妨害を引き起こすDoS型の資源枯渇攻撃に該当。システム停止を伴わずに“リソース占有”による間接的な被害を狙う | AB5: 3 | AC5: 1 | AD5: =IF(SPRV_Source_For_Formulas!G17<=0.2,3,IF(SPRV_Source_For_Formulas!G17<=0.5,2,1)) -> 2 | AE5: =4-AD5 -> 2 | AF5: =IF(AND(AB5=3,AC5*AE5>=6),"A",IF(AND(AB5=3,AC5*AE5>=3),"B",IF(AND(AB5=3,AC5*AE5>=1),"C",""))) -> C | AG5: | 評価カテゴリ | 対策内容（遵守済と仮定） | 評価 | | ----------------- | -------------------------------------------------------- | ------ | | **プロキシ通信監視** | SWG・Proxyログは収集済、SIEM連携も実施。DNSや宛先IPでのトラフィック可視化が可能。 | ★★★（3） | | **異常帯域検出とアラート** | GuardDuty相当で異常通信のアラートはあるが、**帯域使用量ベースのしきい値監視は未設定** | ★★☆（2） | | **アウトバウンド制御** | Egress制御ポリシーあり（国別やFQDN制限）。ただし動的アノマリー検知は未導入。 | ★★☆（2） | | **構成ミス・ルーティング検知** | CSPMは導入済。SWGの過剰許可設定については検出対象。 | ★★★（3） | | **サービス間通信制限** | VPCピアリングやプロキシ経路の制限は設計上存在。ただし、**運用上の例外が散見される**（一部緩いルールあり） | ★★☆（2） |総合評価（レベル判定） 評価平均：約 2.4 → 切り上げ処理により レベル：★★★（3） | AP5: =MAX(D5,L5,T5,AB5) -> 3 | AQ5: 1 | AR5: =4-AS5 -> 1 | AS5: =MAX(F5,N5,V5,AD5) -> 3 | AT5: =IF(AND(AP5=3,AQ5*AR5>=6),"A",IF(AND(AP5=3,AQ5*AR5>=3),"B",IF(AND(AP5=3,AQ5*AR5>=1),"C",""))) -> C | AU5: ="Scenario-level Threat=1; Step1="&H5&" Step2="&P5&" Step3="&X5&" Step4="&AF5&" ; Overall Threat fixed=1, Max Mitigation="&AS5&" => Overall="&AT5 -> Scenario-level Threat=1; Step1=C Step2=C Step3=C Step4=C ; Overall Threat fixed=1, Max Mitigation=3 => Overall=C
A6: =SPRV_Source_For_Formulas!D18 -> T1189 | B6: 攻撃手法の具体化 運用管理者が、日常的に利用する 業務関連Webポータル／ガバメントクラウド管理サイト にアクセス。 攻撃者がWebサイトを改ざんし、マルウェアを仕込んでいる。 管理者が 閲覧またはファイルをダウンロードするだけで自動的にマルウェア感染。 結果として： 管理者端末を初期感染させ、GovCloud管理コンソールへの認証情報（セッションCookie、MFAトークン等）を窃取 その後の クラウドリソース操作権限の奪取 に直結。 | D6: 3 | E6: 1 | F6: =IF(SPRV_Source_For_Formulas!G18<=0.2,3,IF(SPRV_Source_For_Formulas!G18<=0.5,2,1)) -> 3 | G6: =4-F6 -> 1 | H6: =IF(AND(D6=3,E6*G6>=6),"A",IF(AND(D6=3,E6*G6>=3),"B",IF(AND(D6=3,E6*G6>=1),"C",""))) -> C | I6: | 評価観点 | 状況・施策内容 | 評価 | | ----------------- | -------------------------------------------------- | ------ | | エンドポイント防御（EDR/AV） | EDR導入済み、シグネチャ更新自動化。未知マルウェアにはふるまい検知依存。 | ★★★（3） | | Webフィルタリング／改ざん検知 | SWG導入済。不審サイト遮断可能。ただし正規業務ポータル改ざんのゼロデイ検知は困難。 | ★★☆（2） | | パッチ管理／ソフト更新 | ブラウザ・OSはMDMで強制更新。48時間以内に重大パッチ適用（β’モデル準拠）。 | ★★★（3） | | アクセス制御（ZTNA） | 管理端末以外からのアクセスは不可。職員ID＋MFA必須。ただし端末感染時のセッション乗っ取りは残る。 | ★★☆（2） | | ログ監視・SOC連携 | SOC監視下にあり、端末挙動ログをSIEMで分析。ただし初期感染段階での即時検知は限定的。 | ★★☆（2） |→ 総合評価：2.4 → 切り上げて レベル3 | J6: =SPRV_Source_For_Formulas!D19 -> T1578.002 | K6: クラウド管理権限を悪用し、Update Serverと同一VPC内または他VPCに不正なクラウドインスタンス（C2やバックドア用）を作成し、横展開を試みる | L6: 3 | M6: 1 | N6: =IF(SPRV_Source_For_Formulas!G19<=0.2,3,IF(SPRV_Source_For_Formulas!G19<=0.5,2,1)) -> 2 | O6: =4-N6 -> 2 | P6: =IF(AND(L6=3,M6*O6>=6),"A",IF(AND(L6=3,M6*O6>=3),"B",IF(AND(L6=3,M6*O6>=1),"C",""))) -> C | Q6: 評価観点 評価内容 評価 認証管理 Step1でMFA導入・監視ログ・アラート通知設定済み ★★★（3） 権限管理（IAM） 管理者権限の最小化、RBAC運用、Update ServerのIAMロールも定期監査対象 ★★★（3） インスタンス作成の監視 CloudTrail相当のログ収集有効化とSIEM連携、異常インスタンス作成アラート設定 ★★★（3） ガードレール制御 テンプレート制限・事前承認フロー未導入（自動インスタンス作成が可能な設定あり） ★★☆（2） 構成ミスの検出自動化 CSPMは導入済、ただしSSPMは未導入 ★★☆（2） 監査と事後対応 月次の操作監査あり。外部監査は年1回 ★★☆（2） → 総合評価：2.5 → 切り上げて 3（レベル3） | R6: =SPRV_Source_For_Formulas!D20 -> T1555.006 | S6: Secrets ManagerやKey VaultからDBパスワードやAPI鍵を抽出し、My Number系システムへの認証回避を試みる高度なクラウド認証情報窃取攻撃。 | T6: 3 | U6: 1 | V6: =IF(SPRV_Source_For_Formulas!G20<=0.2,3,IF(SPRV_Source_For_Formulas!G20<=0.5,2,1)) -> 3 | W6: =4-V6 -> 1 | X6: =IF(AND(T6=3,U6*W6>=6),"A",IF(AND(T6=3,U6*W6>=3),"B",IF(AND(T6=3,U6*W6>=1),"C",""))) -> C | Y6: | 評価項目 | 状況・施策内容 | 評価 | | ------------- | -------------------------------------------------- | ------ | | Secretsアクセス制御 | IAMにてSecretsごとにアクセス制御が設定されている。ただし一部ロールは広範囲に許可されている | ★★☆（2） | | Secretsの暗号化 | KMSによる暗号化は実施済み。KMSキーは別ロールで管理 | ★★★（3） | | アクセス監視・検知 | CloudTrail有効だが、**Secretsへの読み取りに対する即時アラート設定が不完全** | ★★☆（2） | | ローテーション運用 | 自動ローテーションは一部適用（APIキー等）。DBパスワードは手動更新ベース | ★★☆（2） | | SSPMなどの逸脱検知 | CSPM導入済、SSPMは評価中。ルールベース検知は整備途上 | ★★☆（2） |→ 総合評価：2.2 → 切り下げて ★★（2） | Z6: =SPRV_Source_For_Formulas!D21 -> T1486 | AA6: クラウドリソース（仮想マシン等）を乗っ取り、暗号資産マイニング/DDoS中継に悪用。 | AB6: 3 | AC6: 1 | AD6: =IF(SPRV_Source_For_Formulas!G21<=0.2,3,IF(SPRV_Source_For_Formulas!G21<=0.5,2,1)) -> 3 | AE6: =4-AD6 -> 1 | AF6: =IF(AND(AB6=3,AC6*AE6>=6),"A",IF(AND(AB6=3,AC6*AE6>=3),"B",IF(AND(AB6=3,AC6*AE6>=1),"C",""))) -> C | AG6: CSPMによるリソース使用率監視、アラート設定が有効（β’3.4.3相当）。 | AP6: =MAX(D6,L6,T6,AB6) -> 3 | AQ6: 1 | AR6: =4-AS6 -> 1 | AS6: =MAX(F6,N6,V6,AD6) -> 3 | AT6: =IF(AND(AP6=3,AQ6*AR6>=6),"A",IF(AND(AP6=3,AQ6*AR6>=3),"B",IF(AND(AP6=3,AQ6*AR6>=1),"C",""))) -> C | AU6: ="Scenario-level Threat=1; Step1="&H6&" Step2="&P6&" Step3="&X6&" Step4="&AF6&" ; Overall Threat fixed=1, Max Mitigation="&AS6&" => Overall="&AT6 -> Scenario-level Threat=1; Step1=C Step2=C Step3=C Step4=C ; Overall Threat fixed=1, Max Mitigation=3 => Overall=C
A7: =SPRV_Source_For_Formulas!D22 -> T1189 | B7: 攻撃手法の具体化 運用管理者が、日常的に利用する 業務関連Webポータル／ガバメントクラウド管理サイト にアクセス。 攻撃者がWebサイトを改ざんし、マルウェアを仕込んでいる。 管理者が 閲覧またはファイルをダウンロードするだけで自動的にマルウェア感染。 結果として： 管理者端末を初期感染させ、GovCloud管理コンソールへの認証情報（セッションCookie、MFAトークン等）を窃取 その後の クラウドリソース操作権限の奪取 に直結。 | D7: 3 | E7: 1 | F7: =IF(SPRV_Source_For_Formulas!G22<=0.2,3,IF(SPRV_Source_For_Formulas!G22<=0.5,2,1)) -> 3 | G7: =4-F7 -> 1 | H7: =IF(AND(D7=3,E7*G7>=6),"A",IF(AND(D7=3,E7*G7>=3),"B",IF(AND(D7=3,E7*G7>=1),"C",""))) -> C | I7: | 評価観点 | 状況・施策内容 | 評価 | | ----------------- | -------------------------------------------------- | ------ | | エンドポイント防御（EDR/AV） | EDR導入済み、シグネチャ更新自動化。未知マルウェアにはふるまい検知依存。 | ★★★（3） | | Webフィルタリング／改ざん検知 | SWG導入済。不審サイト遮断可能。ただし正規業務ポータル改ざんのゼロデイ検知は困難。 | ★★☆（2） | | パッチ管理／ソフト更新 | ブラウザ・OSはMDMで強制更新。48時間以内に重大パッチ適用（β’モデル準拠）。 | ★★★（3） | | アクセス制御（ZTNA） | 管理端末以外からのアクセスは不可。職員ID＋MFA必須。ただし端末感染時のセッション乗っ取りは残る。 | ★★☆（2） | | ログ監視・SOC連携 | SOC監視下にあり、端末挙動ログをSIEMで分析。ただし初期感染段階での即時検知は限定的。 | ★★☆（2） |→ 総合評価：2.4 → 切り上げて レベル3 | J7: =SPRV_Source_For_Formulas!D23 -> T1578.002 | K7: クラウド管理権限を悪用し、Update Serverと同一VPC内または他VPCに不正なクラウドインスタンス（C2やバックドア用）を作成し、横展開を試みる | L7: 3 | M7: 1 | N7: =IF(SPRV_Source_For_Formulas!G23<=0.2,3,IF(SPRV_Source_For_Formulas!G23<=0.5,2,1)) -> 2 | O7: =4-N7 -> 2 | P7: =IF(AND(L7=3,M7*O7>=6),"A",IF(AND(L7=3,M7*O7>=3),"B",IF(AND(L7=3,M7*O7>=1),"C",""))) -> C | Q7: 評価観点 評価内容 評価 認証管理 Step1でMFA導入・監視ログ・アラート通知設定済み ★★★（3） 権限管理（IAM） 管理者権限の最小化、RBAC運用、Update ServerのIAMロールも定期監査対象 ★★★（3） インスタンス作成の監視 CloudTrail相当のログ収集有効化とSIEM連携、異常インスタンス作成アラート設定 ★★★（3） ガードレール制御 テンプレート制限・事前承認フロー未導入（自動インスタンス作成が可能な設定あり） ★★☆（2） 構成ミスの検出自動化 CSPMは導入済、ただしSSPMは未導入 ★★☆（2） 監査と事後対応 月次の操作監査あり。外部監査は年1回 ★★☆（2） → 総合評価：2.5 → 切り上げて 3（レベル3） | R7: =SPRV_Source_For_Formulas!D24 -> T1555.006 | S7: Secrets ManagerやKey VaultからDBパスワードやAPI鍵を抽出し、My Number系システムへの認証回避を試みる高度なクラウド認証情報窃取攻撃。 | T7: 3 | U7: 1 | V7: =IF(SPRV_Source_For_Formulas!G24<=0.2,3,IF(SPRV_Source_For_Formulas!G24<=0.5,2,1)) -> 3 | W7: =4-V7 -> 1 | X7: =IF(AND(T7=3,U7*W7>=6),"A",IF(AND(T7=3,U7*W7>=3),"B",IF(AND(T7=3,U7*W7>=1),"C",""))) -> C | Y7: | 評価項目 | 状況・施策内容 | 評価 | | ------------- | -------------------------------------------------- | ------ | | Secretsアクセス制御 | IAMにてSecretsごとにアクセス制御が設定されている。ただし一部ロールは広範囲に許可されている | ★★☆（2） | | Secretsの暗号化 | KMSによる暗号化は実施済み。KMSキーは別ロールで管理 | ★★★（3） | | アクセス監視・検知 | CloudTrail有効だが、**Secretsへの読み取りに対する即時アラート設定が不完全** | ★★☆（2） | | ローテーション運用 | 自動ローテーションは一部適用（APIキー等）。DBパスワードは手動更新ベース | ★★☆（2） | | SSPMなどの逸脱検知 | CSPM導入済、SSPMは評価中。ルールベース検知は整備途上 | ★★☆（2） |→ 総合評価：2.2 → 切り下げて ★★（2） | Z7: =SPRV_Source_For_Formulas!D25 -> T1496.001 | AA7: 計算リソースを秘匿的に不正利用（Compute Hijacking）。 | AB7: 3 | AC7: 1 | AD7: =IF(SPRV_Source_For_Formulas!G25<=0.2,3,IF(SPRV_Source_For_Formulas!G25<=0.5,2,1)) -> 2 | AE7: =4-AD7 -> 2 | AF7: =IF(AND(AB7=3,AC7*AE7>=6),"A",IF(AND(AB7=3,AC7*AE7>=3),"B",IF(AND(AB7=3,AC7*AE7>=1),"C",""))) -> C | AG7: モニタリング＋しきい値制限（Azure Monitor等）で抑止可能。 | AP7: =MAX(D7,L7,T7,AB7) -> 3 | AQ7: 1 | AR7: =4-AS7 -> 1 | AS7: =MAX(F7,N7,V7,AD7) -> 3 | AT7: =IF(AND(AP7=3,AQ7*AR7>=6),"A",IF(AND(AP7=3,AQ7*AR7>=3),"B",IF(AND(AP7=3,AQ7*AR7>=1),"C",""))) -> C | AU7: ="Scenario-level Threat=1; Step1="&H7&" Step2="&P7&" Step3="&X7&" Step4="&AF7&" ; Overall Threat fixed=1, Max Mitigation="&AS7&" => Overall="&AT7 -> Scenario-level Threat=1; Step1=C Step2=C Step3=C Step4=C ; Overall Threat fixed=1, Max Mitigation=3 => Overall=C
A8: =SPRV_Source_For_Formulas!D26 -> T1189 | B8: 攻撃手法の具体化 運用管理者が、日常的に利用する 業務関連Webポータル／ガバメントクラウド管理サイト にアクセス。 攻撃者がWebサイトを改ざんし、マルウェアを仕込んでいる。 管理者が 閲覧またはファイルをダウンロードするだけで自動的にマルウェア感染。 結果として： 管理者端末を初期感染させ、GovCloud管理コンソールへの認証情報（セッションCookie、MFAトークン等）を窃取 その後の クラウドリソース操作権限の奪取 に直結。 | D8: 3 | E8: 1 | F8: =IF(SPRV_Source_For_Formulas!G26<=0.2,3,IF(SPRV_Source_For_Formulas!G26<=0.5,2,1)) -> 3 | G8: =4-F8 -> 1 | H8: =IF(AND(D8=3,E8*G8>=6),"A",IF(AND(D8=3,E8*G8>=3),"B",IF(AND(D8=3,E8*G8>=1),"C",""))) -> C | I8: | 評価観点 | 状況・施策内容 | 評価 | | ----------------- | -------------------------------------------------- | ------ | | エンドポイント防御（EDR/AV） | EDR導入済み、シグネチャ更新自動化。未知マルウェアにはふるまい検知依存。 | ★★★（3） | | Webフィルタリング／改ざん検知 | SWG導入済。不審サイト遮断可能。ただし正規業務ポータル改ざんのゼロデイ検知は困難。 | ★★☆（2） | | パッチ管理／ソフト更新 | ブラウザ・OSはMDMで強制更新。48時間以内に重大パッチ適用（β’モデル準拠）。 | ★★★（3） | | アクセス制御（ZTNA） | 管理端末以外からのアクセスは不可。職員ID＋MFA必須。ただし端末感染時のセッション乗っ取りは残る。 | ★★☆（2） | | ログ監視・SOC連携 | SOC監視下にあり、端末挙動ログをSIEMで分析。ただし初期感染段階での即時検知は限定的。 | ★★☆（2） |→ 総合評価：2.4 → 切り上げて レベル3 | J8: =SPRV_Source_For_Formulas!D27 -> T1578.002 | K8: クラウド管理権限を悪用し、Update Serverと同一VPC内または他VPCに不正なクラウドインスタンス（C2やバックドア用）を作成し、横展開を試みる | L8: 3 | M8: 1 | N8: =IF(SPRV_Source_For_Formulas!G27<=0.2,3,IF(SPRV_Source_For_Formulas!G27<=0.5,2,1)) -> 2 | O8: =4-N8 -> 2 | P8: =IF(AND(L8=3,M8*O8>=6),"A",IF(AND(L8=3,M8*O8>=3),"B",IF(AND(L8=3,M8*O8>=1),"C",""))) -> C | Q8: 評価観点 評価内容 評価 認証管理 Step1でMFA導入・監視ログ・アラート通知設定済み ★★★（3） 権限管理（IAM） 管理者権限の最小化、RBAC運用、Update ServerのIAMロールも定期監査対象 ★★★（3） インスタンス作成の監視 CloudTrail相当のログ収集有効化とSIEM連携、異常インスタンス作成アラート設定 ★★★（3） ガードレール制御 テンプレート制限・事前承認フロー未導入（自動インスタンス作成が可能な設定あり） ★★☆（2） 構成ミスの検出自動化 CSPMは導入済、ただしSSPMは未導入 ★★☆（2） 監査と事後対応 月次の操作監査あり。外部監査は年1回 ★★☆（2） → 総合評価：2.5 → 切り上げて 3（レベル3） | R8: =SPRV_Source_For_Formulas!D28 -> T1555.006 | S8: Secrets ManagerやKey VaultからDBパスワードやAPI鍵を抽出し、My Number系システムへの認証回避を試みる高度なクラウド認証情報窃取攻撃。 | T8: 3 | U8: 1 | V8: =IF(SPRV_Source_For_Formulas!G28<=0.2,3,IF(SPRV_Source_For_Formulas!G28<=0.5,2,1)) -> 3 | W8: =4-V8 -> 1 | X8: =IF(AND(T8=3,U8*W8>=6),"A",IF(AND(T8=3,U8*W8>=3),"B",IF(AND(T8=3,U8*W8>=1),"C",""))) -> C | Y8: | 評価項目 | 状況・施策内容 | 評価 | | ------------- | -------------------------------------------------- | ------ | | Secretsアクセス制御 | IAMにてSecretsごとにアクセス制御が設定されている。ただし一部ロールは広範囲に許可されている | ★★☆（2） | | Secretsの暗号化 | KMSによる暗号化は実施済み。KMSキーは別ロールで管理 | ★★★（3） | | アクセス監視・検知 | CloudTrail有効だが、**Secretsへの読み取りに対する即時アラート設定が不完全** | ★★☆（2） | | ローテーション運用 | 自動ローテーションは一部適用（APIキー等）。DBパスワードは手動更新ベース | ★★☆（2） | | SSPMなどの逸脱検知 | CSPM導入済、SSPMは評価中。ルールベース検知は整備途上 | ★★☆（2） |→ 総合評価：2.2 → 切り下げて ★★（2） | Z8: =SPRV_Source_For_Formulas!D29 -> T1496.004 | AA8: クラウドAPI経由で Proxy Server on GovCloud に対して以下を実施： EC2/EBSなどのストレージを暗号化（KMSキーを使って再暗号化またはKMSキーを削除） OSレベルでスクリプトを投入し、ボリュームをBitLockerやLinuxのLUKS等で暗号化 システムログやスナップショットの削除による復旧妨害 IAMの一時的制御権を用いた“復旧阻止”工作 ガバメントクラウド内で復旧オプションが封じられた状態にされることで、実質的なデータロックアウトが生じる。 | AB8: 3 | AC8: 1 | AD8: =IF(SPRV_Source_For_Formulas!G29<=0.2,3,IF(SPRV_Source_For_Formulas!G29<=0.5,2,1)) -> 2 | AE8: =4-AD8 -> 2 | AF8: =IF(AND(AB8=3,AC8*AE8>=6),"A",IF(AND(AB8=3,AC8*AE8>=3),"B",IF(AND(AB8=3,AC8*AE8>=1),"C",""))) -> C | AG8: | 評価観点 | 評価内容 | 評価 | | ------------- | ---------------------------------------------------- | ------ | | データ暗号化制御 | KMSのアクセス制御やEBS暗号化ポリシーは一部導入。ただしProxy Server単体の制御は未記載。 | ★★☆（2） | | ログ・スナップショット保全 | CloudTrailログ保全は一部設定あり。スナップショット削除阻止や整合性保全策は記載なし。 | ★★☆（2） | | API実行制御 | Step3でAPI攻撃が成立済のため、IAM/API制御に抜けあり。SSPM未導入。 | ★☆☆（1） |→ 総合評価：1.7 → 切り捨てて「レベル1」 | AP8: =MAX(D8,L8,T8,AB8) -> 3 | AQ8: 1 | AR8: =4-AS8 -> 1 | AS8: =MAX(F8,N8,V8,AD8) -> 3 | AT8: =IF(AND(AP8=3,AQ8*AR8>=6),"A",IF(AND(AP8=3,AQ8*AR8>=3),"B",IF(AND(AP8=3,AQ8*AR8>=1),"C",""))) -> C | AU8: ="Scenario-level Threat=1; Step1="&H8&" Step2="&P8&" Step3="&X8&" Step4="&AF8&" ; Overall Threat fixed=1, Max Mitigation="&AS8&" => Overall="&AT8 -> Scenario-level Threat=1; Step1=C Step2=C Step3=C Step4=C ; Overall Threat fixed=1, Max Mitigation=3 => Overall=C
A9: =SPRV_Source_For_Formulas!D30 -> T1189 | B9: 攻撃手法の具体化 運用管理者が、日常的に利用する 業務関連Webポータル／ガバメントクラウド管理サイト にアクセス。 攻撃者がWebサイトを改ざんし、マルウェアを仕込んでいる。 管理者が 閲覧またはファイルをダウンロードするだけで自動的にマルウェア感染。 結果として： 管理者端末を初期感染させ、GovCloud管理コンソールへの認証情報（セッションCookie、MFAトークン等）を窃取 その後の クラウドリソース操作権限の奪取 に直結。 | D9: 3 | E9: 1 | F9: =IF(SPRV_Source_For_Formulas!G30<=0.2,3,IF(SPRV_Source_For_Formulas!G30<=0.5,2,1)) -> 3 | G9: =4-F9 -> 1 | H9: =IF(AND(D9=3,E9*G9>=6),"A",IF(AND(D9=3,E9*G9>=3),"B",IF(AND(D9=3,E9*G9>=1),"C",""))) -> C | I9: | 評価観点 | 状況・施策内容 | 評価 | | ----------------- | -------------------------------------------------- | ------ | | エンドポイント防御（EDR/AV） | EDR導入済み、シグネチャ更新自動化。未知マルウェアにはふるまい検知依存。 | ★★★（3） | | Webフィルタリング／改ざん検知 | SWG導入済。不審サイト遮断可能。ただし正規業務ポータル改ざんのゼロデイ検知は困難。 | ★★☆（2） | | パッチ管理／ソフト更新 | ブラウザ・OSはMDMで強制更新。48時間以内に重大パッチ適用（β’モデル準拠）。 | ★★★（3） | | アクセス制御（ZTNA） | 管理端末以外からのアクセスは不可。職員ID＋MFA必須。ただし端末感染時のセッション乗っ取りは残る。 | ★★☆（2） | | ログ監視・SOC連携 | SOC監視下にあり、端末挙動ログをSIEMで分析。ただし初期感染段階での即時検知は限定的。 | ★★☆（2） |→ 総合評価：2.4 → 切り上げて レベル3 | J9: =SPRV_Source_For_Formulas!D31 -> T1578.002 | K9: クラウド管理権限を悪用し、Update Serverと同一VPC内または他VPCに不正なクラウドインスタンス（C2やバックドア用）を作成し、横展開を試みる | L9: 3 | M9: 1 | N9: =IF(SPRV_Source_For_Formulas!G31<=0.2,3,IF(SPRV_Source_For_Formulas!G31<=0.5,2,1)) -> 2 | O9: =4-N9 -> 2 | P9: =IF(AND(L9=3,M9*O9>=6),"A",IF(AND(L9=3,M9*O9>=3),"B",IF(AND(L9=3,M9*O9>=1),"C",""))) -> C | Q9: 評価観点 評価内容 評価 認証管理 Step1でMFA導入・監視ログ・アラート通知設定済み ★★★（3） 権限管理（IAM） 管理者権限の最小化、RBAC運用、Update ServerのIAMロールも定期監査対象 ★★★（3） インスタンス作成の監視 CloudTrail相当のログ収集有効化とSIEM連携、異常インスタンス作成アラート設定 ★★★（3） ガードレール制御 テンプレート制限・事前承認フロー未導入（自動インスタンス作成が可能な設定あり） ★★☆（2） 構成ミスの検出自動化 CSPMは導入済、ただしSSPMは未導入 ★★☆（2） 監査と事後対応 月次の操作監査あり。外部監査は年1回 ★★☆（2） → 総合評価：2.5 → 切り上げて 3（レベル3） | R9: =SPRV_Source_For_Formulas!D32 -> T1555.006 | S9: Secrets ManagerやKey VaultからDBパスワードやAPI鍵を抽出し、My Number系システムへの認証回避を試みる高度なクラウド認証情報窃取攻撃。 | T9: 3 | U9: 1 | V9: =IF(SPRV_Source_For_Formulas!G32<=0.2,3,IF(SPRV_Source_For_Formulas!G32<=0.5,2,1)) -> 3 | W9: =4-V9 -> 1 | X9: =IF(AND(T9=3,U9*W9>=6),"A",IF(AND(T9=3,U9*W9>=3),"B",IF(AND(T9=3,U9*W9>=1),"C",""))) -> C | Y9: | 評価項目 | 状況・施策内容 | 評価 | | ------------- | -------------------------------------------------- | ------ | | Secretsアクセス制御 | IAMにてSecretsごとにアクセス制御が設定されている。ただし一部ロールは広範囲に許可されている | ★★☆（2） | | Secretsの暗号化 | KMSによる暗号化は実施済み。KMSキーは別ロールで管理 | ★★★（3） | | アクセス監視・検知 | CloudTrail有効だが、**Secretsへの読み取りに対する即時アラート設定が不完全** | ★★☆（2） | | ローテーション運用 | 自動ローテーションは一部適用（APIキー等）。DBパスワードは手動更新ベース | ★★☆（2） | | SSPMなどの逸脱検知 | CSPM導入済、SSPMは評価中。ルールベース検知は整備途上 | ★★☆（2） |→ 総合評価：2.2 → 切り下げて ★★（2） | Z9: =SPRV_Source_For_Formulas!D33 -> T1496.002 | AA9: 侵入済みのクラウド環境において、プロキシサーバの帯域を意図的に消費（例：大量データ送信、仮想マイニングノードの設置など）することで、ガバメントクラウドやVPN経路の通信品質を劣化させ、他の通信遅延・業務妨害を引き起こすDoS型の資源枯渇攻撃に該当。システム停止を伴わずに“リソース占有”による間接的な被害を狙う | AB9: 3 | AC9: 1 | AD9: =IF(SPRV_Source_For_Formulas!G33<=0.2,3,IF(SPRV_Source_For_Formulas!G33<=0.5,2,1)) -> 2 | AE9: =4-AD9 -> 2 | AF9: =IF(AND(AB9=3,AC9*AE9>=6),"A",IF(AND(AB9=3,AC9*AE9>=3),"B",IF(AND(AB9=3,AC9*AE9>=1),"C",""))) -> C | AG9: | 評価カテゴリ | 対策内容（遵守済と仮定） | 評価 | | ----------------- | -------------------------------------------------------- | ------ | | **プロキシ通信監視** | SWG・Proxyログは収集済、SIEM連携も実施。DNSや宛先IPでのトラフィック可視化が可能。 | ★★★（3） | | **異常帯域検出とアラート** | GuardDuty相当で異常通信のアラートはあるが、**帯域使用量ベースのしきい値監視は未設定** | ★★☆（2） | | **アウトバウンド制御** | Egress制御ポリシーあり（国別やFQDN制限）。ただし動的アノマリー検知は未導入。 | ★★☆（2） | | **構成ミス・ルーティング検知** | CSPMは導入済。SWGの過剰許可設定については検出対象。 | ★★★（3） | | **サービス間通信制限** | VPCピアリングやプロキシ経路の制限は設計上存在。ただし、**運用上の例外が散見される**（一部緩いルールあり） | ★★☆（2） |総合評価（レベル判定） 評価平均：約 2.4 → 切り上げ処理により レベル：★★★（3） | AP9: =MAX(D9,L9,T9,AB9) -> 3 | AQ9: 1 | AR9: =4-AS9 -> 1 | AS9: =MAX(F9,N9,V9,AD9) -> 3 | AT9: =IF(AND(AP9=3,AQ9*AR9>=6),"A",IF(AND(AP9=3,AQ9*AR9>=3),"B",IF(AND(AP9=3,AQ9*AR9>=1),"C",""))) -> C | AU9: ="Scenario-level Threat=1; Step1="&H9&" Step2="&P9&" Step3="&X9&" Step4="&AF9&" ; Overall Threat fixed=1, Max Mitigation="&AS9&" => Overall="&AT9 -> Scenario-level Threat=1; Step1=C Step2=C Step3=C Step4=C ; Overall Threat fixed=1, Max Mitigation=3 => Overall=C
A10: =SPRV_Source_For_Formulas!D34 -> T1189 | B10: 攻撃手法の具体化 運用管理者が、日常的に利用する 業務関連Webポータル／ガバメントクラウド管理サイト にアクセス。 攻撃者がWebサイトを改ざんし、マルウェアを仕込んでいる。 管理者が 閲覧またはファイルをダウンロードするだけで自動的にマルウェア感染。 結果として： 管理者端末を初期感染させ、GovCloud管理コンソールへの認証情報（セッションCookie、MFAトークン等）を窃取 その後の クラウドリソース操作権限の奪取 に直結。 | D10: 3 | E10: 1 | F10: =IF(SPRV_Source_For_Formulas!G34<=0.2,3,IF(SPRV_Source_For_Formulas!G34<=0.5,2,1)) -> 3 | G10: =4-F10 -> 1 | H10: =IF(AND(D10=3,E10*G10>=6),"A",IF(AND(D10=3,E10*G10>=3),"B",IF(AND(D10=3,E10*G10>=1),"C",""))) -> C | I10: | 評価観点 | 状況・施策内容 | 評価 | | ----------------- | -------------------------------------------------- | ------ | | エンドポイント防御（EDR/AV） | EDR導入済み、シグネチャ更新自動化。未知マルウェアにはふるまい検知依存。 | ★★★（3） | | Webフィルタリング／改ざん検知 | SWG導入済。不審サイト遮断可能。ただし正規業務ポータル改ざんのゼロデイ検知は困難。 | ★★☆（2） | | パッチ管理／ソフト更新 | ブラウザ・OSはMDMで強制更新。48時間以内に重大パッチ適用（β’モデル準拠）。 | ★★★（3） | | アクセス制御（ZTNA） | 管理端末以外からのアクセスは不可。職員ID＋MFA必須。ただし端末感染時のセッション乗っ取りは残る。 | ★★☆（2） | | ログ監視・SOC連携 | SOC監視下にあり、端末挙動ログをSIEMで分析。ただし初期感染段階での即時検知は限定的。 | ★★☆（2） |→ 総合評価：2.4 → 切り上げて レベル3 | J10: =SPRV_Source_For_Formulas!D35 -> T1578.002 | K10: クラウド管理権限を悪用し、Update Serverと同一VPC内または他VPCに不正なクラウドインスタンス（C2やバックドア用）を作成し、横展開を試みる | L10: 3 | M10: 1 | N10: =IF(SPRV_Source_For_Formulas!G35<=0.2,3,IF(SPRV_Source_For_Formulas!G35<=0.5,2,1)) -> 2 | O10: =4-N10 -> 2 | P10: =IF(AND(L10=3,M10*O10>=6),"A",IF(AND(L10=3,M10*O10>=3),"B",IF(AND(L10=3,M10*O10>=1),"C",""))) -> C | Q10: 評価観点 評価内容 評価 認証管理 Step1でMFA導入・監視ログ・アラート通知設定済み ★★★（3） 権限管理（IAM） 管理者権限の最小化、RBAC運用、Update ServerのIAMロールも定期監査対象 ★★★（3） インスタンス作成の監視 CloudTrail相当のログ収集有効化とSIEM連携、異常インスタンス作成アラート設定 ★★★（3） ガードレール制御 テンプレート制限・事前承認フロー未導入（自動インスタンス作成が可能な設定あり） ★★☆（2） 構成ミスの検出自動化 CSPMは導入済、ただしSSPMは未導入 ★★☆（2） 監査と事後対応 月次の操作監査あり。外部監査は年1回 ★★☆（2） → 総合評価：2.5 → 切り上げて 3（レベル3） | R10: =SPRV_Source_For_Formulas!D36 -> T1059.009 | S10: クラウドAPIを使ってスクリプトを遠隔実行し設定変更やマルウェア展開。 | T10: 3 | U10: 1 | V10: =IF(SPRV_Source_For_Formulas!G36<=0.2,3,IF(SPRV_Source_For_Formulas!G36<=0.5,2,1)) -> 3 | W10: =4-V10 -> 1 | X10: =IF(AND(T10=3,U10*W10>=6),"A",IF(AND(T10=3,U10*W10>=3),"B",IF(AND(T10=3,U10*W10>=1),"C",""))) -> C | Y10: | 観点 | 内容 | | ------------ | ----------------------------------------------------------------------- | | ? IAM制御 | IAM最小権限ポリシー、ロールベースアクセス制御（RBAC）の適用が前提となっており、基本的な対策は講じられていると考えられる | | ? API監視 | CloudTrail（AWS）やAudit Log（GCP）等による**API呼び出しログの記録と分析**も想定されている | | ? 不安要素 | クラウドAPIは「正規操作」として処理されやすいため、不正利用が**異常検知で気付きにくい**<br>⇒ 監視設定が甘いと侵害が長期化しやすい | | ? 利用頻度 | 管理者も通常業務でAPIを使うため、攻撃と区別が困難（例：異常な時間帯やIPでの利用を監視できるかどうかが鍵） | | ? 自治体側の技術成熟度 | クラウドセキュリティに不慣れな自治体ではAPI監査設定が**未設定または過剰権限のまま**であるケースが懸念される |リスクをさらに下げる効果的な対策は、| 項目 | 推奨構成（ベンダ中立） | | ----- | --------------------------------------------- | | ログ取得 | CloudTrail / Audit Logs + 長期保管 | | 検知・分析 | GuardDuty / SCC / Defender for Cloud + SIEM連携 | | 統制 | IAM最小権限 + 条件付きアクセス + 定期レビューワークフロー | | ツール連携 | EDRやPAM、SIEMとCNAppと連携して**誤用や内部不正**にも対応 | | Z10: =SPRV_Source_For_Formulas!D37 -> T1486 | AA10: クラウドリソース（仮想マシン等）を乗っ取り、暗号資産マイニング/DDoS中継に悪用。 | AB10: 3 | AC10: 1 | AD10: =IF(SPRV_Source_For_Formulas!G37<=0.2,3,IF(SPRV_Source_For_Formulas!G37<=0.5,2,1)) -> 3 | AE10: =4-AD10 -> 1 | AF10: =IF(AND(AB10=3,AC10*AE10>=6),"A",IF(AND(AB10=3,AC10*AE10>=3),"B",IF(AND(AB10=3,AC10*AE10>=1),"C",""))) -> C | AG10: CSPMによるリソース使用率監視、アラート設定が有効（β’3.4.3相当）。 | AP10: =MAX(D10,L10,T10,AB10) -> 3 | AQ10: 1 | AR10: =4-AS10 -> 1 | AS10: =MAX(F10,N10,V10,AD10) -> 3 | AT10: =IF(AND(AP10=3,AQ10*AR10>=6),"A",IF(AND(AP10=3,AQ10*AR10>=3),"B",IF(AND(AP10=3,AQ10*AR10>=1),"C",""))) -> C | AU10: ="Scenario-level Threat=1; Step1="&H10&" Step2="&P10&" Step3="&X10&" Step4="&AF10&" ; Overall Threat fixed=1, Max Mitigation="&AS10&" => Overall="&AT10 -> Scenario-level Threat=1; Step1=C Step2=C Step3=C Step4=C ; Overall Threat fixed=1, Max Mitigation=3 => Overall=C
A11: =SPRV_Source_For_Formulas!D38 -> T1189 | B11: 攻撃手法の具体化 運用管理者が、日常的に利用する 業務関連Webポータル／ガバメントクラウド管理サイト にアクセス。 攻撃者がWebサイトを改ざんし、マルウェアを仕込んでいる。 管理者が 閲覧またはファイルをダウンロードするだけで自動的にマルウェア感染。 結果として： 管理者端末を初期感染させ、GovCloud管理コンソールへの認証情報（セッションCookie、MFAトークン等）を窃取 その後の クラウドリソース操作権限の奪取 に直結。 | D11: 3 | E11: 1 | F11: =IF(SPRV_Source_For_Formulas!G38<=0.2,3,IF(SPRV_Source_For_Formulas!G38<=0.5,2,1)) -> 3 | G11: =4-F11 -> 1 | H11: =IF(AND(D11=3,E11*G11>=6),"A",IF(AND(D11=3,E11*G11>=3),"B",IF(AND(D11=3,E11*G11>=1),"C",""))) -> C | I11: | 評価観点 | 状況・施策内容 | 評価 | | ----------------- | -------------------------------------------------- | ------ | | エンドポイント防御（EDR/AV） | EDR導入済み、シグネチャ更新自動化。未知マルウェアにはふるまい検知依存。 | ★★★（3） | | Webフィルタリング／改ざん検知 | SWG導入済。不審サイト遮断可能。ただし正規業務ポータル改ざんのゼロデイ検知は困難。 | ★★☆（2） | | パッチ管理／ソフト更新 | ブラウザ・OSはMDMで強制更新。48時間以内に重大パッチ適用（β’モデル準拠）。 | ★★★（3） | | アクセス制御（ZTNA） | 管理端末以外からのアクセスは不可。職員ID＋MFA必須。ただし端末感染時のセッション乗っ取りは残る。 | ★★☆（2） | | ログ監視・SOC連携 | SOC監視下にあり、端末挙動ログをSIEMで分析。ただし初期感染段階での即時検知は限定的。 | ★★☆（2） |→ 総合評価：2.4 → 切り上げて レベル3 | J11: =SPRV_Source_For_Formulas!D39 -> T1578.002 | K11: クラウド管理権限を悪用し、Update Serverと同一VPC内または他VPCに不正なクラウドインスタンス（C2やバックドア用）を作成し、横展開を試みる | L11: 3 | M11: 1 | N11: =IF(SPRV_Source_For_Formulas!G39<=0.2,3,IF(SPRV_Source_For_Formulas!G39<=0.5,2,1)) -> 2 | O11: =4-N11 -> 2 | P11: =IF(AND(L11=3,M11*O11>=6),"A",IF(AND(L11=3,M11*O11>=3),"B",IF(AND(L11=3,M11*O11>=1),"C",""))) -> C | Q11: 評価観点 評価内容 評価 認証管理 Step1でMFA導入・監視ログ・アラート通知設定済み ★★★（3） 権限管理（IAM） 管理者権限の最小化、RBAC運用、Update ServerのIAMロールも定期監査対象 ★★★（3） インスタンス作成の監視 CloudTrail相当のログ収集有効化とSIEM連携、異常インスタンス作成アラート設定 ★★★（3） ガードレール制御 テンプレート制限・事前承認フロー未導入（自動インスタンス作成が可能な設定あり） ★★☆（2） 構成ミスの検出自動化 CSPMは導入済、ただしSSPMは未導入 ★★☆（2） 監査と事後対応 月次の操作監査あり。外部監査は年1回 ★★☆（2） → 総合評価：2.5 → 切り上げて 3（レベル3） | R11: =SPRV_Source_For_Formulas!D40 -> T1059.009 | S11: クラウドAPIを使ってスクリプトを遠隔実行し設定変更やマルウェア展開。 | T11: 3 | U11: 1 | V11: =IF(SPRV_Source_For_Formulas!G40<=0.2,3,IF(SPRV_Source_For_Formulas!G40<=0.5,2,1)) -> 3 | W11: =4-V11 -> 1 | X11: =IF(AND(T11=3,U11*W11>=6),"A",IF(AND(T11=3,U11*W11>=3),"B",IF(AND(T11=3,U11*W11>=1),"C",""))) -> C | Y11: | 観点 | 内容 | | ------------ | ----------------------------------------------------------------------- | | ? IAM制御 | IAM最小権限ポリシー、ロールベースアクセス制御（RBAC）の適用が前提となっており、基本的な対策は講じられていると考えられる | | ? API監視 | CloudTrail（AWS）やAudit Log（GCP）等による**API呼び出しログの記録と分析**も想定されている | | ? 不安要素 | クラウドAPIは「正規操作」として処理されやすいため、不正利用が**異常検知で気付きにくい**<br>⇒ 監視設定が甘いと侵害が長期化しやすい | | ? 利用頻度 | 管理者も通常業務でAPIを使うため、攻撃と区別が困難（例：異常な時間帯やIPでの利用を監視できるかどうかが鍵） | | ? 自治体側の技術成熟度 | クラウドセキュリティに不慣れな自治体ではAPI監査設定が**未設定または過剰権限のまま**であるケースが懸念される |リスクをさらに下げる効果的な対策は、| 項目 | 推奨構成（ベンダ中立） | | ----- | --------------------------------------------- | | ログ取得 | CloudTrail / Audit Logs + 長期保管 | | 検知・分析 | GuardDuty / SCC / Defender for Cloud + SIEM連携 | | 統制 | IAM最小権限 + 条件付きアクセス + 定期レビューワークフロー | | ツール連携 | EDRやPAM、SIEMとCNAppと連携して**誤用や内部不正**にも対応 | | Z11: =SPRV_Source_For_Formulas!D41 -> T1496.001 | AA11: 計算リソースを秘匿的に不正利用（Compute Hijacking）。 | AB11: 3 | AC11: 1 | AD11: =IF(SPRV_Source_For_Formulas!G41<=0.2,3,IF(SPRV_Source_For_Formulas!G41<=0.5,2,1)) -> 2 | AE11: =4-AD11 -> 2 | AF11: =IF(AND(AB11=3,AC11*AE11>=6),"A",IF(AND(AB11=3,AC11*AE11>=3),"B",IF(AND(AB11=3,AC11*AE11>=1),"C",""))) -> C | AG11: モニタリング＋しきい値制限（Azure Monitor等）で抑止可能。 | AP11: =MAX(D11,L11,T11,AB11) -> 3 | AQ11: 1 | AR11: =4-AS11 -> 1 | AS11: =MAX(F11,N11,V11,AD11) -> 3 | AT11: =IF(AND(AP11=3,AQ11*AR11>=6),"A",IF(AND(AP11=3,AQ11*AR11>=3),"B",IF(AND(AP11=3,AQ11*AR11>=1),"C",""))) -> C | AU11: ="Scenario-level Threat=1; Step1="&H11&" Step2="&P11&" Step3="&X11&" Step4="&AF11&" ; Overall Threat fixed=1, Max Mitigation="&AS11&" => Overall="&AT11 -> Scenario-level Threat=1; Step1=C Step2=C Step3=C Step4=C ; Overall Threat fixed=1, Max Mitigation=3 => Overall=C
A12: =SPRV_Source_For_Formulas!D42 -> T1189 | B12: 攻撃手法の具体化 運用管理者が、日常的に利用する 業務関連Webポータル／ガバメントクラウド管理サイト にアクセス。 攻撃者がWebサイトを改ざんし、マルウェアを仕込んでいる。 管理者が 閲覧またはファイルをダウンロードするだけで自動的にマルウェア感染。 結果として： 管理者端末を初期感染させ、GovCloud管理コンソールへの認証情報（セッションCookie、MFAトークン等）を窃取 その後の クラウドリソース操作権限の奪取 に直結。 | D12: 3 | E12: 1 | F12: =IF(SPRV_Source_For_Formulas!G42<=0.2,3,IF(SPRV_Source_For_Formulas!G42<=0.5,2,1)) -> 3 | G12: =4-F12 -> 1 | H12: =IF(AND(D12=3,E12*G12>=6),"A",IF(AND(D12=3,E12*G12>=3),"B",IF(AND(D12=3,E12*G12>=1),"C",""))) -> C | I12: | 評価観点 | 状況・施策内容 | 評価 | | ----------------- | -------------------------------------------------- | ------ | | エンドポイント防御（EDR/AV） | EDR導入済み、シグネチャ更新自動化。未知マルウェアにはふるまい検知依存。 | ★★★（3） | | Webフィルタリング／改ざん検知 | SWG導入済。不審サイト遮断可能。ただし正規業務ポータル改ざんのゼロデイ検知は困難。 | ★★☆（2） | | パッチ管理／ソフト更新 | ブラウザ・OSはMDMで強制更新。48時間以内に重大パッチ適用（β’モデル準拠）。 | ★★★（3） | | アクセス制御（ZTNA） | 管理端末以外からのアクセスは不可。職員ID＋MFA必須。ただし端末感染時のセッション乗っ取りは残る。 | ★★☆（2） | | ログ監視・SOC連携 | SOC監視下にあり、端末挙動ログをSIEMで分析。ただし初期感染段階での即時検知は限定的。 | ★★☆（2） |→ 総合評価：2.4 → 切り上げて レベル3 | J12: =SPRV_Source_For_Formulas!D43 -> T1578.002 | K12: クラウド管理権限を悪用し、Update Serverと同一VPC内または他VPCに不正なクラウドインスタンス（C2やバックドア用）を作成し、横展開を試みる | L12: 3 | M12: 1 | N12: =IF(SPRV_Source_For_Formulas!G43<=0.2,3,IF(SPRV_Source_For_Formulas!G43<=0.5,2,1)) -> 2 | O12: =4-N12 -> 2 | P12: =IF(AND(L12=3,M12*O12>=6),"A",IF(AND(L12=3,M12*O12>=3),"B",IF(AND(L12=3,M12*O12>=1),"C",""))) -> C | Q12: 評価観点 評価内容 評価 認証管理 Step1でMFA導入・監視ログ・アラート通知設定済み ★★★（3） 権限管理（IAM） 管理者権限の最小化、RBAC運用、Update ServerのIAMロールも定期監査対象 ★★★（3） インスタンス作成の監視 CloudTrail相当のログ収集有効化とSIEM連携、異常インスタンス作成アラート設定 ★★★（3） ガードレール制御 テンプレート制限・事前承認フロー未導入（自動インスタンス作成が可能な設定あり） ★★☆（2） 構成ミスの検出自動化 CSPMは導入済、ただしSSPMは未導入 ★★☆（2） 監査と事後対応 月次の操作監査あり。外部監査は年1回 ★★☆（2） → 総合評価：2.5 → 切り上げて 3（レベル3） | R12: =SPRV_Source_For_Formulas!D44 -> T1059.009 | S12: クラウドAPIを使ってスクリプトを遠隔実行し設定変更やマルウェア展開。 | T12: 3 | U12: 1 | V12: =IF(SPRV_Source_For_Formulas!G44<=0.2,3,IF(SPRV_Source_For_Formulas!G44<=0.5,2,1)) -> 3 | W12: =4-V12 -> 1 | X12: =IF(AND(T12=3,U12*W12>=6),"A",IF(AND(T12=3,U12*W12>=3),"B",IF(AND(T12=3,U12*W12>=1),"C",""))) -> C | Y12: | 観点 | 内容 | | ------------ | ----------------------------------------------------------------------- | | ? IAM制御 | IAM最小権限ポリシー、ロールベースアクセス制御（RBAC）の適用が前提となっており、基本的な対策は講じられていると考えられる | | ? API監視 | CloudTrail（AWS）やAudit Log（GCP）等による**API呼び出しログの記録と分析**も想定されている | | ? 不安要素 | クラウドAPIは「正規操作」として処理されやすいため、不正利用が**異常検知で気付きにくい**<br>⇒ 監視設定が甘いと侵害が長期化しやすい | | ? 利用頻度 | 管理者も通常業務でAPIを使うため、攻撃と区別が困難（例：異常な時間帯やIPでの利用を監視できるかどうかが鍵） | | ? 自治体側の技術成熟度 | クラウドセキュリティに不慣れな自治体ではAPI監査設定が**未設定または過剰権限のまま**であるケースが懸念される |リスクをさらに下げる効果的な対策は、| 項目 | 推奨構成（ベンダ中立） | | ----- | --------------------------------------------- | | ログ取得 | CloudTrail / Audit Logs + 長期保管 | | 検知・分析 | GuardDuty / SCC / Defender for Cloud + SIEM連携 | | 統制 | IAM最小権限 + 条件付きアクセス + 定期レビューワークフロー | | ツール連携 | EDRやPAM、SIEMとCNAppと連携して**誤用や内部不正**にも対応 | | Z12: =SPRV_Source_For_Formulas!D45 -> T1496.004 | AA12: クラウドAPI経由で Proxy Server on GovCloud に対して以下を実施： EC2/EBSなどのストレージを暗号化（KMSキーを使って再暗号化またはKMSキーを削除） OSレベルでスクリプトを投入し、ボリュームをBitLockerやLinuxのLUKS等で暗号化 システムログやスナップショットの削除による復旧妨害 IAMの一時的制御権を用いた“復旧阻止”工作 ガバメントクラウド内で復旧オプションが封じられた状態にされることで、実質的なデータロックアウトが生じる。 | AB12: 3 | AC12: 1 | AD12: =IF(SPRV_Source_For_Formulas!G45<=0.2,3,IF(SPRV_Source_For_Formulas!G45<=0.5,2,1)) -> 2 | AE12: =4-AD12 -> 2 | AF12: =IF(AND(AB12=3,AC12*AE12>=6),"A",IF(AND(AB12=3,AC12*AE12>=3),"B",IF(AND(AB12=3,AC12*AE12>=1),"C",""))) -> C | AG12: | 評価観点 | 評価内容 | 評価 | | ------------- | ---------------------------------------------------- | ------ | | データ暗号化制御 | KMSのアクセス制御やEBS暗号化ポリシーは一部導入。ただしProxy Server単体の制御は未記載。 | ★★☆（2） | | ログ・スナップショット保全 | CloudTrailログ保全は一部設定あり。スナップショット削除阻止や整合性保全策は記載なし。 | ★★☆（2） | | API実行制御 | Step3でAPI攻撃が成立済のため、IAM/API制御に抜けあり。SSPM未導入。 | ★☆☆（1） |→ 総合評価：1.7 → 切り捨てて「レベル1」 | AP12: =MAX(D12,L12,T12,AB12) -> 3 | AQ12: 1 | AR12: =4-AS12 -> 1 | AS12: =MAX(F12,N12,V12,AD12) -> 3 | AT12: =IF(AND(AP12=3,AQ12*AR12>=6),"A",IF(AND(AP12=3,AQ12*AR12>=3),"B",IF(AND(AP12=3,AQ12*AR12>=1),"C",""))) -> C | AU12: ="Scenario-level Threat=1; Step1="&H12&" Step2="&P12&" Step3="&X12&" Step4="&AF12&" ; Overall Threat fixed=1, Max Mitigation="&AS12&" => Overall="&AT12 -> Scenario-level Threat=1; Step1=C Step2=C Step3=C Step4=C ; Overall Threat fixed=1, Max Mitigation=3 => Overall=C
A13: =SPRV_Source_For_Formulas!D46 -> T1189 | B13: 攻撃手法の具体化 運用管理者が、日常的に利用する 業務関連Webポータル／ガバメントクラウド管理サイト にアクセス。 攻撃者がWebサイトを改ざんし、マルウェアを仕込んでいる。 管理者が 閲覧またはファイルをダウンロードするだけで自動的にマルウェア感染。 結果として： 管理者端末を初期感染させ、GovCloud管理コンソールへの認証情報（セッションCookie、MFAトークン等）を窃取 その後の クラウドリソース操作権限の奪取 に直結。 | D13: 3 | E13: 1 | F13: =IF(SPRV_Source_For_Formulas!G46<=0.2,3,IF(SPRV_Source_For_Formulas!G46<=0.5,2,1)) -> 3 | G13: =4-F13 -> 1 | H13: =IF(AND(D13=3,E13*G13>=6),"A",IF(AND(D13=3,E13*G13>=3),"B",IF(AND(D13=3,E13*G13>=1),"C",""))) -> C | I13: | 評価観点 | 状況・施策内容 | 評価 | | ----------------- | -------------------------------------------------- | ------ | | エンドポイント防御（EDR/AV） | EDR導入済み、シグネチャ更新自動化。未知マルウェアにはふるまい検知依存。 | ★★★（3） | | Webフィルタリング／改ざん検知 | SWG導入済。不審サイト遮断可能。ただし正規業務ポータル改ざんのゼロデイ検知は困難。 | ★★☆（2） | | パッチ管理／ソフト更新 | ブラウザ・OSはMDMで強制更新。48時間以内に重大パッチ適用（β’モデル準拠）。 | ★★★（3） | | アクセス制御（ZTNA） | 管理端末以外からのアクセスは不可。職員ID＋MFA必須。ただし端末感染時のセッション乗っ取りは残る。 | ★★☆（2） | | ログ監視・SOC連携 | SOC監視下にあり、端末挙動ログをSIEMで分析。ただし初期感染段階での即時検知は限定的。 | ★★☆（2） |→ 総合評価：2.4 → 切り上げて レベル3 | J13: =SPRV_Source_For_Formulas!D47 -> T1578.002 | K13: クラウド管理権限を悪用し、Update Serverと同一VPC内または他VPCに不正なクラウドインスタンス（C2やバックドア用）を作成し、横展開を試みる | L13: 3 | M13: 1 | N13: =IF(SPRV_Source_For_Formulas!G47<=0.2,3,IF(SPRV_Source_For_Formulas!G47<=0.5,2,1)) -> 2 | O13: =4-N13 -> 2 | P13: =IF(AND(L13=3,M13*O13>=6),"A",IF(AND(L13=3,M13*O13>=3),"B",IF(AND(L13=3,M13*O13>=1),"C",""))) -> C | Q13: 評価観点 評価内容 評価 認証管理 Step1でMFA導入・監視ログ・アラート通知設定済み ★★★（3） 権限管理（IAM） 管理者権限の最小化、RBAC運用、Update ServerのIAMロールも定期監査対象 ★★★（3） インスタンス作成の監視 CloudTrail相当のログ収集有効化とSIEM連携、異常インスタンス作成アラート設定 ★★★（3） ガードレール制御 テンプレート制限・事前承認フロー未導入（自動インスタンス作成が可能な設定あり） ★★☆（2） 構成ミスの検出自動化 CSPMは導入済、ただしSSPMは未導入 ★★☆（2） 監査と事後対応 月次の操作監査あり。外部監査は年1回 ★★☆（2） → 総合評価：2.5 → 切り上げて 3（レベル3） | R13: =SPRV_Source_For_Formulas!D48 -> T1059.009 | S13: クラウドAPIを使ってスクリプトを遠隔実行し設定変更やマルウェア展開。 | T13: 3 | U13: 1 | V13: =IF(SPRV_Source_For_Formulas!G48<=0.2,3,IF(SPRV_Source_For_Formulas!G48<=0.5,2,1)) -> 3 | W13: =4-V13 -> 1 | X13: =IF(AND(T13=3,U13*W13>=6),"A",IF(AND(T13=3,U13*W13>=3),"B",IF(AND(T13=3,U13*W13>=1),"C",""))) -> C | Y13: | 観点 | 内容 | | ------------ | ----------------------------------------------------------------------- | | ? IAM制御 | IAM最小権限ポリシー、ロールベースアクセス制御（RBAC）の適用が前提となっており、基本的な対策は講じられていると考えられる | | ? API監視 | CloudTrail（AWS）やAudit Log（GCP）等による**API呼び出しログの記録と分析**も想定されている | | ? 不安要素 | クラウドAPIは「正規操作」として処理されやすいため、不正利用が**異常検知で気付きにくい**<br>⇒ 監視設定が甘いと侵害が長期化しやすい | | ? 利用頻度 | 管理者も通常業務でAPIを使うため、攻撃と区別が困難（例：異常な時間帯やIPでの利用を監視できるかどうかが鍵） | | ? 自治体側の技術成熟度 | クラウドセキュリティに不慣れな自治体ではAPI監査設定が**未設定または過剰権限のまま**であるケースが懸念される |リスクをさらに下げる効果的な対策は、| 項目 | 推奨構成（ベンダ中立） | | ----- | --------------------------------------------- | | ログ取得 | CloudTrail / Audit Logs + 長期保管 | | 検知・分析 | GuardDuty / SCC / Defender for Cloud + SIEM連携 | | 統制 | IAM最小権限 + 条件付きアクセス + 定期レビューワークフロー | | ツール連携 | EDRやPAM、SIEMとCNAppと連携して**誤用や内部不正**にも対応 | | Z13: =SPRV_Source_For_Formulas!D49 -> T1496.002 | AA13: 侵入済みのクラウド環境において、プロキシサーバの帯域を意図的に消費（例：大量データ送信、仮想マイニングノードの設置など）することで、ガバメントクラウドやVPN経路の通信品質を劣化させ、他の通信遅延・業務妨害を引き起こすDoS型の資源枯渇攻撃に該当。システム停止を伴わずに“リソース占有”による間接的な被害を狙う | AB13: 3 | AC13: 1 | AD13: =IF(SPRV_Source_For_Formulas!G49<=0.2,3,IF(SPRV_Source_For_Formulas!G49<=0.5,2,1)) -> 2 | AE13: =4-AD13 -> 2 | AF13: =IF(AND(AB13=3,AC13*AE13>=6),"A",IF(AND(AB13=3,AC13*AE13>=3),"B",IF(AND(AB13=3,AC13*AE13>=1),"C",""))) -> C | AG13: | 評価カテゴリ | 対策内容（遵守済と仮定） | 評価 | | ----------------- | -------------------------------------------------------- | ------ | | **プロキシ通信監視** | SWG・Proxyログは収集済、SIEM連携も実施。DNSや宛先IPでのトラフィック可視化が可能。 | ★★★（3） | | **異常帯域検出とアラート** | GuardDuty相当で異常通信のアラートはあるが、**帯域使用量ベースのしきい値監視は未設定** | ★★☆（2） | | **アウトバウンド制御** | Egress制御ポリシーあり（国別やFQDN制限）。ただし動的アノマリー検知は未導入。 | ★★☆（2） | | **構成ミス・ルーティング検知** | CSPMは導入済。SWGの過剰許可設定については検出対象。 | ★★★（3） | | **サービス間通信制限** | VPCピアリングやプロキシ経路の制限は設計上存在。ただし、**運用上の例外が散見される**（一部緩いルールあり） | ★★☆（2） |総合評価（レベル判定） 評価平均：約 2.4 → 切り上げ処理により レベル：★★★（3） | AP13: =MAX(D13,L13,T13,AB13) -> 3 | AQ13: 1 | AR13: =4-AS13 -> 1 | AS13: =MAX(F13,N13,V13,AD13) -> 3 | AT13: =IF(AND(AP13=3,AQ13*AR13>=6),"A",IF(AND(AP13=3,AQ13*AR13>=3),"B",IF(AND(AP13=3,AQ13*AR13>=1),"C",""))) -> C | AU13: ="Scenario-level Threat=1; Step1="&H13&" Step2="&P13&" Step3="&X13&" Step4="&AF13&" ; Overall Threat fixed=1, Max Mitigation="&AS13&" => Overall="&AT13 -> Scenario-level Threat=1; Step1=C Step2=C Step3=C Step4=C ; Overall Threat fixed=1, Max Mitigation=3 => Overall=C
A14: =SPRV_Source_For_Formulas!D50 -> T1189 | B14: 攻撃手法の具体化 運用管理者が、日常的に利用する 業務関連Webポータル／ガバメントクラウド管理サイト にアクセス。 攻撃者がWebサイトを改ざんし、マルウェアを仕込んでいる。 管理者が 閲覧またはファイルをダウンロードするだけで自動的にマルウェア感染。 結果として： 管理者端末を初期感染させ、GovCloud管理コンソールへの認証情報（セッションCookie、MFAトークン等）を窃取 その後の クラウドリソース操作権限の奪取 に直結。 | D14: 3 | E14: 1 | F14: =IF(SPRV_Source_For_Formulas!G50<=0.2,3,IF(SPRV_Source_For_Formulas!G50<=0.5,2,1)) -> 3 | G14: =4-F14 -> 1 | H14: =IF(AND(D14=3,E14*G14>=6),"A",IF(AND(D14=3,E14*G14>=3),"B",IF(AND(D14=3,E14*G14>=1),"C",""))) -> C | I14: | 評価観点 | 状況・施策内容 | 評価 | | ----------------- | -------------------------------------------------- | ------ | | エンドポイント防御（EDR/AV） | EDR導入済み、シグネチャ更新自動化。未知マルウェアにはふるまい検知依存。 | ★★★（3） | | Webフィルタリング／改ざん検知 | SWG導入済。不審サイト遮断可能。ただし正規業務ポータル改ざんのゼロデイ検知は困難。 | ★★☆（2） | | パッチ管理／ソフト更新 | ブラウザ・OSはMDMで強制更新。48時間以内に重大パッチ適用（β’モデル準拠）。 | ★★★（3） | | アクセス制御（ZTNA） | 管理端末以外からのアクセスは不可。職員ID＋MFA必須。ただし端末感染時のセッション乗っ取りは残る。 | ★★☆（2） | | ログ監視・SOC連携 | SOC監視下にあり、端末挙動ログをSIEMで分析。ただし初期感染段階での即時検知は限定的。 | ★★☆（2） |→ 総合評価：2.4 → 切り上げて レベル3 | J14: =SPRV_Source_For_Formulas!D51 -> T1578.002 | K14: クラウド管理権限を悪用し、Update Serverと同一VPC内または他VPCに不正なクラウドインスタンス（C2やバックドア用）を作成し、横展開を試みる | L14: 3 | M14: 1 | N14: =IF(SPRV_Source_For_Formulas!G51<=0.2,3,IF(SPRV_Source_For_Formulas!G51<=0.5,2,1)) -> 2 | O14: =4-N14 -> 2 | P14: =IF(AND(L14=3,M14*O14>=6),"A",IF(AND(L14=3,M14*O14>=3),"B",IF(AND(L14=3,M14*O14>=1),"C",""))) -> C | Q14: 評価観点 評価内容 評価 認証管理 Step1でMFA導入・監視ログ・アラート通知設定済み ★★★（3） 権限管理（IAM） 管理者権限の最小化、RBAC運用、Update ServerのIAMロールも定期監査対象 ★★★（3） インスタンス作成の監視 CloudTrail相当のログ収集有効化とSIEM連携、異常インスタンス作成アラート設定 ★★★（3） ガードレール制御 テンプレート制限・事前承認フロー未導入（自動インスタンス作成が可能な設定あり） ★★☆（2） 構成ミスの検出自動化 CSPMは導入済、ただしSSPMは未導入 ★★☆（2） 監査と事後対応 月次の操作監査あり。外部監査は年1回 ★★☆（2） → 総合評価：2.5 → 切り上げて 3（レベル3） | R14: =SPRV_Source_For_Formulas!D52 -> T1484.002 | S14: GPOなどを再度改変し、持続的侵入を確保。 | T14: 3 | U14: 1 | V14: =IF(SPRV_Source_For_Formulas!G52<=0.2,3,IF(SPRV_Source_For_Formulas!G52<=0.5,2,1)) -> 3 | W14: =4-V14 -> 1 | X14: =IF(AND(T14=3,U14*W14>=6),"A",IF(AND(T14=3,U14*W14>=3),"B",IF(AND(T14=3,U14*W14>=1),"C",""))) -> C | Y14: | 対策カテゴリ | 記載内容 | 評価 | | ------------------- | -------------------------------- | -------------- | | **IAM権限制御の厳格化** | 「特権ロールは必要最小限に限定」「特定職員のみ管理可能」 | 実施済 | | **クラウド設定の変更履歴の監査** | 「CloudTrail等を用いた変更記録」「月次で変更レビュー」 | 実施（GovCloud要件） | | **SaaS側のロール分離** | 「システム管理者とデータ閲覧者の分離」 | 一部SaaSで未対応 | | **クラウド構成管理**（CSPM等） | 「自動でポリシー逸脱を検知・可視化」 | 一部導入（推奨構成ベース） | | **異常挙動検知（UEBA）** | 「IAM操作ログの異常行動監視」 | 導入未確実（明記なし） | さらなる効果的な対策は、UEBA（ユーザー行動分析）やCNAPPの導入強化により、意図しないポリシー変更の「兆候検知」が可能 **SaaS基盤側のIAM制御精度向上（管理者ロールの細分化）**は今後の課題 **構成管理の自動逸脱修正（Auto Remediation）**の仕組み導入が望まれる | Z14: =SPRV_Source_For_Formulas!D53 -> T1486 | AA14: クラウドリソース（仮想マシン等）を乗っ取り、暗号資産マイニング/DDoS中継に悪用。 | AB14: 3 | AC14: 1 | AD14: =IF(SPRV_Source_For_Formulas!G53<=0.2,3,IF(SPRV_Source_For_Formulas!G53<=0.5,2,1)) -> 3 | AE14: =4-AD14 -> 1 | AF14: =IF(AND(AB14=3,AC14*AE14>=6),"A",IF(AND(AB14=3,AC14*AE14>=3),"B",IF(AND(AB14=3,AC14*AE14>=1),"C",""))) -> C | AG14: CSPMによるリソース使用率監視、アラート設定が有効（β’3.4.3相当）。 | AP14: =MAX(D14,L14,T14,AB14) -> 3 | AQ14: 1 | AR14: =4-AS14 -> 1 | AS14: =MAX(F14,N14,V14,AD14) -> 3 | AT14: =IF(AND(AP14=3,AQ14*AR14>=6),"A",IF(AND(AP14=3,AQ14*AR14>=3),"B",IF(AND(AP14=3,AQ14*AR14>=1),"C",""))) -> C | AU14: ="Scenario-level Threat=1; Step1="&H14&" Step2="&P14&" Step3="&X14&" Step4="&AF14&" ; Overall Threat fixed=1, Max Mitigation="&AS14&" => Overall="&AT14 -> Scenario-level Threat=1; Step1=C Step2=C Step3=C Step4=C ; Overall Threat fixed=1, Max Mitigation=3 => Overall=C
A15: =SPRV_Source_For_Formulas!D54 -> T1189 | B15: 攻撃手法の具体化 運用管理者が、日常的に利用する 業務関連Webポータル／ガバメントクラウド管理サイト にアクセス。 攻撃者がWebサイトを改ざんし、マルウェアを仕込んでいる。 管理者が 閲覧またはファイルをダウンロードするだけで自動的にマルウェア感染。 結果として： 管理者端末を初期感染させ、GovCloud管理コンソールへの認証情報（セッションCookie、MFAトークン等）を窃取 その後の クラウドリソース操作権限の奪取 に直結。 | D15: 3 | E15: 1 | F15: =IF(SPRV_Source_For_Formulas!G54<=0.2,3,IF(SPRV_Source_For_Formulas!G54<=0.5,2,1)) -> 3 | G15: =4-F15 -> 1 | H15: =IF(AND(D15=3,E15*G15>=6),"A",IF(AND(D15=3,E15*G15>=3),"B",IF(AND(D15=3,E15*G15>=1),"C",""))) -> C | I15: | 評価観点 | 状況・施策内容 | 評価 | | ----------------- | -------------------------------------------------- | ------ | | エンドポイント防御（EDR/AV） | EDR導入済み、シグネチャ更新自動化。未知マルウェアにはふるまい検知依存。 | ★★★（3） | | Webフィルタリング／改ざん検知 | SWG導入済。不審サイト遮断可能。ただし正規業務ポータル改ざんのゼロデイ検知は困難。 | ★★☆（2） | | パッチ管理／ソフト更新 | ブラウザ・OSはMDMで強制更新。48時間以内に重大パッチ適用（β’モデル準拠）。 | ★★★（3） | | アクセス制御（ZTNA） | 管理端末以外からのアクセスは不可。職員ID＋MFA必須。ただし端末感染時のセッション乗っ取りは残る。 | ★★☆（2） | | ログ監視・SOC連携 | SOC監視下にあり、端末挙動ログをSIEMで分析。ただし初期感染段階での即時検知は限定的。 | ★★☆（2） |→ 総合評価：2.4 → 切り上げて レベル3 | J15: =SPRV_Source_For_Formulas!D55 -> T1578.002 | K15: クラウド管理権限を悪用し、Update Serverと同一VPC内または他VPCに不正なクラウドインスタンス（C2やバックドア用）を作成し、横展開を試みる | L15: 3 | M15: 1 | N15: =IF(SPRV_Source_For_Formulas!G55<=0.2,3,IF(SPRV_Source_For_Formulas!G55<=0.5,2,1)) -> 2 | O15: =4-N15 -> 2 | P15: =IF(AND(L15=3,M15*O15>=6),"A",IF(AND(L15=3,M15*O15>=3),"B",IF(AND(L15=3,M15*O15>=1),"C",""))) -> C | Q15: 評価観点 評価内容 評価 認証管理 Step1でMFA導入・監視ログ・アラート通知設定済み ★★★（3） 権限管理（IAM） 管理者権限の最小化、RBAC運用、Update ServerのIAMロールも定期監査対象 ★★★（3） インスタンス作成の監視 CloudTrail相当のログ収集有効化とSIEM連携、異常インスタンス作成アラート設定 ★★★（3） ガードレール制御 テンプレート制限・事前承認フロー未導入（自動インスタンス作成が可能な設定あり） ★★☆（2） 構成ミスの検出自動化 CSPMは導入済、ただしSSPMは未導入 ★★☆（2） 監査と事後対応 月次の操作監査あり。外部監査は年1回 ★★☆（2） → 総合評価：2.5 → 切り上げて 3（レベル3） | R15: =SPRV_Source_For_Formulas!D56 -> T1484.002 | S15: GPOなどを再度改変し、持続的侵入を確保。 | T15: 3 | U15: 1 | V15: =IF(SPRV_Source_For_Formulas!G56<=0.2,3,IF(SPRV_Source_For_Formulas!G56<=0.5,2,1)) -> 3 | W15: =4-V15 -> 1 | X15: =IF(AND(T15=3,U15*W15>=6),"A",IF(AND(T15=3,U15*W15>=3),"B",IF(AND(T15=3,U15*W15>=1),"C",""))) -> C | Y15: | 対策カテゴリ | 記載内容 | 評価 | | ------------------- | -------------------------------- | -------------- | | **IAM権限制御の厳格化** | 「特権ロールは必要最小限に限定」「特定職員のみ管理可能」 | 実施済 | | **クラウド設定の変更履歴の監査** | 「CloudTrail等を用いた変更記録」「月次で変更レビュー」 | 実施（GovCloud要件） | | **SaaS側のロール分離** | 「システム管理者とデータ閲覧者の分離」 | 一部SaaSで未対応 | | **クラウド構成管理**（CSPM等） | 「自動でポリシー逸脱を検知・可視化」 | 一部導入（推奨構成ベース） | | **異常挙動検知（UEBA）** | 「IAM操作ログの異常行動監視」 | 導入未確実（明記なし） | さらなる効果的な対策は、UEBA（ユーザー行動分析）やCNAPPの導入強化により、意図しないポリシー変更の「兆候検知」が可能 **SaaS基盤側のIAM制御精度向上（管理者ロールの細分化）**は今後の課題 **構成管理の自動逸脱修正（Auto Remediation）**の仕組み導入が望まれる | Z15: =SPRV_Source_For_Formulas!D57 -> T1496.001 | AA15: 計算リソースを秘匿的に不正利用（Compute Hijacking）。 | AB15: 3 | AC15: 1 | AD15: =IF(SPRV_Source_For_Formulas!G57<=0.2,3,IF(SPRV_Source_For_Formulas!G57<=0.5,2,1)) -> 2 | AE15: =4-AD15 -> 2 | AF15: =IF(AND(AB15=3,AC15*AE15>=6),"A",IF(AND(AB15=3,AC15*AE15>=3),"B",IF(AND(AB15=3,AC15*AE15>=1),"C",""))) -> C | AG15: モニタリング＋しきい値制限（Azure Monitor等）で抑止可能。 | AP15: =MAX(D15,L15,T15,AB15) -> 3 | AQ15: 1 | AR15: =4-AS15 -> 1 | AS15: =MAX(F15,N15,V15,AD15) -> 3 | AT15: =IF(AND(AP15=3,AQ15*AR15>=6),"A",IF(AND(AP15=3,AQ15*AR15>=3),"B",IF(AND(AP15=3,AQ15*AR15>=1),"C",""))) -> C | AU15: ="Scenario-level Threat=1; Step1="&H15&" Step2="&P15&" Step3="&X15&" Step4="&AF15&" ; Overall Threat fixed=1, Max Mitigation="&AS15&" => Overall="&AT15 -> Scenario-level Threat=1; Step1=C Step2=C Step3=C Step4=C ; Overall Threat fixed=1, Max Mitigation=3 => Overall=C
A16: =SPRV_Source_For_Formulas!D58 -> T1189 | B16: 攻撃手法の具体化 運用管理者が、日常的に利用する 業務関連Webポータル／ガバメントクラウド管理サイト にアクセス。 攻撃者がWebサイトを改ざんし、マルウェアを仕込んでいる。 管理者が 閲覧またはファイルをダウンロードするだけで自動的にマルウェア感染。 結果として： 管理者端末を初期感染させ、GovCloud管理コンソールへの認証情報（セッションCookie、MFAトークン等）を窃取 その後の クラウドリソース操作権限の奪取 に直結。 | D16: 3 | E16: 1 | F16: =IF(SPRV_Source_For_Formulas!G58<=0.2,3,IF(SPRV_Source_For_Formulas!G58<=0.5,2,1)) -> 3 | G16: =4-F16 -> 1 | H16: =IF(AND(D16=3,E16*G16>=6),"A",IF(AND(D16=3,E16*G16>=3),"B",IF(AND(D16=3,E16*G16>=1),"C",""))) -> C | I16: | 評価観点 | 状況・施策内容 | 評価 | | ----------------- | -------------------------------------------------- | ------ | | エンドポイント防御（EDR/AV） | EDR導入済み、シグネチャ更新自動化。未知マルウェアにはふるまい検知依存。 | ★★★（3） | | Webフィルタリング／改ざん検知 | SWG導入済。不審サイト遮断可能。ただし正規業務ポータル改ざんのゼロデイ検知は困難。 | ★★☆（2） | | パッチ管理／ソフト更新 | ブラウザ・OSはMDMで強制更新。48時間以内に重大パッチ適用（β’モデル準拠）。 | ★★★（3） | | アクセス制御（ZTNA） | 管理端末以外からのアクセスは不可。職員ID＋MFA必須。ただし端末感染時のセッション乗っ取りは残る。 | ★★☆（2） | | ログ監視・SOC連携 | SOC監視下にあり、端末挙動ログをSIEMで分析。ただし初期感染段階での即時検知は限定的。 | ★★☆（2） |→ 総合評価：2.4 → 切り上げて レベル3 | J16: =SPRV_Source_For_Formulas!D59 -> T1578.002 | K16: クラウド管理権限を悪用し、Update Serverと同一VPC内または他VPCに不正なクラウドインスタンス（C2やバックドア用）を作成し、横展開を試みる | L16: 3 | M16: 1 | N16: =IF(SPRV_Source_For_Formulas!G59<=0.2,3,IF(SPRV_Source_For_Formulas!G59<=0.5,2,1)) -> 2 | O16: =4-N16 -> 2 | P16: =IF(AND(L16=3,M16*O16>=6),"A",IF(AND(L16=3,M16*O16>=3),"B",IF(AND(L16=3,M16*O16>=1),"C",""))) -> C | Q16: 評価観点 評価内容 評価 認証管理 Step1でMFA導入・監視ログ・アラート通知設定済み ★★★（3） 権限管理（IAM） 管理者権限の最小化、RBAC運用、Update ServerのIAMロールも定期監査対象 ★★★（3） インスタンス作成の監視 CloudTrail相当のログ収集有効化とSIEM連携、異常インスタンス作成アラート設定 ★★★（3） ガードレール制御 テンプレート制限・事前承認フロー未導入（自動インスタンス作成が可能な設定あり） ★★☆（2） 構成ミスの検出自動化 CSPMは導入済、ただしSSPMは未導入 ★★☆（2） 監査と事後対応 月次の操作監査あり。外部監査は年1回 ★★☆（2） → 総合評価：2.5 → 切り上げて 3（レベル3） | R16: =SPRV_Source_For_Formulas!D60 -> T1484.002 | S16: GPOなどを再度改変し、持続的侵入を確保。 | T16: 3 | U16: 1 | V16: =IF(SPRV_Source_For_Formulas!G60<=0.2,3,IF(SPRV_Source_For_Formulas!G60<=0.5,2,1)) -> 3 | W16: =4-V16 -> 1 | X16: =IF(AND(T16=3,U16*W16>=6),"A",IF(AND(T16=3,U16*W16>=3),"B",IF(AND(T16=3,U16*W16>=1),"C",""))) -> C | Y16: | 対策カテゴリ | 記載内容 | 評価 | | ------------------- | -------------------------------- | -------------- | | **IAM権限制御の厳格化** | 「特権ロールは必要最小限に限定」「特定職員のみ管理可能」 | 実施済 | | **クラウド設定の変更履歴の監査** | 「CloudTrail等を用いた変更記録」「月次で変更レビュー」 | 実施（GovCloud要件） | | **SaaS側のロール分離** | 「システム管理者とデータ閲覧者の分離」 | 一部SaaSで未対応 | | **クラウド構成管理**（CSPM等） | 「自動でポリシー逸脱を検知・可視化」 | 一部導入（推奨構成ベース） | | **異常挙動検知（UEBA）** | 「IAM操作ログの異常行動監視」 | 導入未確実（明記なし） | さらなる効果的な対策は、UEBA（ユーザー行動分析）やCNAPPの導入強化により、意図しないポリシー変更の「兆候検知」が可能 **SaaS基盤側のIAM制御精度向上（管理者ロールの細分化）**は今後の課題 **構成管理の自動逸脱修正（Auto Remediation）**の仕組み導入が望まれる | Z16: =SPRV_Source_For_Formulas!D61 -> T1496.004 | AA16: クラウドAPI経由で Proxy Server on GovCloud に対して以下を実施： EC2/EBSなどのストレージを暗号化（KMSキーを使って再暗号化またはKMSキーを削除） OSレベルでスクリプトを投入し、ボリュームをBitLockerやLinuxのLUKS等で暗号化 システムログやスナップショットの削除による復旧妨害 IAMの一時的制御権を用いた“復旧阻止”工作 ガバメントクラウド内で復旧オプションが封じられた状態にされることで、実質的なデータロックアウトが生じる。 | AB16: 3 | AC16: 1 | AD16: =IF(SPRV_Source_For_Formulas!G61<=0.2,3,IF(SPRV_Source_For_Formulas!G61<=0.5,2,1)) -> 2 | AE16: =4-AD16 -> 2 | AF16: =IF(AND(AB16=3,AC16*AE16>=6),"A",IF(AND(AB16=3,AC16*AE16>=3),"B",IF(AND(AB16=3,AC16*AE16>=1),"C",""))) -> C | AG16: | 評価観点 | 評価内容 | 評価 | | ------------- | ---------------------------------------------------- | ------ | | データ暗号化制御 | KMSのアクセス制御やEBS暗号化ポリシーは一部導入。ただしProxy Server単体の制御は未記載。 | ★★☆（2） | | ログ・スナップショット保全 | CloudTrailログ保全は一部設定あり。スナップショット削除阻止や整合性保全策は記載なし。 | ★★☆（2） | | API実行制御 | Step3でAPI攻撃が成立済のため、IAM/API制御に抜けあり。SSPM未導入。 | ★☆☆（1） |→ 総合評価：1.7 → 切り捨てて「レベル1」 | AP16: =MAX(D16,L16,T16,AB16) -> 3 | AQ16: 1 | AR16: =4-AS16 -> 1 | AS16: =MAX(F16,N16,V16,AD16) -> 3 | AT16: =IF(AND(AP16=3,AQ16*AR16>=6),"A",IF(AND(AP16=3,AQ16*AR16>=3),"B",IF(AND(AP16=3,AQ16*AR16>=1),"C",""))) -> C | AU16: ="Scenario-level Threat=1; Step1="&H16&" Step2="&P16&" Step3="&X16&" Step4="&AF16&" ; Overall Threat fixed=1, Max Mitigation="&AS16&" => Overall="&AT16 -> Scenario-level Threat=1; Step1=C Step2=C Step3=C Step4=C ; Overall Threat fixed=1, Max Mitigation=3 => Overall=C
